Workbook

Sheet Kompetenzraster
B1: Kompetenzraster 1.Semester Sanitärinstallateur/in EFZ | I1: Semesterstart: | J1: 46248 | K1: Schultag: | L1: Montag | Q1: Klasse SAI1X
B3: Handlungsfelder und Kompetenzen | M3: Bewertung / Benotung | Q3: Unterichtsplanung 1. Semester
B5: HF 1 (PDA) | E5: Auftrag 1.1 | G5: Auftrag 1.2 | J5: Auftrag 1.3 | M5: Zeugnisnote | Q5: =J1+0 -> 46248 | R5: Allgemeine Infos zum Schulbetrieb / ICT
E6: 5 Schultage (10L) | G6: 8 Schultage (16L) | J6: 2 Schultage (4L) | M6: Die Zeugnisnote setzt sich aus den Leistungsnachweisen und Kompetenzprüfungen zusammen. Die Note aus den Leistungsnachweisen zählt zu ca. 30% an die Zeugnisnote. Alle Noten der Prüfungen zählen zu ca. 60% an die Zeugnisnote. | Q6: 1.12
B7: Planen der Arbeiten | E7: Sie rechnen Masse aus Plänen in Baumasse um. | F7: Sie interpretieren einfache Architekturpläne. | G7: Sie verstehen die Grundlagen des technischen Zeichnens und können diese anwenden. | H7: Sie können die drei Ansichten aus der Vorgabe einer Normalprojektion erstellen. | I7: Sie können aus der Vorgabe der drei Ansichten dreidimensionale Körper erstellen. | J7: Sie erläutern einen einfachen Stromkreislauf. | K7: Sie erläutern die Gefahren von Strom und beschreiben den Personen- und Sachschutz. | Q7: =Q5+7 -> 46255 | R7: Trinkwasser, Eigenschaften & Gewinnung
Q8: 1.4 1.1 | R8: Masse und Flächen berechnen
J9: Sie beschreiben, bei welchen Situationen eine PSA getragen werden muss. | Q9: =Q7+7 -> 46262 | R9: Trinkwasser, Eigenschaften & Gewinnung
E10: Sie berechnen Längen- und Höhenmasse. | F10: Sie berechnen den Platzbedarf (Fläche) von Apparaten und Anlagen anhand von Planvorgaben. | K10: Sie erklären, welche Reparatur- und Wartungsarbeiten an Maschinen erlaubt sind. | Q10: 1.4 1.1 | R10: Masse und Flächen berechnen
J11: Sie erläutern die Gefahren auf der Baustelle und in der Werkstatt. | Q11: =Q9+7 -> 46269 | R11: Trinkwasser, Eigenschaften & Gewinnung
Q12: 1.4 1.1 | R12: Masse und Flächen berechnen
Q13: =Q11+7 -> 46276 | R13: Trinkwasser, Eigenschaften & Gewinnung
B14: HF 1 (PDA) | E14: Auftrag 1.12 | M14: Leistungsnachweise | Q14: 1.4 1.1 | R14: Masse und Flächen berechnen
E15: 1 Schultag (4L) | M15: Die Note der Leistungsnachweise entsteht aus den während des Semestes erzielten Punkten. | Q15: =Q13+7 -> 46283 | R15: Wasserleitungsmaterialien & Verbindungen
B16: Planen der Arbeiten | E16: Sie beherschen ihr Arbeitsgerät (Convertible) und können die Software korrekt bedienen. | Q16: 1.5 1.1 | R16: Arbeitssicherheit & Elektrizität
Q17: =Q15+7 -> 46290 | R17: Wasserleitungsmaterialien & Verbindungen
Q18: 1.5 1.3 | R18: Arbeitssicherheit & Elektrizität
M19: Planen der Arbeiten | Q19: =Q17+28 -> 46318 | R19: Wasserleitungsmaterialien & Verbindungen
M20: Auftrag 1.1 | N20: 2 | Q20: 1.5 1.3 | R20: Arbeitssicherheit & Elektrizität
M21: Auftrag 1.2 | N21: 3 | Q21: =Q19+7 -> 46325 | R21: Wasserleitungsmaterialien & Verbindungen
M22: Auftrag 1.3 | N22: 1 | Q22: 1.5 1.2 | R22: Grundlagen technisches Zeichnen
B23: HF 2 (MVS) | E23: Auftrag 1.4 | G23: Auftrag 1.5 | M23: Auftrag 1.12 | N23: 1 | Q23: =Q21+7 -> 46332 | R23: WAS Leitungsmaterialien & Verbindungen
E24: 4 Schultage (12L) | G24: 4 Schultage (12L) | M24: Total Punkte | N24: =SUM(N20:O23) -> 7 | Q24: 1.6 1.2 | R24: Grundlagen technisches Zeichnen
B25: Montieren von Sanitäranlagen | E25: Sie beschreiben die wichtigsten Eigenschaften von Wasser. | F25: Sie beschreiben die Funktionsweise der Wasserversorgung. | G25: Sie unterscheiden die Systeme für Wasserleitungen nach Material und Verwendungszweck. | H25: Sie ordnen die gebräuchlichen Armaturen den Armaturengruppen korrekt zu. | I25: Sie beschreiben die Materialeigenschaften der verschiedenen Rohrsysteme aus Kunststoff und Metall. | Q25: =Q23+7 -> 46339 | R25: WAS Leitungsmaterialien & Verbindungen
M26: Montieren von Sanitäranlagen | Q26: 1.6 1.2 | R26: Grundlagen technisches Zeichnen
M27: Auftrag 1.4 | N27: 1.5 | Q27: =Q25+7 -> 46346 | R27: WAS Leitungsmaterialien & Verbindungen
E28: Sie erklären die Trink-wassergewinnung. | F28: Sie benennen die gängigen Vorschriften bezüglich Wasserhygiene. | G28: Sie benennen die Verbindungen und Dichtungsmaterialien der verschiedenen Installationssysteme. | M28: Auftrag 1.5 | N28: 1.5 | Q28: 1.6 1.2 | R28: Grundlagen technisches Zeichnen
M29: Auftrag 1.6 | N29: 1.5 | Q29: =Q27+7 -> 46353 | R29: WAS Leitungsmaterialien & Verbindungen
M30: Auftrag 1.8 | N30: 2 | Q30: 1.6 1.2 | R30: Grundlagen technisches Zeichnen
M31: Auftrag 1.9 | N31: 2 | Q31: =Q29+7 -> 46360 | R31: Die wichtigsten Sanitärapparate
B32: HF 4/7 (MVS) | E32: Auftrag 1.6 | H32: Auftrag 1.8 | J32: Auftrag 1.9 | M32: Total Punkte | N32: =SUM(N27:O31) -> 8.5 | Q32: 1.8 1.2 | R32: Grundlagen technisches Zeichnen
E33: 4 Schultage (12L) | H33: 3 Schultage (9L) | J33: 2 Schultage (5L) | Q33: =Q31+7 -> 46367 | R33: Die wichtigsten Sanitärapparate
B34: Montieren von Sanitäranlagen | E34: Sie beschreiben die unterschiedlichen Abwasserarten. | F34: Sie unterscheiden die Systeme von Entsorgungsleitungen nach Verwendungszweck. | G34: Sie beschreiben die Materialen und Werkstoffe, die bei Entsorgungsleitungen eingesetzt werden. | H34: Sie beschreiben die gebräuchlichen Entwässerungsgegenstände. | J34: Sie erklären den organisatorischen Ablauf bei der Entsorgung von Abfällen. | K34: Sie benennen die relevanten Umweltvorschriften im Zusammenhang mit der Vermeidung und Entsorgung von Abfällen. | Q34: 1.8 1.2 | R34: Grundlagen technisches Zeichnen
Q35: =Q33+7 -> 46374 | R35: Die wichtigsten Sanitärapparate
Q36: 1.8 1.2 | R36: Grundlagen technisches Zeichnen
E37: Sie beschreiben die verschiedenen Rohrmaterialien für Entsorgungsleitungen. | F37: Sie erläutern die Verbindungsmöglichkeiten der verschiedenen Installationssysteme. | G37: Sie bestimmen geeignete Befestigungen mit Hilfe von Montagebüchern. | J37: Sie erläutern den Recycling-Kreislauf und erläutern die Gefahren von Sonderabfällen. | Q37: =Q35+21 -> 46395 | R37: Abfallentsorgung
Q38: 1.9 1.2 | R38: Grundlagen technisches Zeichnen
Q39: =Q37+7 -> 46402 | R39: Abfallentsorgung / Besprechung Zeugnis
Q40: 1.9 1.11 | R40: Leitungsisometrie
Q41: =Q39+7 -> 46409 | R41: Elektrotechnik / Berechnungen
R42: Leitungsisometrie
...

Sheet ST_1_KW33
B1: Unterrichtsverlauf | E1: =Kompetenzraster!Q5 -> 46248 | G1: 1
B3: ICT Grundlagen | G3: 1.12
B5: 1 - 3 Lektion | C5: * Einstieg mit Film Digitalisierung | G5: Filme / Theorie
C6: * Installation Convertible / GBS Login der Schule
C7: * Download & Erklärung Microsoft Teams
C8: * Login und Erkärung myGBS / NESA
C10: Lernziele
C11: Sie kennen Ihren Login und können sich in den Portalen der Schule (mygbs / NESA) anmelden.
C12: Sie kennen die Plattform Microsoft Teams und myPlanner, myGBS, myDrive, myMail, MyEDU
B15: Pause
B17: ICT Grundlagen | G17: 1.12
B19: 4 - 5 Lektion | C19: * Erklärung & Einrichtung OneDrive
C20: * Erklärung & Installation OneNote
C21: * Auftrag Leistungsnachweis
C24: Lernziele
C25: Sie wissen wie man eine Aufgabe entgegennimmt und ein PDF bearbeitet.
C26: Sie wissen wie man ein Dokument auf OneDrive abspeichert und eine Aufgabe abgiebt.
B28: Hausaufgaben | E28: Administratives
E31: Nächste Woche Taschenrechner mitnehmen!

Sheet ST_2_KW34
B1: Unterrichtsverlauf | E1: =Kompetenzraster!Q7 -> 46255 | G1: 2
B3: Trinkwasser, Eigenschaften & Gewinnung | G3: 1.4
B5: 1 - 3 Lektion | C5: Auftrag 1 | G5: Filme / Theorie
C6: * Einstieg mit Film - Wasser uns seine besonderen Eigenschaften
C7: Auftrag 2
C8: * Spezielle Eigenschaften von Wasser kennen
C9: * Wasserkreislauf & Verteilung auf der Erde
C10: * Durchschnittsverbrauch & Anteile der Apparate im Haushalt
C12: Lernziele
C13: Sie beschreiben die wichtigsten Eigenschaften von Wasser.
C14: Sie können den natürlichen Wasserkreislauf aufzeichnen und erklären.
B15: Pause
B17: Masse und Flächen berechnen | G17: 1.1
B19: 4 - 5 Lektion | C19: Auftrag 1/2/3 | G19: Filme / Theorie
C20: * Der Gebrauch des Taschenrechners & wichtige Funktionen
C21: * Sinn und Zweck der SI - Einheiten & Einheiten umrechnen
C22: * Einheiten umrechnen / Übungen
C24: Lernziele
C25: Sie können den Taschenrechner bedienen kennen die wichtigsten Funktionen.
C26: Sie kennen den Sinn der SI-Einheiten und können Einheiten umrechnen.
B28: Hausaufgaben | E28: Administratives

Sheet ST_3_KW35
B1: Unterrichtsverlauf | E1: =Kompetenzraster!Q9 -> 46262 | G1: 3
B3: Trinkwasser, Eigenschaften & Gewinnung | G3: 1.4
B5: 1 - 3 Lektion | C5: * Einstieg mit Quizacademy | G5: Filme / Theorie
C7: Auftrag 3
C8: * Einstieg und Erklärung der SVGW W3 Norm
C9: * Wichtigste hygienische Grundsätze / Auftrag 3
C10: * Trinkwasserqualität & Trinkwasser bei mir zuhause kennen lernen
C11: Einheit verbessen / Andere Fragen, anders strukturieren / A4 wöre noch nicht nötig
C12: Auftrag 4
C13: * Start eine Lektion mit Auftrag LN "Trinkwassergewinnung"
C15: Lernziele
C16: Sie benennen die gängigen Vorschriften bezüglich Wasserhygiene
C17: Sie beschreiben die Trinkwassergewinnung
B19: Pause
B21: Masse und Flächen berechnen | G21: 1.1
B23: 4 - 5 Lektion | C23: Auftrag 4 | G23: Filme / Theorie
C24: * Umrechnung von Massen aus Plänen
C26: Auftrag 5
C27: * Kennen und verstehen des Meterrisses / Auftrag 5
C29: Hinweis: Praxisaufträge / Idee und Umsetzung
C30: Lernziele
C31: Sie rechnen Masse aus Plänen in Baumasse um.
B34: Hausaufgaben

Sheet ST_4_KW36
B1: Unterrichtsverlauf | E1: =Kompetenzraster!Q11 -> 46269 | G1: 4
B3: Trinkwasser, Eigenschaften & Gewinnung | G3: 1.4
B5: 1 - 3 Lektion | C5: Auftrag 4 | G5: Theorie
C6: * Leistungsnachweis Trinkwassergewinnung A3
C10: Lernziele
C11: Sie beschreiben die drei Arten der Trinkwassergewinnung (Grundwasser, Seewasser, Quellwasser)
B15: Pause
B17: Masse und Flächen berechnen | G17: 1.1
B19: 4 - 5 Lektion | C19: Auftrag 7 | G19: Theorie
C20: * Start mit rechteckiger Flächenberechnung / Formeln herleiten
C21: * Formelbuch (Erklärung / Bedienung / Einsatz)
C22: * Hinweis auf Übungen / selbst. Lernen!
C24: Lernziele
C25: Sie können einfache Längen und Flächen berechnen und umrechnen.
B28: Hausaufgaben

Sheet ST_5_KW37
B1: Unterrichtsverlauf | E1: =Kompetenzraster!Q13 -> 46276 | G1: 5
B3: Trinkwasser, Eigenschaften & Gewinnung | G3: 1.4
B5: 1 - 3 Lektion | C5: * Film: Der Weg des Wassers von der Gewinnung zum Verbraucher | G5: Theorie
C6: * Bearbeitung Auftrag 5 inkl. Besprechung
C7: * Erdverlegte Leitungen im Demoraum betrachten / Stadt Hydranten
C8: * Evtl. Zeit für Vorbereitung Prüfung | G8: Lernziele / Prüfung
C11: Lernziele
C12: Sie beschreiben die Funktionsweise der Wasserversorgung
B15: Pause
B17: Masse und Flächen berechnen | G17: 1.1
B19: 4 - 5 Lektion | C19: Auftrag 8 | G19: Theorie
C20: * Start mit runder Flächenberechnung / Formeln herleiten
C21: * Berechnungen an Beispielen Auftrag 8
C25: Lernziele
C26: Sie können einfache Längen und Flächen berechnen und umrechnen.
B28: Hausaufgaben

Sheet ST_6_KW38
B1: Unterrichtsverlauf | E1: =Kompetenzraster!Q15 -> 46283 | G1: 6
B3: Leitungsmaterialien & Verbindungen | G3: 1.5
B5: 1 - 3 Lektion | C5: Prüfung Auftrag 1.4 | F5: 20min | G5: Theorie
C6: Auftrag 1
C7: * Grundlagen Kunststoff / Verarbeitung Anbohrschelle
C8: * Rohrsysteme aus Kunststoff kennen lernen / Demoraum
C10: Lernziele
C11: Sie beschreiben die Materialeigenschaften der verschiedenen Rohrsysteme aus Kunststoff.
C12: Sie unterscheiden die Systeme für Wasserleitungen nach Material und Verwendungszweck.
C13: Sie benennen die Verbindungen und Dichtungsmaterialien der verschiedenen Installationssysteme.
B15: Pause
B17: Masse und Flächen berechnen | G17: 1.1
B19: 4 - 5 Lektion | C19: Auftrag 9 | G19: Theorie
C20: * Flächenberechnungen üben und Vorbereitung für Prüfung
C21: * Auftrag / Hinweis für Leistungsnachweis
G22: Lernziele / Prüfung
C25: Lernziele
C26: Sie können einfache Längen und Flächen berechnen und umrechnen.
B29: Hausaufgaben

Sheet ST_7_KW39
B1: Unterrichtsverlauf | E1: =Kompetenzraster!Q17 -> 46290 | G1: 7
B3: Leitungsmaterialien & Verbindungen | G3: 1.5
B5: 1 - 3 Lektion | C5: Prüfung Auftrag 1.1 | F5: 45min | G5: Theorie
C6: Auftrag 3
C7: * Einstieg mit Film "Herstellung von Stahlrohren"
C8: * Betrachtung von Stahlrohrsystemen
C9: * Betrachtung von Verbundrohrsystemen
C10: Lernziele
C11: Sie beschreiben die Materialeigenschaften der verschiedenen Rohrsysteme aus Metall.
C12: Sie unterscheiden die Systeme für Wasserleitungen nach Material und Verwendungszweck.
C13: Sie benennen die Verbindungen und Dichtungsmaterialien der verschiedenen Installationssysteme.
B15: Pause
B17: Arbeitssicherheit / Umgang mit Maschinen | G17: 1.3
B19: 4 - 5 Lektion | C19: * Einstieg mit Fotos und Bildern der Baustelle. | G19: Theorie
C20: * PSA kennen lernen und erklären können.
C21: * Cast «Meine persönliche Schutzausrüstung PSA»
C22: * Evtl. schon Einstieg in Elektrotechnik (Stromkreis)
C24: Lernziele
C25: Sie erläutern die Gefahren auf der Baustelle und in der Werkstatt.
B28: Hausaufgaben

Sheet ST_8_KW43
B1: Unterrichtsverlauf | E1: =Kompetenzraster!Q19 -> 46318 | G1: 8
B3: Leitungsmaterialien & Verbindungen | G3: 1.5
B5: 1 - 3 Lektion | C5: Auftrag 4 | G5: Theorie
C6: * Auftrag "Cast" Leitungsmaterialien in unserer Firma
C7: * Einstieg / Sinn und Aufbau Drehbuch
C12: Lernziele
C13: Sie beschreiben die Materialeigenschaften der verschiedenen Rohrsysteme.
C14: Sie unterscheiden die Systeme für Wasserleitungen nach Material und Verwendungszweck.
B15: Pause
B17: Arbeitssicherheit / Umgang mit Maschinen | G17: 1.3
B19: 4 - 5 Lektion | C19: * Einstieg / Repetition mit Grundlagen zum Stromkreis | G19: Theorie
C20: * Erklärung & Herleitung der Begriffe Spannung, Stromstärke und Leistung
C21: * Kennen und Verstehen der Sicherheitseinrichtung Sicherung & FI Schalter
C22: * Abschluss mit GHL Symbole => Vorbereitung Teams Umfrage
C24: Lernziele
C25: Sie erläutern einen einfachen Stromkreislauf.
C26: Sie erläutern die Gefahren von Strom und beschreiben den Personen- und Sachschutz.
B28: Hausaufgaben

Sheet ST_9_KW44
B1: Unterrichtsverlauf | E1: =Kompetenzraster!Q21 -> 46325 | G1: 9
B3: Leitungsmaterialien & Verbindungen | G3: 1.5
B5: 1 - 3 Lektion | C5: Auftrag 5 | G5: Theorie
C6: * Armaturen im Demoraum anschauen und in Gruppen anordnen
C7: * Auftrag fertig machen / Leistungsnachweis "Armaturengruppen"
G8: Lernziele / Prüfung
C11: Lernziele
C12: Sie ordnen die gebräuchlichen Armaturen den Armaturengruppen korrekt zu.
B15: Pause
B17: Grundlagen Fachzeichnen / Isometrie | G17: 1.2
B19: 4 - 5 Lektion | C19: Auftrag 1 & 2 | G19: Theorie
C20: * Wichtige Zeichenmaterialien
C21: * Übungen Normschrift & Linienarten
C22: * Erstellen eines Plankopfes
C24: Lernziele
C25: Sie verstehen die Grundlagen des technischen Zeichnens und können Sie anwenden.
B28: Hausaufgaben
B32: *Hinweis Deadline Prüfungen unterschereiben lassen!

Sheet ST_10_KW45
B1: Unterrichtsverlauf | E1: =Kompetenzraster!Q23 -> 46332 | G1: 10
B3: WAS Leitungsmaterialien & Verbindungen | G3: 1.6
B5: 1 - 3 Lektion | C5: Prüfung Auftrag 1.5 | F5: 30min | G5: Theorie
C6: Auftrag 1 & 2 (bis. Seite 4)
C7: * Einstieg mit Aufgabe (Zuständigkeiten der Gewerke)
C8: * Gemeinsames Herleiten der Bezeichnungen von Medien
C9: * Film - was gehört ins WC? / Min Map Gusseisenwerkstoffe / Demoraum
C10: Lernziele
C11: Sie beschreiben die unterschiedlichen Abwasserarten
C12: Sie beschreiben die Materialien und Werkstoffe, die bei Entsorgungsleitungen eingesetzt werden.
B15: Pause
B17: Grundlagen Fachzeichnen / Isometrie | G17: 1.2
B19: 4 - 5 Lektion | C19: Auftrag 2 & 3 | G19: Theorie
C20: * Gemeinsam Vermassung anschauen
C21: * Übungen zum Thema Vermassung
C22: * Evtl. Arbeit an Leistungsnachweis
C24: Lernziele
C25: Sie verstehen die Grundlagen des technischen Zeichnens und können Sie anwenden.
B28: Hausaufgaben
B34: Deadline Unterschrift Prüfungen!

Sheet ST_11_KW46
B1: Unterrichtsverlauf | E1: =Kompetenzraster!Q25 -> 46339 | G1: 11
B3: WAS Leitungsmaterialien & Verbindungen | G3: 1.6
B5: 1 - 3 Lektion | C5: Auftrag 2/3 (Seite 5/6/7) | G5: Theorie
C6: * Eigenschaften von Thermoplasten (PE/SIL/ Verbindungen im Demoraum)
C7: Auftrag 4 (Seite 6/7/8)
C8: * Video betrachten der Leitungsteile / Bezeichnungen
C9: * Alle Leitungsteile betrachten im Lehrmittel S.40
C10: * Evtl. Zeit für Vorbereitung Leistungsnachweis / Hausaufgabe!
C12: Lernziele
C13: Sie beschreiben die Materialien und Werkstoffe, die bei Entsorgungsleitungen eingesetzt werden.
C14: Sie erläutern die Verbindungsmöglichkeiten der verschiedenen Installationssystemen.
B17: Pause
B19: Grundlagen Fachzeichnen / Isometrie | G19: 1.2
B21: 4 - 5 Lektion | C21: Auftrag 3 & 4 | G21: Theorie
C22: * Repetition Vermassung und vorzeichnen
C23: * Arbeit an Leistungsnachweis
C24: * Schnellere Lernende steigen in die Normprojektion ein
C25: * Übungen zum Thema Normprojektion machen
C26: Lernziele
C27: Sie verstehen die Grundlagen des technischen Zeichnens und können Sie anwenden.
C28: Sie können die drei Ansichten aus der Vorgabe einer Normprojektion erstellen.
B30: Hausaufgaben

Sheet ST_12_KW47
B1: Unterrichtsverlauf | E1: =Kompetenzraster!Q27 -> 46346 | G1: 12
B3: WAS Leitungsmaterialien & Verbindungen | G3: 1.6
B5: 1 - 3 Lektion | C5: Auftrag (Seite 6/7/8) | G5: Theorie
C6: * Einstieg in die Gewichtskraft / Beispiele rechnen
C7: * Verweis auf Masse / Dichte Berechnungen lösen
C8: * Hinweis Leistungsnachweis (Lernkontrolle)
C10: Lernziele
C11: Sie unterscheiden die Systeme von Entsorgungsleitungen nach deren Verwendungszweck
C12: Sie bestimmen geeignete Befestigungen mit Hilfe von Montagehandbüchern
B15: Pause
B17: Grundlagen Fachzeichnen / Isometrie | G17: 1.2
B19: 4 - 5 Lektion | C19: Auftrag 4 | G19: Theorie
C20: * Einstieg / Herleitung Normprojektion
C21: * Übungen zum Thema Normprojektion machen
C24: Lernziele
C25: Sie verstehen die Grundlagen des technischen Zeichnens und können Sie anwenden.
C26: Sie können die drei Ansichten aus der Vorgabe einer Normprojektion erstellen.
B28: Hausaufgaben

Sheet ST_13_KW48
B1: Unterrichtsverlauf | E1: =Kompetenzraster!Q29 -> 46353 | G1: 13
B3: WAS Leitungsmaterialien & Verbindungen | G3: 1.6
B5: 1 - 3 Lektion | C5: Auftrag 5-6 (Seite 9/10/11/12) | G5: Theorie
C6: * Einstieg Quizacademy Bezeichnung Leitungsteile
C7: * Berechnungen in der Gewichtskraft / Beispiele rechnen
C8: * Übungen und Hinweis Lösung Leistungsnachweis | G8: Lernziele / Prüfung
C11: Lernziele
C12: Sie unterscheiden die Systeme von Entsorgungsleitungen nach deren Verwendungszweck
C13: Sie bestimmen geeignete Befestigungen mit Hilfe von Montagehandbüchern
B15: Pause
B17: Grundlagen Fachzeichnen / Isometrie | G17: 1.2
B19: 4 - 5 Lektion | C19: Auftrag 4 | G19: Theorie
C20: * Übungen zum Thema Normprojektion machen
C24: Lernziele
C25: Sie verstehen die Grundlagen des technischen Zeichnens und können Sie anwenden.
C26: Sie können die drei Ansichten aus der Vorgabe einer Normprojektion erstellen.
B28: Hausaufgaben

Sheet ST_14_KW49
B1: Unterrichtsverlauf | E1: =Kompetenzraster!Q31 -> 46360 | G1: 14
B3: Entwässerungsgegenstände | G3: 1.8
B5: 1 - 3 Lektion | C5: Auftrag 1/2/3 | G5: Theorie
C6: * Einstieg im Demoraum / Ablaufventile
C7: * Arbeit an Fragen / Dossier Beantwortung
C8: * Hinweis / Leistungsnachweis
C9: Prüfung Auftrag 1.6 | F9: 20min
C10: Lernziele
C11: Sie kennen die Aufgabe und Funktion von Ablaufventilen und Geruchsverschlüssen bei sanitären Apparaten.
C12: Sie kennen die Hauptgruppen und Eigenschaftenbei sanitären Apparaten.
B15: Pause
B17: Grundlagen Fachzeichnen / Isometrie | G17: 1.2
B19: 4 - 5 Lektion | C19: Auftrag 4 | G19: Theorie
C20: * Übungen zum Thema Normprojektion machen
C21: * Hinweis / Abgabe Leistungsnachweis
C24: Lernziele
C25: Sie verstehen die Grundlagen des technischen Zeichnens und können Sie anwenden.
C26: Sie können die drei Ansichten aus der Vorgabe einer Normprojektion erstellen.
B28: Hausaufgaben

Sheet ST_15_KW50
B1: Unterrichtsverlauf | E1: =Kompetenzraster!Q33 -> 46367 | G1: 15
B3: Entwässerungsgegenstände | G3: 1.8
B5: 1 - 3 Lektion | C5: Auftrag 3 | G5: Theorie
C6: * Einstieg im Demoraum / Spülung WC
C7: * Arbeit an Fragen / Spülkasten / Duofix
C8: * Hinweis / Leistungsnachweis
C10: Lernziele
C11: Sie kennen die unterschiedlichen Spüleinrichtungen bei sanitären Apparaten.
B15: Pause
B17: Grundlagen Fachzeichnen / Isometrie | G17: 1.2
B19: 4 - 5 Lektion | C19: Auftrag 5 | G19: Theorie
C20: * Einstieg / Herleitung Körperisometrie
C21: * Übungen zum Thema Körperisometrie machen
C24: Lernziele
C25: Sie können aus der Vorgabe der drei Ansichten dreisimenionale Körper erstellen.
B28: Hausaufgaben

Sheet ST_16_KW51
B1: Unterrichtsverlauf | E1: =Kompetenzraster!Q35 -> 46374 | G1: 16
B3: Entwässerungsgegenstände | G3: 1.8
B5: 1 - 3 Lektion | C5: Auftrag 4 | G5: Theorie
C6: * Einstieg im Demoraum / Urinoirsteuerung
C7: * Arbeit an Fragen / Spülsysteme / Wasserlose Urinoir
C8: * Zeit für Arbeit an Leistungsnachweisen
C10: Lernziele
B15: Pause
B17: Grundlagen Fachzeichnen / Isometrie | G17: 1.2
B19: 4 - 5 Lektion | C19: Auftrag 5 | G19: Theorie
C20: * Arbeit an Thema "Körperisometrie
C21: * Zeit und Besprechung Leistungsnachweise
G22: Lernziele / Prüfung
C25: Lernziele
C26: Sie können aus der Vorgabe der drei Ansichten dreisimenionale Körper erstellen.
B28: Hausaufgaben

Sheet ST_17_KW52
B1: Unterrichtsverlauf | E1: =Kompetenzraster!Q37 -> 46395 | G1: 17
B3: Abfallentsorgung | G3: 1.9
B5: 1 - 3 Lektion | C5: Auftrag 1/2 | G5: Theorie
C6: * Einstieg => (Lehrmittel Nachhaltigkeit Kapitel 5 / Seite 26 -28) lesen
C7: * Video Theorie schauen (Link auf der Seite / Fragen 1-5 beantworten
C8: * Anschliessend Bericht lesen in Auftrag 1.9 und Fragen 6 - 11 beantorten
C9: * Arbeit an Leistungsnachweis "Entsorgungskonzept meiner Firma"
C10: Lernziele
C11: Sie erklären den organisatorischen Ablauf bei der Entsorgung von Abfällen
C12: Sie benennen die Umweltvorschriften bei der Entsorgung von Abfällen.
B15: Pause
G17: 1.2
B19: 4 - 5 Lektion | C19: Prüfung Auftrag 1.2 | F19: 50min | G19: Theorie
C20: Auftrag 5
C21: * Übungen zur Körperisometrie machen
C22: * Abgabe Leistungsnachweis spätestens heute um 17.20 Uhr!
C24: Lernziele
C25: Sie können aus der Vorgabe der drei Ansichten dreisimenionale Körper erstellen.
B28: Hausaufgaben

Sheet ST_18_KW2
B1: Unterrichtsverlauf | E1: =Kompetenzraster!Q39 -> 46402 | G1: 18
B3: Abfallentsorgung | G3: 1.9
B5: 1 - 3 Lektion | C5: Auftrag 3,4,5 | G5: Theorie
C6: * Einstieg mit Video "Kunststoffe Gefahr für die Umwelt & PET" aus Auftrag
C7: * Übersicht erstellen auf Seite 5 gem. Auftrag
C8: * Video "Asbest" schauen und Fragen 11 -12 machen im Auftrag.
C9: Hinweis Leistungsnachweise 1.9 (Abfallkonzept & Onlineprüfung Asbest)
C10: Lernziele
C11: Sie erläutern den Recycling -Kreislauf und die Gefahren von Sonderabfällen.
B15: Pause
G17: 1.11
B19: 4 - 5 Lektion | C19: Auftrag 1,2 | G19: Theorie
C20: * Einstieg mit Video "Leitungsisometrie" / Erklärung"
C21: * Aufgabe Alpha, Betta und Gamma lösen
C24: Lernziele
C25: Sie erstellen selbstständig Isometriezeichnunen von Leitungsteilen
B28: Hausaufgaben

Sheet ST_19_KW3 
B1: Unterrichtsverlauf | E1: =Kompetenzraster!Q41 -> 46409 | G1: 19
B3: Elektrotechnik | G3: 1.1
B5: 1 - 3 Lektion | C5: * Einstieg mit Beispiel "Phasenprüfer" | G5: Theorie
C6: * Spannung und Stromstärke verstehen
C10: Lernziele
C11: Sie verstehen die Begriffe Stromstärke, Widerstand
C12: Sie verstehen das Ohmsche Gesetz und können einfache Berechnungen dazu ausführen.
B15: Pause
B17: Leitungsisometrie | G17: 1.11
B19: 4 - 5 Lektion | C19: * Einstieg und Erklärung der Leitungsisometrie | G19: Theorie
C20: * Üben und Fertigkeiten trainieren an Beispielen aus Auftrag
C24: Lernziele
C25: * Sie erstellen Isometriezeichnungen aus Grundrissplänen
B28: Hausaufgaben

Sheet ST_20_KW4
B1: Unterrichtsverlauf | E1: =(Kompetenzraster!Q41)+7 -> 46416 | G1: 20
B3: Elektrotechnik | G3: 1.1
B5: 1 - 3 Lektion | C5: * Einstieg mit Beispiel "Phasenprüfer" | G5: Theorie
C6: * Spannung und Stromstärke verstehen
C10: Lernziele
C11: Sie verstehen die Begriffe Stromstärke, Widerstand
C12: Sie verstehen das Ohmsche Gesetz und können einfache Berechnungen dazu ausführen.
B15: Pause
B17: Leitungsisometrie | G17: 1.11
B19: 4 - 5 Lektion | C19: * Einstieg und Erklärung der Leitungsisometrie | G19: Theorie
C20: * Üben und Fertigkeiten trainieren an Beispielen aus Auftrag
C24: Lernziele
C25: * Sie erstellen Isometriezeichnungen aus Grundrissplänen
B28: Hausaufgaben
C31: Alternativ Skitag

Sheet ST_21_KW5
B1: Unterrichtsverlauf | E1: =(Kompetenzraster!Q41)+7 -> 46416 | G1: 20
B3: Elektrotechnik | G3: 1.1
B5: 1 - 3 Lektion | C5: * Einstieg mit p=u*i | G5: Theorie
C6: * Spannung und Stromstärke verstehen
C10: Lernziele
C11: Sie verstehen die Begriffe Stromstärke, Widerstand
C12: Sie verstehen das Ohmsche Gesetz und können einfache Berechnungen dazu ausführen.
B15: Pause
B17: Leitungsisometrie | G17: 1.11
B19: 4 - 5 Lektion | C19: * Einstieg und Erklärung der Leitungsisometrie | G19: Theorie
C20: * Üben und Fertigkeiten trainieren an Beispielen aus Auftrag
C24: Lernziele
C25: * Sie erstellen Isometriezeichnungen aus Grundrissplänen
B28: Hausaufgaben
C31: Alternativ Skitag

Sheet Aufgaben_Teams
B1: Aufgaben Teams
B4: Auftrag 1.1 | C4: Lernziele: - Sie rechnen Masse aus Plänen in Baumasse um. - Sie berechnen Längen- und Höhenmasse. - Sie Sie berechnen den Platzbedarf (Fläche) von Apparaten und Anlagen anhand von Planvorgaben. Abzugebende Leistungsnachweise: - Bestandene elektronische Lernzielkontrolle
B6: Punkte
B7: =Kompetenzraster!N20 -> 2
B15: Auftrag 1.2 | C15: Lernziele: - Sie verstehen die Grundlagen des technischen Zeichnens und können diese anwenden. - Sie können die drei Ansichten aus der Vorgabe einer Normalprojektion erstellen. - Sie können aus der Vorgabe der drei Ansichten dreidimensionale Körper erstellen. Abzugebende Leistungsnachweise: - Abgabe der Fachzeichnung «Beschriftung & Bemassung» - Abgabe der Fachzeichnung «Normprojektion» - Abgabe der Fachzeichnung «Körperisometrie»
B17: Punkte
B18: =Kompetenzraster!N21 -> 3
B30: Auftrag 1.3 | C30: Lernziele: - Sie erläutern die Gefahren auf der Baustelle und in der Werkstatt. - Sie beschreiben, bei welchen Situationen eine getragen werden muss. - Sie erläutern einen einfachen Stromkreislauf. - Sie erläutern die Gefahren von Strom und beschreiben den Personen- und Sachschutz. - Sie kennen die gängigsten Gefahrensymbole. Abzugebende Leistungsnachweise: - Cast «Meine persönliche Schutzausrüstung PSA» - Forms Umfrage «Gefahrensymbole»
B32: Punkte
B33: =Kompetenzraster!N22 -> 1
B44: Auftrag 1.4 | C44: Lernziele: - Sie beschreiben die wichtigsten Eigenschaften von Wasser - Sie benennen die gängigen Vorschriften bezüglich Wasserhygiene - Sie beschreiben die Trinkwassergewinnung - Sie beschreiben die Funktionsweise der Wasserversorgung Abzugebende Leistungsnachweise: - 3 Grafiz zum Thema «Trinkwassergewinnung»
B46: Punkte
B47: =Kompetenzraster!N27 -> 1.5
B55: Auftrag 1.5 | C55: Lernziele: - Sie beschreiben die Materialeigenschaften der verschiedenen Rohrsysteme aus Kunststoff und Metall. - Sie unterscheiden die Systeme für Wasserleitungen nach Material und Verwendungszweck. - Sie benennen die Verbindungen und Dichtungsmaterialien der verschiedenen Installationssysteme. - Sie ordnen die gebräuchlichen Armaturen den Armaturengruppen korrekt zu. - Sie benennen die gängigen Vorschriften bezüglich Wasserhygiene. Abzugebende Leistungsnachweise: - Cast «Leitungsmaterialien in unserer Firma» - A3 Übersicht Armaturengruppen
B57: Punkte
B58: =[1]Kompetenzraster!N14 -> 0
B72: Auftrag 1.6 | C72: Lernziele: - Sie beschreiben die unterschiedlichen Abwasserarten. - Sie beschreiben die Materialien und Werkstoffe, die bei Entsorgungsleitungen eingesetzt werden. - Sie erläutern die Verbindungsmöglichkeiten der verschiedenen Installationssysteme. - Sie unterscheiden die Systeme von Entsorgungsleitungen nach Verwendungszweck. - Sie bestimmen geeignete Befestigungen mit Hilfe von Montagebüchern. Abzugebende Leistungsnachweise: - Leistungsnachweis «Materialien und Verbindungen im Abwasser» - Leistungsnachweis «Bestandene Lernzielkontrolle»
B74: Punkte
B75: =[1]Kompetenzraster!N15 -> 0
B89: Auftrag 1.8 | C89: Lernziele: - Sie beschreiben die gebräuchlichen Entwässerungsgegenstände - Sie kennen die Aufgabe und Funktion von Ablaufventilen und Geruchsverschlüssen bei sanitären Apparaten - Sie kennen die Hauptgruppen und Eigenschaften bei sanitären Apparaten - Sie kennen die unterschiedlichen Spüleinrichtungen bei sanitären Apparaten Abzugebende Leistungsnachweise: - Leistungsnachweis «A3 Übersicht Apparategruppen»
B91: Punkte
B92: =Kompetenzraster!N30 -> 2
B101: Auftrag 1.9 | C101: Lernziele: - Sie erklären den organisatorischen Ablauf bei der Entsorgung von Abfällen - Sie benennen die relevanten Umweltvorschriften im Zusammenhang mit der Vermeidung und Entsorgung von Abfällen - Sie erläutern den Recycling – Kreislauf und die Gefahren von Sonderabfällen. - Sie erläutern die Gefahren von Sonderabfällen. (z.B. Asbest) Abzugebende Leistungsnachweise: - Leistungsnachweis «Abfallkonzept meiner Firma» - Leistungsnachweis «Onlinequiz Asbest erkennen»
B103: Punkte
B104: =Kompetenzraster!N31 -> 2
B114: Auftrag 1.12 | C114: Lernziele: - Sie kennen Ihren Login und können sich in den Portalen der Schule (mygbs / NESA) anmelden. - Sie kennen die Plattform Microsoft Teams und finden darin die wichtigsten Bereiche. - Sie können einen Auftrag runterladen, in OneNote ablegen und barbeiteten. - Sie können einen Leistungsnachweis am korrekten Ort ablegen, bearbeiten und anschliessend in Teams abgeben, Abzugebende Leistungsnachweise: - «ICT-Kompetenzen»
B116: Punkte
B117: =Kompetenzraster!N23 -> 1
