Workbook

Sheet Kompetenzraster
B1: Kompetenzraster 4.Semester Sanitärinstallateur/in EFZ | I1: Semesterstart: | J1: 46426 | K1: Schultag: | L1: Montag
B3: Handlungsfelder und Kompetenzen | M3: Bewertung / Benotung | Q3: Unterichtsplanung 4. Semester
B5: HF 1 | E5: Auftrag 4.1 | G5: Auftrag 4.2 | I5: Auftrag 4.3 | M5: Zeugnisnote | Q5: =J1+0 -> 46426 | R5: Rohrweitenbestimmung Trinkwasser
E6: 4 Schultage (12L) | G6: 6 Schultage (18L) | I6: 3 Schultage (9L) | M6: Die Zeugnisnote setzt sich aus den Leistungsnachweisen und Kompetenzprüfungen zusammen. Die Note aus den Leistungsnachweisen zählt zu ca. 30% an die Zeugnisnote. Alle Noten der Prüfungen zählen zu ca. 60% an die Zeugnisnote. | Q6: 4.6 4.1 | R6: Grundlagen Erdgas inkl. Versorgung
B7: Planen der Arbeiten | E7: Sie interpretieren und unterscheiden einfache Installations- und Schemapläne. (K4) | F7: Sie bestimmen die Rohrweiten von Trinkwasserleitungen anhand der geltenden Vorschriften (vereinfachte Rohrweiten­bestimmung). (K3 | G7: Sie kennen die Grundlagen der X-Mass Methode und wenden diese in einfachen Beispielen an. | H7: Sie erstellen selbstständig einfache X-Mass Vorfabrikationszeichnungen inkl. Rohrlängen und Stückliste. | I7: Sie benennen die Anforderungen an die Apparatemontage. (K1) | J7: Sie bestimmen anhand von Beispielen den Platzbedarf, Achsabstände und Montagehöhen von Apparaten und den zugehörigen Garnituren. (K3) | Q7: =Q5+7 -> 46433 | R7: Rohrweitenbestimmung Trinkwasser
Q8: 4.6 4.1 | R8: Grundlagen Erdgas inkl. Versorgung
Q9: =Q7+7 -> 46440 | R9: Rohrweitenbestimmung Trinkwasser
E10: Sie ordnen die gebräuchlichen Plansymbole korrekt zu. (K1) | I10: Sie erstellen eine Handskizze eines Apparates oder einer Anlage. (K3) | Q10: 4.6 4.1 | R10: Grundlagen Erdgas inkl. Versorgung
Q11: =Q9+7 -> 46447 | R11: Rohrweitenbestimmung Trinkwasser
Q12: 4.6 4.1 | R12: Grundlagen Erdgas inkl. Versorgung
Q13: =Q11+8 -> 46455 | R13: Arbeitsvorbereitung AVOR X-Mass
B14: HF 1 | E14: Auftrag 4.4 | G14: Auftrag 4.5 | I14: Auftrag 4.11 | M14: Leistungsnachweise | Q14: 4.6 4.2 | R14: Grundlagen Erdgas inkl. Versorgung
E15: 3 Schultage (9L) | G15: 1 Schultage (3L) | I15: 0.5 Schultage (3L) | M15: Die Note der Leistungsnachweise entsteht aus den während des Semestes erzielten Punkten. | Q15: =Q13+7 -> 46462 | R15: Arbeitsvorbereitung AVOR X-Mass
B16: Planen der Arbeiten | E16: Sie beschreiben die für Vorwände relevanten Inhalte der Schallschutznorm und Brandschutzvorschriften. (K2) | F16: Sie erstellen anhand von Planunterlagen einen Werkstattplan für eine Vorwand. (K3) | G16: Sie berechnen rechtwinklige Dreiecke. (K3) | I16: Sie berechnen und bestimmen das Gefälle von Entsorgungsleitungen. | J16: Sie bestimmen die Rohrweiten von Trinkwasserleitungen anhand der geltenden Vorschriften. | Q16: 4.7 4.2 | R16: Montage von Erdgasleitungen
G17: Sie können mit Hilfe von Unterlagen Abzweig - Bogen Kombinationen in Schmutzwasserinstallationen bestimmen | H17: Sie können mit Hilfe von Unterlagen den seitlichen Versatz in Schmutzwasserinstallationen unter Berücksichtigung des Gefälles bestimmen. | Q17: =Q15+7 -> 46469 | R17: Arbeitsvorbereitung AVOR X-Mass
Q18: 4.7 4.2 | R18: Montage von Erdgasleitungen
I19: Sie berechnen den Druck unter Berücksichtigung der Kompressibilität des Wassers. | J19: Sie interpretieren einfache Montage- und Einlegepläne für die Installation von Wasserleitungen. | M19: Planen der Arbeiten | Q19: =Q17+7 -> 46476 | R19: Arbeitsvorbereitung AVOR X-Mass
M20: Auftrag 4.1 | N20: 3 | Q20: 4.7 4.2 | R20: Montage von Erdgasleitungen
M21: Auftrag 4.2 | N21: 3 | Q21: =Q19+7 -> 46483 | R21: Arbeitsvorbereitung AVOR X-Mass
M22: Auftrag 4.3 | N22: 3 | Q22: 4.7 4.2 | R22: Montage von Erdgasleitungen
B23: HF 3 | E23: Auftrag 4.6 | H23: Auftrag 4.7 | M23: Auftrag 4.4 | N23: 2 | Q23: =Q21+21 -> 46504 | R23: Arbeitsvorbereitung AVOR X-Mass
E24: 5 Schultage (10L) | H24: 4 Schultage (8L) | M24: Auftrag 4.5 | N24: 1 | Q24: 4.8 4.2 | R24: Fallleitungen, Entlüftung und Sammelleitung
B25: Montieren von Sanitäranlagen | E25: Sie erklären die Erdgasgewinnung. (K2) | F25: Sie beschreiben die verschiedenen Gasarten. (K2) | G25: Sie erläutern die Bedingungen, wie es zu einem Brand oder einer Explosion kommen kann. (K2) | H25: Sie unterscheiden die Systeme für Erdgasleitungen nach Material und Verwendungszweck. (K4) | I25: Sie benennen die Vorschriften für die Befestigung von Erdgasleitungen. (K1) | M25: Auftrag 4.11 | N25: 1 | Q25: =Q23+7 -> 46511 | R25: Arbeitsvorbereitung AVOR X-Mass
M26: Total Punkte | N26: =SUM(N20:O25) -> 13 | Q26: 4.8 4.3 | R26: Fallleitungen, Entlüftung und Sammelleitung
Q27: =Q25+7 -> 46518 | R27: Planung und Einteilung von Apparaten
E28: Sie beschreiben die Funktionsweise der Erdgasversorgung. (K2) | F28: Sie beschreiben die wichtigsten Eigenschaften von Gas. (K2) | H28: Sie erläutern die Vorschriften zur Ausser­betriebnahme von Erdgasleitungen. (K2) | I28: Sie erklären den Zweck und die Funktion verschiedener Armaturen für Erdgasleitungen. | M28: Mont. von Sanitäranlagen | Q28: 4.8 4.3 | R28: Fallleitungen, Entlüftung und Sammelleitung
M29: Auftrag 4.6 | N29: 3 | Q29: =Q27+7 -> 46525 | R29: Planung und Einteilung von Apparaten
M30: Auftrag 4.7 | N30: 2 | Q30: 4.8 4.3 | R30: Fallleitungen, Entlüftung und Sammelleitung
M31: Auftrag 4.8 | N31: 3 | Q31: =Q29+7 -> 46532 | R31: Planung und Einteilung von Apparaten
B32: HF 4 | E32: Auftrag 4.8 | G32: Auftrag 4.9 | J32: Auftrag 4.10 | M32: Auftrag 4.9 | N32: 2 | Q32: 4.9 4.4 | R32: Ausdehnung & Befestigungspunkte
E33: 4 Schultage (8L) | G33: 3 Schultage (6L) | J33: 1 Schultag (3L) | M33: Auftrag 4.10 | N33: 3 | Q33: =Q31+7 -> 46539 | R33: Planung von Vorwänden
B34: Montieren von Sanitäranlagen | E34: Sie beschreiben die Inhalte der geltenden Vorschriften in Bezug auf die Installation von Entsorgungsleitungen. (K2) | G34: Sie erläutern die Problematik der Ausdehnung von Entsorgungsleitungen. (K2) | H34: Sie bestimmen die Ausdehnung von Entsorgungsleitungen anhand von Montagehand-büchern. (K3) | I34: Sie bestimmen geeignete Leitungs-befestigungen mit Hilfe von Montage-hand¬büchern (z.B. Ausdehnung, Rohr-schellentyp). (K1) | J34: Exkursion Geberit | M34: Total Punkte | N34: =SUM(N29:O33) -> 13 | Q34: 4.9 4.4 | R34: Ausdehnung & Befestigungspunkte
Q35: =Q33+7 -> 46546 | R35: Planung von Vorwänden
Q36: 4.9 4.4 | R36: Ausdehnung & Befestigungspunkte
G37: Sie unterscheiden Rohrbefestigungen für verschiedene Bauuntergründe. (K4) | J37: QV Woche | Q37: =Q35+7 -> 46553 | R37: Exkursion Geberit
Q38: 4.1
Q39: =Q37+7 -> 46560 | R39: Berechnung Überkröpfung AVOR X -Mass
Q40: 4.5 4.10 | R40: Vernetzendes Projekt
Q41: =Q39+7 -> 46567 | R41: Besprechung Zeugnis
Q42: =Q41+7 -> 46574 | R42: Exkursion
...

Sheet ST_1_KW_6
B1: Unterrichtsverlauf | E1: =Kompetenzraster!Q5 -> 46426 | G1: 1
B3: Grundlagen Erdgas | F3: 4.6 | G3: Filme / Theorie
B5: 1 - 2 Lektion
C6: Einstieg
C7: * Film "Sanierung bestehende Heizung"
C8: * Was wisst ihr alles über Erdgas?
C9: => sanitärbezogen / politisch / Technisch
C11: Auftrag 1
C12: * Einstieg mit Lehrmittel
C13: * Erstellung MindMap "Fakten und Grundlagen"
C15: Lernziele
C16: * Sie beschreiben die verschiedenen Gasarten.
C17: * Sie beschreiben die wichtigsten Eigenschaften von Erdgas.
B18: Pause
B20: Rohrweitenbestimmung Wasser | F20: 4.1 | G20: Filme / Theorie
B22: 3 - 5 Lektion
C23: Auftrag 1
C24: * Einstieg mit Gruppendiskussion
C25: * Gemeinsamer Versuch im Demoraum "Druckverust"
C27: Auftrag 2
C28: * Gemeinsames lösen mit der Anleitung
C29: * Erste einfachere Beispiele lösen
C31: Lernziele
C32: * Sie bestimmen die Rohrweiten von Trinkwasserleitungen anhand
C33: der geltenden Vorschriften.
C34: * Sie interpretieren einfache Installations- und Schemapläne.
C35: * Sie ordnen die gebräuchlichen Plansymbole korrekt zu.
B36: Hausaufgaben | E36: Administratives

Sheet ST_2_KW_7
B1: Unterrichtsverlauf | E1: =Kompetenzraster!Q7 -> 46433 | G1: 2
B3: Grundlagen Erdgas | F3: 4.6 | G3: Filme / Theorie
B5: 1 - 2 Lektion
C6: Auftrag 2
C7: * Einstieg mit Schlagzeile / Unfall mit CO!
C8: * Versuch / Verbrennung Gase / Feste Stoffe
C9: * Erarbeitung Theorie Fragen 6-8
C10: * Versuch vollständige und unvollständige Verbrennung
C11: * Erarbeitung Theorie Fragen 9-11
C12: * Evtl. 1.Mal Zeit für Arbeit an LN
C14: Lernziele
C15: * Sie erläutern die Bedingungen, wie es zu einem Brand oder einer Explosion kommen kann.
B18: Pause
B20: Rohrweitenbestimmung Wasser | F20: 4.1 | G20: Filme / Theorie
B22: 3 - 5 Lektion
C23: Auftrag 4
C24: * Komplexeres, grösseres Beispiel (EFH zusammen lösen)
C31: Lernziele
C32: * Sie bestimmen die Rohrweiten von Trinkwasserleitungen anhand
C33: der geltenden Vorschriften.
C34: * Sie interpretieren einfache Installations- und Schemapläne.
C35: * Sie ordnen die gebräuchlichen Plansymbole korrekt zu.
B36: Hausaufgaben | E36: Administratives

Sheet ST_3_KW_8
B1: Unterrichtsverlauf | E1: =Kompetenzraster!Q9 -> 46440 | G1: 3
B3: Grundlagen Erdgas | F3: 4.6 | G3: Filme / Theorie
B5: 1 - 2 Lektion
C6: Auftrag 3
C7: * Repetition der Aufträge 1 & 2
C8: * Ausführung Expertenpuzzle zum Thema
C10: Auftrag 4
C11: * Der Weg des Gases bis ins Haus
C12: * Zeit für Arbeit an LN
C14: Lernziele
C15: * Voraussetzungen für dieVerbrennung von Erdgas kennen
C16: * Unterschied zwischen Explosion und Verbrennung kennen
C17: * Die Gefahren der unvollständigen Verbrennung kennen
B18: Pause
B20: Rohrweitenbestimmung Wasser | F20: 4.1 | G20: Filme / Theorie
B22: 3 - 5 Lektion
C23: Auftrag 4
C24: * Aufgabe EFH Carlotta
C25: * Aufgabe EFH Dilaria
C31: Lernziele
C32: * Sie bestimmen die Rohrweiten von Trinkwasserleitungen anhand
C33: der geltenden Vorschriften.
C34: * Sie interpretieren einfache Installations- und Schemapläne.
C35: * Sie ordnen die gebräuchlichen Plansymbole korrekt zu.
B36: Hausaufgaben | E36: Administratives

Sheet ST_4_KW_9
B1: Unterrichtsverlauf | E1: =Kompetenzraster!Q19 -> 46476 | G1: 4
B3: Grundlagen Erdgas | F3: 4.6 | G3: Filme / Theorie
B5: 1 - 2 Lektion
C6: Auftrag 5
C7: * Einstieg mit Demoraum / Arbeit an Fragen zum Thema
C8: * Gemeinsames Aufzeichnen des Hausanschlusses
C9: * Zeit für Arbeit an LN
G11: Lernziele / Prüfung
C14: Lernziele
C15: * Sie erklären die Erdgasgewinnung.
C16: * Sie beschreiben die Funktionsweise der Erdgasversorgung.
B18: Pause
B20: Rohrweitenbestimmung Wasser | F20: 4.1 | G20: Filme / Theorie
B22: 3 - 5 Lektion
C23: Auftrag 4
C24: * Aufgabe EFH Esther
C25: * Zeit für Arbeit an Leistungsnachweis
G28: Lernziele / Prüfung
C31: Lernziele
C32: * Sie bestimmen die Rohrweiten von Trinkwasserleitungen anhand
C33: der geltenden Vorschriften.
C34: * Sie interpretieren einfache Installations- und Schemapläne.
C35: * Sie ordnen die gebräuchlichen Plansymbole korrekt zu.
B36: Hausaufgaben | E36: Administratives

Sheet ST_5_KW_10
B1: Unterrichtsverlauf | E1: =Kompetenzraster!Q13 -> 46455 | G1: 5
B3: Grundlagen Erdgas | F3: 4.6 | G3: Filme / Theorie
B5: 1 - 2 Lektion
C6: Prüfung Auftrag 4.6 | F6: 25 min
C8: Prüfung Auftrag 4.1 | F8: 40 min
C11: Nach Kurzpause Wechsel in AVOR
C14: Lernziele
B18: Pause
B20: Grundlagen AVOR X-Mass | F20: 4.2 | G20: Filme / Theorie
B22: 3 - 5 Lektion | C22: Auftrag 1
C23: * Einstieg mit Herleitung Logik / AVOR X-Mass
C24: * Übungen zur Suche von X-Massen in den Unterlagen / Aufgaben 1-3
C25: * Herleitung zum Sinn des 055 Formstückes
C26: * Übbungen zum schneiden des 055 Formstückes / Aufgaben 4 -7
C28: Auftrag 2
C29: * Eintieg mit Übung zur Berechnung von Gefälle
C30: * Übungen zur Berechnung lösen
C31: Lernziele
C32: * Sie kennen die Grundlagen der X-Mass Methode und wenden
C33: diese in einfachen Beispielen an.
B36: Hausaufgaben | E36: Administratives

Sheet ST_6_KW_11
B1: Unterrichtsverlauf | E1: =Kompetenzraster!Q13 -> 46455 | G1: 6
B3: Montageregeln Erdgas | F3: 4.7 | G3: Filme / Theorie
B5: 1 - 2 Lektion
C6: Gemeinsamer Einstieg
C7: * Bild Gasexplosion Bremerhaven
C8: * Gruppeneinteilung & Start Vorbereitung Vortrag
C14: Lernziele
C15: * Sie unterscheiden die Systeme für Erdgasleitungen nach Material und Verwendungszweck.
C16: * Sie benennen die Vorschriften für die Befestigung von Erdgasleitungen.
C17: * Sie erklären den Zweck und die Funktion verschiedener Armaturen für Erdgasleitungen.
B18: Pause
B20: Grundlagen AVOR X-Mass | F20: 4.2 | G20: Filme / Theorie
B22: 3 - 5 Lektion
C23: Auftrag 2
C24: * Eintieg mit Aufgabe zur Berechnung von Gefälle
C26: Auftrag 3
C27: * Erste gemeinsame Aufgabe lösen.
C28: * Aufgabe 6.5 Bodenklosett lösen (evtl. als Hausaufgabe)
C31: Lernziele
C32: * Sie kennen die Grundlagen der X-Mass Methode und wenden
C33: diese in einfachen Beispielen an.
B36: Hausaufgaben | E36: Administratives

Sheet ST_7_KW_12
B1: Unterrichtsverlauf | E1: =Kompetenzraster!Q17 -> 46469 | G1: 7
B3: Montageregeln Erdgas | F3: 4.7 | G3: Filme / Theorie
B5: 1 - 2 Lektion
C6: Gemeinsamer Einstieg
C7: * Arbeit an Vorträgen
C8: * Fragen klären & Hilfestellung
C14: Lernziele
C15: * Sie unterscheiden die Systeme für Erdgasleitungen nach Material und Verwendungszweck.
C16: * Sie benennen die Vorschriften für die Befestigung von Erdgasleitungen.
C17: * Sie erklären den Zweck und die Funktion verschiedener Armaturen für Erdgasleitungen.
B18: Pause
B20: Grundlagen AVOR X-Mass | F20: 4.2 | G20: Filme / Theorie
B22: 3 - 5 Lektion
C23: Auftrag 4
C24: * Aufgabe 6.6 Reservestutzen
C25: * Aufgabe 6.7 Duschwannenanschluss
C31: Lernziele
C32: * Sie kennen die Grundlagen der X-Mass Methode und wenden
C33: diese in einfachen Beispielen an.
B36: Hausaufgaben | E36: Administratives

Sheet ST_8_KW_13
B1: Unterrichtsverlauf | E1: =Kompetenzraster!Q19 -> 46476 | G1: 8
B3: Montageregeln Erdgas | F3: 4.7 | G3: Filme / Theorie
B5: 1 - 2 Lektion
C6: Gemeinsamer Einstieg
C7: * 1. Etappe der Vorträge
C8: * Thema 1 / Hausinstallation bis zum Zähler & Rohrwerkstoffe
C9: * Quizacademy / Themeblock 1
C10: * Thema 2 / Montageregeln für Erdgasleitungen
C11: * Bearbeitung der Fragen im Dossier
C12: * Quizacademy / Themeblock 2
C14: Lernziele
C15: * Sie unterscheiden die Systeme für Erdgasleitungen nach Material und Verwendungszweck.
C16: * Sie benennen die Vorschriften für die Befestigung von Erdgasleitungen.
C17: * Sie erklären den Zweck und die Funktion verschiedener Armaturen für Erdgasleitungen.
B18: Pause
B20: Grundlagen AVOR X-Mass | F20: 4.2 | G20: Filme / Theorie
B22: 3 - 5 Lektion
C23: Auftrag 4
C24: * Aufgabe 6.8 | D24: Achsverschiebung
C25: * Aufgabe 6.9 | D25: Pe - WC Anschluss
C31: Lernziele
C32: * Sie kennen die Grundlagen der X-Mass Methode und wenden
C33: diese in einfachen Beispielen an.
B36: Hausaufgaben | E36: Administratives

Sheet ST_9_KW_14
B1: Unterrichtsverlauf | E1: =Kompetenzraster!Q21+3 -> 46486 | G1: 9
B3: Montageregeln Erdgas | F3: 4.7 | G3: Filme / Theorie
B5: 1 - 3 Lektion
C6: Auftrag 2
C7: * Repetition Bilder Stadtwerke zu Thema 1&2
C8: * Vortrag Thema 3 / Bearbeitung Fragen aus Dossier
C9: * Vortrag Thema 4 / Bearbeitung Fragen aus Dossier
C11: Auftrag 3 | G11: Lernziele / Prüfung
C12: * Leistungsnachweis zur Vertiefung
C14: Lernziele
C15: * Sie unterscheiden die Systeme für Erdgasleitungen nach Material und Verwendungszweck.
C16: * Sie benennen die Vorschriften für die Befestigung von Erdgasleitungen.
C17: * Sie erklären den Zweck und die Funktion verschiedener Armaturen für Erdgasleitungen.
B18: Pause
B20: Grundlagen AVOR X-Mass | F20: 4.2 | G20: Filme / Theorie
B22: 4 - 5 Lektion
C23: Auftrag 5
C24: * Spezialfälle anhand von Aufgabe in Auftrag
C25: * Aufgabe 6.10 | D25: Zwischenetage
C26: * Zusatzaufgaben für Prüfungsvorbereitung
C31: Lernziele
C32: * Sie kennen die Grundlagen der X-Mass Methode und wenden
C33: diese in einfachen Beispielen an.
B36: Hausaufgaben | E36: Administratives

Sheet ST_10_KW_17
B1: Unterrichtsverlauf | E1: =Kompetenzraster!Q23 -> 46504 | G1: 10
B3: Installieren von Fallleitungen | F3: 4.8 | G3: Filme / Theorie
B5: 1 - 3 Lektion | C5: Prüfung Auftrag 4.7 | F5: 25 min
C7: Auftrag 1
C8: * Einstieg mit Lehrmittel (Erarbeitung Theorie)
C9: * Fragen im Dossier bearbeiten / Details erklären
C14: Lernziele
C15: * Sie beschreiben die Inhalte der aktuellen Vorschriften in Bezug auf
C16: die Installation von Entsorgungsaleitungen.
B18: Pause
B20: Grundlagen AVOR X-Mass | F20: 4.2 | G20: Filme / Theorie
B22: 4 - 5 Lektion
C23: Auftrag 4
C24: * Aufgabe 6.10 | D24: Zwischenetage
C25: * Zusatzaufgaben für Prüfungsvorbereitung
G28: Lernziele / Prüfung
C31: Lernziele
C32: * Sie kennen die Grundlagen der X-Mass Methode und wenden
C33: diese in einfachen Beispielen an.
B36: Hausaufgaben | E36: Administratives

Sheet ST_11_KW_18
B1: Unterrichtsverlauf | E1: =Kompetenzraster!Q25 -> 46511 | G1: 11
B3: Installieren von Fallleitungen | F3: 4.8 | G3: Filme / Theorie
B5: 1 - 3 Lektion
C6: Auftrag 1
C7: * Fragen 5 & 6 im Plenum beantworten und besprechen
C8: * Fragen 7 -10 in Einzelarbeit lösen und besprechen
C10: Auftrag 2
C11: * Selbstständiges Erstellen einer MindMap zum Thema Entlüftung
C14: Lernziele
C15: * Sie beschreiben die Inhalte der aktuellen Vorschriften in Bezug auf
C16: die Installation von Entsorgungsaleitungen.
B18: Pause
B20: Grundlagen AVOR X-Mass | F20: 4.2 | G20: Filme / Theorie
B22: 4 - 5 Lektion
C23: * Zeit für Prüfungsvorbereitung
C25: Prüfung Auftrag 4.2 | F25: 45 min
C31: Lernziele
C32: * Sie kennen die Grundlagen der X-Mass Methode und wenden
C33: diese in einfachen Beispielen an.
B36: Hausaufgaben | E36: Administratives

Sheet ST_12_KW_19
B1: Unterrichtsverlauf | E1: =Kompetenzraster!Q27 -> 46518 | G1: 12
B3: Installieren von Fallleitungen | F3: 4.8 | G3: Filme / Theorie
B5: 1 - 3 Lektion
C6: Auftrag 2
C7: * Einstieg mit Quizacademy "Fallleitungen"
C8: * Einstieg in handlungsorientierte Übungen
C14: Lernziele
C15: * Sie beschreiben die Inhalte der aktuellen Vorschriften in Bezug auf
C16: die Installation von Entsorgungsaleitungen.
B18: Pause
B20: Planung von Apparaten | F20: 4.3 | G20: Filme / Theorie
B22: 4 - 5 Lektion
C23: Auftrag 2
C24: * Übung 1 gemeinsam starten
C25: * Skizze einer Apparateplanung erstellen
C26: * Exakte Planung erstellen / Ansicht & Grundriss
C31: Lernziele
C32: * Sie bestimmen anhand von Beispielen den Platzbedarf, Achsabstände
C33: und Montagehöhen von Apparaten und den zugehörigen Garnituren.
C34: * Sie erstellen eine Handskizze eines Apparates oder einer Anlage.
B36: Hausaufgaben | E36: Administratives

Sheet ST_13_KW_20
B1: Unterrichtsverlauf | E1: =Kompetenzraster!Q29 -> 46525 | G1: 13
B3: Installieren von Fallleitungen | F3: 4.8 | G3: Filme / Theorie
B5: 1 - 3 Lektion
C6: Auftrag 2
C7: * Einstieg mit Korrektur Übung 2
C8: * Hinweis & Abgabe Leistungsnachweis
C9: * Hinweis zus. Übungen für Prüfungen
C10: * Hinweis Prüfung / Lernziele…
G11: Lernziele / Prüfung
C14: Lernziele
C15: * Sie beschreiben die Inhalte der aktuellen Vorschriften in Bezug auf
C16: die Installation von Entsorgungsaleitungen.
B18: Pause
B20: Planung von Apparaten | F20: 4.3 | G20: Filme / Theorie
B22: 4 - 5 Lektion
C23: Auftrag 2
C24: * Übung 2 selbstständig lösen
C25: * Exakte Planung erstellen / Ansicht & Grundriss
C31: Lernziele
C32: * Sie bestimmen anhand von Beispielen den Platzbedarf, Achsabstände
C33: und Montagehöhen von Apparaten und den zugehörigen Garnituren.
C34: * Sie erstellen eine Handskizze eines Apparates oder einer Anlage.
B36: Hausaufgaben | E36: Administratives

Sheet ST_14_KW_21
B1: Unterrichtsverlauf | E1: =Kompetenzraster!Q31 -> 46532 | G1: 14
B3: Ausdehnung Entsorgungsleitungen | F3: 4.9 | G3: Filme / Theorie
B5: 1 - 3 Lektion | C5: Prüfung Auftrag 4.8 | F5: 25 min
C7: Einstieg
C8: * Gruppenarbeit Vorwissen Ausdehnung Entsorgungsleitungen
C9: * Herleitung Formeln für die Berechnung / Versuch
C10: * Formeln notieren & erste 3 Beispiele rechnen
C14: Lernziele
C15: * Sie erläutern die Problematik der Ausdehnung von Entsorgungsleitungen.
C16: * Sie bestimmen die Ausdehnung von Entsorgungsleitungen anhand von Montagebüchern.
B18: Pause
B20: Planung von Apparaten | F20: 4.3 | G20: Filme / Theorie
B22: 4 - 5 Lektion
C23: Auftrag 2
C24: * Übung 2 selbstständig lösen
C25: * Zeit für Arbeit an Leistungsnachweis
C31: Lernziele
C32: * Sie bestimmen anhand von Beispielen den Platzbedarf, Achsabstände
C33: und Montagehöhen von Apparaten und den zugehörigen Garnituren.
C34: * Sie erstellen eine Handskizze eines Apparates oder einer Anlage.
B36: Hausaufgaben | E36: Administratives

Sheet ST_15_KW_22
B1: Unterrichtsverlauf | E1: =Kompetenzraster!Q33 -> 46539 | G1: 15
B3: Ausdehnung Entsorgungsleitungen | F3: 4.9 | G3: Filme / Theorie
B5: 1 - 3 Lektion
C6: Einstieg
C7: * Aufgaben 1- 3 kontrollieren und Aufgaben rechnen.
C8: * 3-4 Übungen rechnen / Hinweise für Lösungen
C10: Auftrag 3
C11: * Einstieg in die Theorie Regeln der Montage / Bis Aufg. 11
C14: Lernziele
C15: * Sie bestimmen die Ausdehnung von Entsorgungsleitungen anhand von Montagebüchern.
C16: * Sie bestimmen geeignete Leitungsbefestigungen mit Hilfe von Montagehandbüchern.
B18: Pause
B20: Planung von Vorwänden | F20: 4.4 | G20: Filme / Theorie
B22: 4 - 5 Lektion
C23: Auftrag 1
C24: * Einstieg in die Planung von Vorwänden / Grundlagen
C25: * Gemeinsames Planen mit der Geberit App
C26: * Beispiele 1-3 lösen und besprechen
C31: Lernziele
C32: * Sie beschreiben die für Vorwände relevanten Inhalte der
C33: Schallschutznorm und Brandschutzvorschriften.
C34: * Sie erstellen anhand von Planunterlagen einen Werkstattplan
C35: für eine Vorwand.
B36: Hausaufgaben | E36: Administratives

Sheet ST_16_KW_23
B1: Unterrichtsverlauf | E1: =Kompetenzraster!Q35 -> 46546 | G1: 16
B3: Ausdehnung Entsorgungsleitungen | F3: 4.9 | G3: Filme / Theorie
B5: 1 - 3 Lektion
C6: Auftrag 3
C7: *Praxisorientierte Beispiele 12- 16 lösen.
C8: Auftrag 4
C9: Abgabe und Arbeit am Leistungsnachweis
C14: Lernziele
C15: * Sie bestimmen die Ausdehnung von Entsorgungsleitungen anhand von Montagebüchern.
C16: * Sie bestimmen geeignete Leitungsbefestigungen mit Hilfe von Montagehandbüchern.
B18: Pause
B20: Planung von Vorwänden | F20: 4.4 | G20: Filme / Theorie
B22: 4 - 5 Lektion
C23: Auftrag 2
C24: * Beispiele 4-6 lösen und besprechen
C25: * Gemeinsames Planen mit der Geberit App
C26: - Abgabe und Arbeit am Leistungsnachweis
C31: Lernziele
C32: * Sie beschreiben die für Vorwände relevanten Inhalte der
C33: Schallschutznorm und Brandschutzvorschriften.
C34: * Sie erstellen anhand von Planunterlagen einen Werkstattplan
C35: für eine Vorwand.
B36: Hausaufgaben | E36: Administratives

Sheet ST_17_KW_24
B1: Unterrichtsverlauf | E1: =Kompetenzraster!Q37 -> 46553 | G1: 17
B3: Exkursion Geberit | F3: 4.1 | G3: Filme / Theorie
B5: ganzer Tag
C6: Anreise individuell
C8: Adresse: | D8: Geberit GIZ
D9: Schachenstrasse 77
D10: 8645 Jona
C30: Besammlung 08.20 Uhr
C44: Lernziele
C45: * Sie beschreiben die Inhalte der aktuellen Vorschriften in Bezug
C46: auf die Installation von Entsorgungsleitungen.
C47: * Sie beschreiben Einsatzgebiete, und Eigenschaften der Dämmmaterialien für Entsorgungsleitungen.
C48: * Sie beschreiben die handelsüblichen Vorwandsysteme.

Sheet ST_18_KW_25
B1: Unterrichtsverlauf | E1: =ST_17_KW_24!E1+7 -> 46560 | G1: 18
B3: Berechnung Verschränkungen | F3: 4.5 | G3: Filme / Theorie
B5: 4 - 5 Lektion
C6: Auftrag 1
C7: *Herleitung Theorie mit Montagehelfer
C8: Auftrag 2
C9: *Einfache angewandte Aufgaben in Auftrag lösen
C10: Auftrag 3
C11: *Leistungsnachweis - Situationen auf dem Bau lösen
C13: Lernziele
C14: * Sie berechnen rechtwinklige Dreiecke. (K3)
C15: * Sie können mit Hilfe von Unterlagen Abzweig - Bogen Kombinationen bestimmen.
C16: * Sie können mit Hilfe von Unterlagen den seitlichen Versatz in Schmutzwasserinstallationen
C17: unter Berücksichtigung des Gefälles bestimmen.
B18: Pause
B20: Planung von Vorwänden | F20: 4.4 | G20: Filme / Theorie
B22: 4 - 5 Lektion | C22: Leistungsnachweis
C23: - Abgabe und Arbeit am Leistungsnachweis
C27: Einstieg & Vorbereitung Projektarbeit
C28: Phase 1
C29: * Gruppeneinteilung / max 2-3 Personen
C30: *Arbeitsteilung innerhalb der Gruppe
C31: Lernziele
C32: * gemäss Aufgabenbeschrieb Projekt
B36: Hausaufgaben | E36: Administratives

Sheet ST_19_KW_26
B1: Unterrichtsverlauf | E1: =Kompetenzraster!Q41 -> 46567 | G1: 19
B3: Vernetzendes Abschlussprojekt | F3: 4.11 | G3: Filme / Theorie
B5: 1 - 3 Lektion | C5: Einstieg
C6: Hinweise zur Erstellung verschiedener Medien in einem Projekt
C8: Phase 2
C9: *Arbeiten an den Teilaufgaben inkl. Besprechungen
C11: Phase 3
C12: *Zusammenführung und Abgabe
C13: Lernziele
C14: * gemäss Aufgabenbeschrieb Projekt
B18: Pause
B20: Vernetzendes Abschlussprojekt | F20: 4.11 | G20: Filme / Theorie
B22: 4 - 5 Lektion | C22: Phase 2
C23: *Arbeiten an den Teilaufgaben inkl. Besprechungen
C25: Phase 3
C26: *Zusammenführung und Abgabe
C29: Zeugnisbesprechung
C31: Lernziele
C32: * Sie erklären die Funktionsweise der Abwassereinigungsanlage.
B36: Hausaufgaben | E36: Administratives

Sheet ST_19_KW_4
B1: Unterrichtsverlauf | E1: =Kompetenzraster!Q42 -> 46574 | G1: 20
B3: Exkursion Erdgas
B5: 1 - 5 Lektion
C10: 09.30 Uhr Pause
C12: 09.50 Besammlung beim Brunnen
C13: * Wanderung zur Einstigegsstelle "Stollen"
C14: 10.15 Einstieg & Besichtigung Verteilstation
C15: * Kurze Wanderung durch den Stollen. (Kleider!)
C16: 10.45 Besichtigung Leitwarte / Stadwerke
C26: Lernziele
C27: * Sie erklären die Erdgasgewinnung
C28: * Sie beschreiben die Funktionsweise der Erdgasversorgung. (K2)
C29: * Sie erklären den Zweck und die Funktion verschiedener Armaturen für Erdgasleitungen.
B30: Hausaufgaben | E30: Administratives

Sheet Aufgaben_Teams
B1: Aufgaben Teams
B4: Auftrag 4.1 | C4: Lernziele: - Sie bestimmen die Rohrweiten von Trinkwasserleitungen anhand der geltenden Vorschriften. - Sie interpretieren und unterscheiden einfache Installations und Schemapläne. - Sie ordnen die gebräuchlichen Plansymbole korrekt zu. Abzugebende Leistungsnachweise: - Leistungsnachweis «Dimensionierung»
B6: Punkte
B7: 2
B8: Zuweisung
B9: =Kompetenzraster!Q5 -> 46426
B10: Abgabe
B11: =Kompetenzraster!Q13-1 -> 46454
B17: Auftrag 4.2 | C17: Lernziele: - Sie kennen die Grundlagen der X-Mass Methode und wenden diese in einfachen Beispielen an. - Sie erstellen selbstständig einfache X-Mass Vorfabrikationszeichnungen inkl. Rohrlängen und Stückliste. Abzugebende Leistungsnachweise: - Leistungsnachweis "AVOR X-Mass " - Abgabe von drei korrigierten Fachzeichnungen
B19: Punkte
B20: 3
B21: Zuweisung
B22: =Kompetenzraster!Q13 -> 46455
B23: Abgabe
B24: =Kompetenzraster!Q21-1 -> 46482
B30: Auftrag 4.3 | C30: Lernziele: - Sie benennen die Anforderungen an die Apparatemontage. - Sie bestimmen anhand von Beispielen den Platzbedarf, Achsabstände und Montagehöhen von Apparaten und den zugehörigen Garnituren. - Sie erstellen eine Handskizze eines Apparates oder einer Anlage. Abzugebende Leistungsnachweise: - Leistungsnachweis "Detailplanung Badezimmer"
B32: Punkte
B33: =Kompetenzraster!#REF! -> #REF!
B34: Zuweisung
B35: =Kompetenzraster!Q27 -> 46518
B36: Abgabe
B37: =Kompetenzraster!Q31-1 -> 46531
B43: Auftrag 4.4 | C43: Lernziele: - Sie beschreiben die für Vorwände relevanten Inhalte der Schallschutznorm und Brandschutzvorschriften. - Sie erstellen anhand von Planunterlagen einen Werkstattplan für eine Vorwand. Abzugebende Leistungsnachweise: - Leistungsnachweis "Vorwandplanung"
B45: Punkte
B46: =Kompetenzraster!#REF! -> #REF!
B47: Zuweisung
B48: =Kompetenzraster!Q31 -> 46532
B49: Abgabe
B50: =Kompetenzraster!Q37-1 -> 46552
B56: Auftrag 4.5 | C56: Lernziele: - Sie berechnen rechtwinklige Dreiecke - Sie können mit Hilfe von Montageunterlagen Abzweig - Bogen Kombinationen in Schmutzwasserinstallationen bestimmen - Sie können mit Hilfe von Montageunterlagen den seitlichen Versatz in Schmutzwasserinstallationen unter Berücksichtigung des Gefälles bestimmen Abzugebende Leistungsnachweise: - Leistungsnachweis "«Berechnung seitlicher Versatz in der Praxis»
B58: Punkte
B59: =Kompetenzraster!#REF! -> #REF!
B60: Zuweisung
B61: =Kompetenzraster!Q41 -> 46567
B62: Abgabe
B63: =Kompetenzraster!Q41+6 -> 46573
B70: Auftrag 4.6 | C70: Lernziele: - Sie beschreiben die verschiedenen Gasarten. - Sie beschreiben die wichtigsten Eigenschaften von Erdgas. - Sie erläutern die Bedingungen, wie es zu einem Brand oder einer Explosion kommen kann. - Sie erklären die Erdgasgewinnung. - Sie beschreiben die Funktionsweise der Erdgasversorgung. Abzugebende Leistungsnachweise: - Leistungsnachweis ««Lernkarten erstellen»
B72: Punkte
B73: =Kompetenzraster!#REF! -> #REF!
B74: Zuweisung
...
