Workbook

Sheet Kompetenzraster
B1: Kompetenzraster 5.Semester Sanitärinstallateur/in EFZ | I1: Semesterstart: | J1: 46244 | K1: Schultag: | L1: Montag
B3: Handlungsfelder und Kompetenzen | M3: Bewertung / Benotung | Q3: Unterichtsplanung 1. Semester
B5: HF 1 | E5: Auftrag 5.1 | G5: Auftrag 5.2 | I5: Auftrag 5.3 | M5: Note Leistungsnachweis | Q5: =J1+0 -> 46244 | R5: Erdgas Apparate & Apparateanschluss
E6: 3 Schultage (6L) | G6: 8 Schultage (16L) | I6: 5 Schultage (10L) | M6: Die Note aus den Leistungsnachweisen berechnet sich aus den während des Semestes erzielten Punkten. | Q6: 5.4 I 5.1 | R6: Dimensionieren Schmutzwasser
B7: Planen der Arbeiten | E7: Sie bestimmen die Rohrweiten von Abwasserleitungen anhand der geltenden Vorschriften. | G7: Sie zeichnen einfache Installationspläne unter Berücksichtigung der relevanten Vorschriften. | I7: Sie erstellen genaue und vollständige Isometrie-Zeichnungen anhand von Planunterlagen. | J7: Sie berechnen rechtwinklige Dreiecke. | K7: Sie berechnen Längen- und Höhenmasse. | Q7: =Q5+7 -> 46251 | R7: Erdgas Apparate & Apparateanschluss
Q8: 5.4 I 5.1 | R8: Dimensionieren Schmutzwasser | Y8: Bewertung / Benotung
Q9: =Q7+7 -> 46258 | R9: Erdgas Apparate & Apparateanschluss
J10: Sie wenden die X- und z-Mass-Methode an verschiedenen Beispielen an. | K10: Sie erstellen anhand von isometrischen Zeichnungen vollständige Stücklisten. | M10: Auftrag 5.1 | N10: 2 | Q10: 5.4 I 5.1 | R10: Dimensionieren Schmutzwasser | Y10: Zeugnisnote
M11: Auftrag 5.2 | N11: 3 | Q11: =Q9+7 -> 46265 | R11: Erdgas Dimensionierung | Y11: Die Zeugnisnote setzt sich aus den Leistungsnachweisen und Kompetenzprüfungen zusammen. Die Note aus den Leistungsnachweisen zählt zu ca. 30% an die Zeugnisnote. Alle Noten der Prüfungen zählen zu ca. 60% an die Zeugnisnote.
M12: Auftrag 5.3 | N12: 2 | Q12: 5.6 I 5.2 | R12: Projektierung / Planbearbeitung
M13: Auftrag 5.4 | N13: 2 | Q13: =Q11+7 -> 46272 | R13: Erdgas Dimensionierung
B14: HF 3 | E14: Auftrag 5.4 | J14: Auftrag 5.6 | M14: Auftrag 5.6 | N14: 1.5 | Q14: 5.6 I 5.2 | R14: Projektierung / Planbearbeitung
E15: 3 Schultage (9L) | J15: 3 Schultage (9L) | M15: Auftrag 5.7 | N15: 1 | Q15: =Q13+7 -> 46279 | R15: Erdgas Dimensionierung
B16: Installieren von Erdgasleitungen | E16: Sie beschreiben die Inhalte der geltenden Vorschriften in Bezug auf die Erdgasinstallation. | F16: Sie können den Gasherd und die Gasheizung als wichtige Gasapparate beschreiben und erklären. | G16: Sie wissen, wie man Gasgeräte fachgerecht anschliesst und wissen, welche Punkte bei der Inbetriebnahme wichtig sind. | J16: Sie bestimmen die Rohrweiten von Erdgasleitungen anhand der SVGW-Richtlinie G1 | M16: Auftrag 5.8 | N16: 1.5 | Q16: 5.6 I 5.2 | R16: Projektierung / Planbearbeitung
M17: Auftrag 5.9 | N17: 1.5 | Q17: =Q15+7 -> 46286 | R17: QV Vorbereitung Erdgas
M18: Auftrag 5.10 | N18: 3 | Q18: 5.11 I 5.2 | R18: Projektierung / Planbearbeitung
M19: Auftrag 5.11 | N19: 1 | Q19: =Q17+28 -> 46314 | R19: WAS Versickerung / Retension | Y19: Leistungsnachweise
M20: Punkte max. | N20: =SUM(N10:N19) -> 18.5 | Q20: 5.7 I 5.2 | R20: Projektierung/ Planbearbeitung | Y20: Die Note der Leistungsnachweise entsteht aus den während des Semestes erzielten Punkten.
Q21: =Q19+7 -> 46321 | R21: WAS Versickerung / Retension
O22: X | Q22: 5.7 I 5.2 | R22: Projektierung / Planbearbeitung
B23: HF 4 / HF 6 | E23: Auftrag 5.7 | G23: Auftrag 5.8 | J23: Auftrag 5.9 | M23: Noten Prüfungen | Q23: =Q21+7 -> 46328 | R23: WAS Versickerung / Retension
E24: 3 Schultage (6L) | G24: 2 Schultage (6L) | J24: 4 Schultage (12L) | M24: Zu vier bis fünf Aufträgen wird im Unterricht eine Prüfung geschrieben. | Q24: 5.7 I 5.2 | R24: Projektierung / Planbearbeitung | Y24: Planen der Arbeiten
B25: Installieren von Entsorgungsleitungen | E25: Sie erläutern die Funktionsweise von Retentions- und Versickerungsanlagen. | F25: Sie beschreiben die Inhalte der geltenden Vorschriften in Bezug auf die Installation von Entsorgungsleitungen. | G25: Sie planen und dimensionieren Fortluftleitungen anhand von Dimensionierungstabellen. | H25: Sie benennen die Anforderungen an Kleinlüftungsanlagen in Bezug auf den Schall- und Brandschutz. | I25: Sie benennen verschiedene Ventilatoren-typen, Ventilatoreneinsätze und deren Gehäuse. | J25: Sie benennen gebräuchliche Ver- und Entsorgungsapparate sowie deren Komponenten. | K25: Sie beschreiben die Funktion, die Einsatzmöglichkeiten und die Montageanforderungen der Ver- und Entsorgungsapparate. | Q25: =Q23+7 -> 46335 | R25: Kleinlüftungsanlagen | Y25: Auftrag 4.1 | Z25: 3
Q26: 5.8 I 5.2 | R26: Projektierung / Planbearbeitung | Y26: Auftrag 4.2 | Z26: 3
Q27: =Q25+7 -> 46342 | R27: Kleinlüftungsanlagen | Y27: Auftrag 4.3 | Z27: 3
B28: Montieren von sanitären Anlagen und Apparate | E28: Sie bestimmen die Rohrweiten von Rohrleitungen. | G28: Sie beschreiben verschiedene Rohrmaterialien und deren Verbindungsmöglichkeiten. | H28: Sie definieren Befestigungsabstände von Fortluftrohren. | J28: Sie bestimmen die Grösse eines Wassererwärmers anhand der geltenden Vorschriften. | M28: Zeugnisnote | Q28: 5.8 I 5.3 | R28: AVOR X-Mass | Y28: Auftrag 4.4 | Z28: 2
M29: Die Note aus den Lernprodukten zählt zu 30%. Alle Noten der Prüfungen zählen zu 60%. | Q29: =Q27+7 -> 46349 | R29: Versorgungsapparate Wassererwärmer | Y29: Auftrag 4.5 | Z29: 1
Q30: 5.9 I 5.3 | R30: AVOR X-Mass | Y30: Auftrag 4.11 | Z30: 1
Q31: =Q29+7 -> 46356 | R31: Versorgungsapparate Wassererwärmer | Y31: Total Punkte | Z31: =SUM(Z25:AA30) -> 13
B32: HF 1/2/3/4/5/6/7 | E32: Auftrag 5.10 | I32: Auftrag 5.11 | Q32: 5.9 I 5.3 | R32: AVOR X-Mass
E33: 2 Schultage (10L) | I33: 1 Schultag (3L) | M33: Gesetzliche Feiertage | Q33: =Q31+7 -> 46363 | R33: Versorgungsapparate Wassererwärmer | Y33: Mont. von Sanitäranlagen
B34: Vernetzung aller Handlungsfelder | E34: Sie erstellen anhand von Planunterlagen einen Werkstattplan für eine Vorwand. | F34: Sie wenden die Z- und X-Mass-Methode an verschiedenen Beispielen an. | G34: Sie erstellen anhand von Planunterlagen, Apparatelisten und Massskizzen einen massstäblichen Detailplan. | H34: Sie zeichnen einfache Installationspläne unter Berücksichtigung der relevanten Vorschriften. | I34: QV Vorbereitung Erdgas Sie erstellen selbstständig Lernkarten zu den Grundlagenkenntnissen im Bereich Erdgas. | M34: Allerheiligen | N34: 44866 | Q34: 5.9 I 5.3 | R34: AVOR X-Mass | Y34: Auftrag 4.6 | Z34: 3
M35: Karfreitag | N35: 45023 | Q35: =Q33+7 -> 46370 | R35: Versorgungsapparate Wassererwärmer | Y35: Auftrag 4.7 | Z35: 2
M36: Ostermontag | N36: 45026 | Q36: 5.9 I 5.3 | R36: AVOR X-Mass | Y36: Auftrag 4.8 | Z36: 3
E37: Sie beschreiben die handelsüblichen Vorwandsysteme. | F37: Sie berechnen den Druck unter Berücksichtigung der Kompressibilität des Wassers. | G37: Sie beschreiben das korrekte Vorgehen zur Überprüfung der Ausstosszeiten. | H37: Sie bestimmen die Rohrweiten von Trinkwasser-Leitungen anhand der geltenden Vorschriften. | M37: Auffahrt | N37: 45064 | Q37: =Q35+21 -> 46391 | R37: Semesterarbeit / Vernetzung | Y37: Auftrag 4.9 | Z37: 2
M38: Pfingstmontag | N38: 45075 | Q38: 5.1 | Y38: Auftrag 4.10 | Z38: 3
Q39: =Q37+7 -> 46398 | R39: Semesterarbeit / Vernetzung | Y39: Total Punkte | Z39: =SUM(Z34:AA38) -> 13
B41: Fachgruppe Sanitär Spengler | K41: itm I sanitärlernen.ch

Sheet ST_1_KW_33
B1: Unterrichtsverlauf | E1: =Kompetenzraster!Q5 -> 46244 | G1: 1
B3: Erdgas Apparateanschluss | F3: 5.4 | G3: Filme / Theorie
B5: 1 - 3 Lektion | C5: Auftrag 1
C6: * Einstieg mit Repetition Montageregeln
C7: * Betrachtung Video / Explosion / Gruppendiskussion
C8: * Aufgabe 2 -6 selbstständig lösen und besprechen
C10: Auftrag 2
C11: * Regeln zur Aufstellung von Gasapparaten
C12: * Aufgabe 7 -12 selbstständig lösen und besprechen
C14: Lernziele
C15: * Sie beschreiben die Inhalte der geltenden Vorschriften in Bezug auf die Erdgasinstallation.
C16: * Sie wissen, wie man Gasgeräte fachgerecht anschliesst und wissen, welche Punkte
C17: bei der Inbetriebnahme wichtig sind.
B19: Pause
B21: Schmutzwasser Dimensionierung | F21: 5.1 | G21: Filme / Theorie
B23: 4 - 5 Lektion
C24: Auftrag 1
C25: * Einstieg mit Übung Betrachtung Schema
C27: Auftrag 2
C28: * Erarbeitung Grundlagen der Dimensionierung
C30: Auftrag 3
C31: * evtl. Start mit Aufgabe 7 / Dimensionierung
C32: Lernziele
C33: * Sie bestimmen die Rohrweiten von Abwasserleitungen anhand der geltenden Vorschriften.
B36: Hausaufgaben | E36: Administratives

Sheet ST_2_KW_34
B1: Unterrichtsverlauf | E1: =Kompetenzraster!Q7 -> 46251 | G1: 2
B3: Erdgas Apparateanschluss | F3: 5.4 | G3: Filme / Theorie
B5: 1 - 3 Lektion
C6: Auftrag 3
C7: * Einstieg Thema Gasherd mit Lehrmittel
C8: * Arbeit an Fragen aus LM / Demoraum
C9: * Flammenbild betrachten & Einregulierung
C10: * Übung Anschlussleistungen für Dimensionierung
C14: Lernziele
C15: * Sie können den Gasherd und die Gasheizung beschreiben und erklären.
C16: * Sie wissen, wie man Gasgeräte fachgerecht anschliesst und wissen, welche Punkte
C17: bei der Inbetriebnahme wichtig sind.
B19: Pause
B21: Schmutzwasser Dimensionierung | F21: 5.1 | G21: Filme / Theorie
B23: 4 - 5 Lektion
C24: Auftrag 3
C25: * Start mit Aufgabe 7 / Dimensionieren gemeinsam
C26: * Üben üben üben mit Aufgaben aus Dossier
C32: Lernziele
C33: * Sie bestimmen die Rohrweiten von Abwasserleitungen anhand der geltenden Vorschriften.
B36: Hausaufgaben | E36: Administratives

Sheet ST_3_KW_35
B1: Unterrichtsverlauf | E1: =Kompetenzraster!Q9 -> 46258 | G1: 3
B3: Erdgas Apparateanschluss | F3: 5.4 | G3: Filme / Theorie
B5: 1 - 3 Lektion
C6: Auftrag 4
C7: * Einstieg Thema Gasheizung
C8: * Arbeit an Fragen aus LM / Demoraum
C9: * Arbeit an Leistungsnachweis "Gasapparate platzieren und anschliessen»
C10: * Hinweis Prüfung & Lernziele
G11: Lernziele / Prüfung
C14: Lernziele
C15: * Sie können den Gasherd und die Gasheizung beschreiben und erklären.
C16: * Sie wissen, wie man Gasgeräte fachgerecht anschliesst und wissen, welche Punkte
C17: bei der Inbetriebnahme wichtig sind.
B19: Pause
B21: Schmutzwasser Dimensionierung | F21: 5.1 | G21: Filme / Theorie
B23: 4 - 5 Lektion
C24: Auftrag 4
C25: * Start mit Korrektur Aufgabe 8
C26: * Üben üben üben mit Aufgaben aus Dossier
C27: * Arbeit an Leistungsnachweis "Dimensionieren Abwasser»
G28: Lernziele / Prüfung
C32: Lernziele
C33: * Sie bestimmen die Rohrweiten von Abwasserleitungen anhand der geltenden Vorschriften.
B36: Hausaufgaben | E36: Administratives

Sheet ST_4_KW_36
B1: Unterrichtsverlauf | E1: =Kompetenzraster!Q11 -> 46265 | G1: 4
B3: Erdgas Dimensionierung | F3: 5.6 | G3: Filme / Theorie
B5: 1 - 3 Lektion | C5: Prüfung Auftrag 5.4 | F5: 30min
C6: Prüfung Auftrag 5.1 | F6: 30min
C9: Einstieg
C10: * gemeinsames Zeichnen eines "normalen EFH Schemas
C11: * Herleitung HiB / Auslegung Anschlussleistung
C14: Lernziele
C15: * Sie bestimmen die Rohrweiten von Erdgasleitungen anhand der SVGW-Richtlinie G1.
B19: Pause
B21: Projektierung / Planbearbeitung | F21: 5.2 | G21: Filme / Theorie
B23: 4 - 5 Lektion
C24: Auftrag 1
C25: * Einstieg mit Plänen aus der Praxis
C26: * Aufzeichnen der relevanten Symbole für Schema
C27: * Übung / Systeme & Bezeichnungen
C32: Lernziele
C33: * Sie zeichnen einfache Installationspläne unter Berücksichtigung
C34: der relevanten Vorschriften.
B36: Hausaufgaben | E36: Administratives

Sheet ST_5_KW_37
B1: Unterrichtsverlauf | E1: =Kompetenzraster!Q13 -> 46272 | G1: 5
B3: Erdgas Dimensionierung | F3: 5.6 | G3: Filme / Theorie
B5: 1 - 3 Lektion
C6: Auftrag 1
C7: * Die zwei Arten der Dimensionierung
C8: * Gemeinsames Erstellen einer Anleitung zum Dimensionieren
C10: Auftrag 2
C11: * Aufgaben 4 / 5 & 6 lösen und gemeinsam besprechen
C12: * Erste Übungsserie lösen
C14: Lernziele
C15: * Sie bestimmen die Rohrweiten von Erdgasleitungen anhand der SVGW-Richtlinie G1.
B19: Pause
B21: Projektierung / Planbearbeitung | F21: 5.2 | G21: Filme / Theorie
B23: 4 - 5 Lektion
C24: Auftrag 1
C25: * Korrektur und Besprechung / Bezeichnungsübung
C26: * Einstieg mit Aufgabe Grundriss & Verteilbatterie
C28: Auftrag 2
C29: * Kellerverteilungen isometrisch aufzeichnen / Übungen
C30: * Aufgaben Zeta & Eta zum selbstständigen üben…
C32: Lernziele
C33: * Sie zeichnen einfache Installationspläne unter Berücksichtigung
C34: der relevanten Vorschriften.
B36: Hausaufgaben | E36: Administratives

Sheet ST_6_KW_38
B1: Unterrichtsverlauf | E1: =Kompetenzraster!Q15 -> 46279 | G1: 6
B3: Erdgas Dimensionierung | F3: 5.6 | G3: Filme / Theorie
B5: 1 - 3 Lektion
C6: Auftrag 2
C7: * Übungen "Alte Prüfungen lösen"
C9: Auftrag 3
C10: * Leistungsnachweis lösen und abgeben…
G11: Lernziele / Prüfung
C14: Lernziele
C15: * Sie bestimmen die Rohrweiten von Erdgasleitungen anhand der SVGW-Richtlinie G1.
B19: Pause
B21: Projektierung / Planbearbeitung | F21: 5.2 | G21: Filme / Theorie
B23: 4 - 5 Lektion
C24: Auftrag 2
C25: * Gemeinsames lösen und korrigieren von Aufgabe Teta
C26: * Korrektur durch LP!
C32: Lernziele
C33: * Sie zeichnen einfache Installationspläne unter Berücksichtigung
C34: der relevanten Vorschriften.
B36: Hausaufgaben | E36: Administratives

Sheet ST_7_KW_39
B1: Unterrichtsverlauf | E1: =Kompetenzraster!Q17 -> 46286 | G1: 7
B3: Erdgas Abschluss / Fragekarten | F3: 5.11 | G3: Filme / Theorie
B5: 1 - 3 Lektion | C5: Prüfung Auftrag 5.6 | F5: 20min
C7: Auftrag 1
C8: * Übersicht Kometenzen / Vermittlung Idee
C9: * Einteilung in Gruppen => Excel Teams
C11: Auftrag 2
C12: * Arbeit an den Antworten in Kleingruppen
C14: Lernziele
C15: * Erstellung von Lernkarten für die Vorbereitung Qualifikationsverfahren.
B19: Pause
B21: Projektierung / Planbearbeitung | F21: 5.2 | G21: Filme / Theorie
B23: 4 - 5 Lektion
C24: Auftrag 3
C25: * Arbeit und Abgabe Leistungsnachweis "Leitungsisometrie"
C32: Lernziele
C33: * Sie zeichnen einfache Installationspläne unter Berücksichtigung
C34: der relevanten Vorschriften.
B36: Hausaufgaben | E36: Administratives

Sheet ST_8_KW_43
B1: Unterrichtsverlauf | E1: =Kompetenzraster!Q19 -> 46314 | G1: 8
B3: Regenwasserleitungen & Retension | F3: 5.7 | G3: Filme / Theorie
B5: 1 - 3 Lektion
C6: Auftrag 1
C7: * Einstieg mit Gruppenarbeit zum Thema "Versickerung"
C8: * Beantwortung und Besprechung der Fragen 1-5
C10: Auftrag 2
C11: * Grundlagen der Montage von Regenwasserleitungen
C14: Lernziele
C15: * Sie beschreiben die Inhalte der aktuellen Vorschriften in Bezug
C16: auf die Installation von Entsorgungsleitungen.
B19: Pause
B21: Projektierung / Planbearbeitung | F21: 5.2 | G21: Filme / Theorie
B23: 4 - 5 Lektion
C24: Auftrag 4
C25: * Start mit selbstständiger Projektierung von Grundrissen inkl. Isometrie
C26: * Aufgabe Alois
C32: Lernziele
C33: * Sie zeichnen einfache Installationspläne unter Berücksichtigung
C34: der relevanten Vorschriften.
B36: Hausaufgaben | E36: Administratives

Sheet ST_9_KW_44
B1: Unterrichtsverlauf | E1: =Kompetenzraster!Q21 -> 46321 | G1: 9
B3: Regenwasserleitungen & Retension | F3: 5.7 | G3: Filme / Theorie
B5: 1 - 3 Lektion
C6: Auftrag 3
C7: * Kennen lernen "Regenwasserabführung mit Pluvia"
C8: * Beantwortung und Besprechung der Fragen 7-9
C10: Auftrag 4
C11: * Dimensionieren von Regenwasserleitungen
C14: Lernziele
C15: * Sie beschreiben die Inhalte der aktuellen Vorschriften in Bezug
C16: auf die Installation von Entsorgungsleitungen.
B19: Pause
B21: Projektierung / Planbearbeitung | F21: 5.2 | G21: Filme / Theorie
B23: 4 - 5 Lektion
C24: Auftrag 4
C25: * Start mit selbstständiger Projektierung von Grundrissen inkl. Isometrie
C26: * Aufgabe Bertram / Claudia
C32: Lernziele
C33: * Sie zeichnen einfache Installationspläne unter Berücksichtigung
C34: der relevanten Vorschriften.
B36: Hausaufgaben | E36: Administratives

Sheet ST_10_KW_45
B1: Unterrichtsverlauf | E1: =Kompetenzraster!Q23 -> 46328 | G1: 10
B3: Regenwasserleitungen & Retension | F3: 5.7 | G3: Filme / Theorie
B5: 1 - 3 Lektion
C6: Auftrag 4
C7: * Dimensionieren von Regenwasserleitungen
C9: Auftrag 5
C10: * Abgabe und Hinweis Leistungsnachweis
G11: Lernziele / Prüfung
C14: Lernziele
C15: * Sie beschreiben die Inhalte der aktuellen Vorschriften in Bezug
C16: auf die Installation von Entsorgungsleitungen.
B19: Pause
B21: Projektierung / Planbearbeitung | F21: 5.2 | G21: Filme / Theorie
B23: 4 - 5 Lektion
C24: Auftrag 4
C25: * Selbstständige Projektierung von Grundrissen inkl. Isometrie
C26: * Aufgabe Bertram / Claudia / LN
G29: Lernziele / Prüfung
C32: Lernziele
C33: * Sie zeichnen einfache Installationspläne unter Berücksichtigung
C34: der relevanten Vorschriften.
B36: Hausaufgaben | E36: Administratives

Sheet ST_11_KW_46
B1: Unterrichtsverlauf | E1: =Kompetenzraster!Q25 -> 46335 | G1: 11
B3: Kleinlüftungsanlagen montieren | F3: 5.8 | G3: Filme / Theorie
B5: 1 - 3 Lektion | C5: Prüfung Auftrag 5.7 | F5: 30min
C6: Auftrag 1
C7: * Film Schimmel / Diskussion & Einstiegsfragen
C9: Auftrag 2
C10: * Arten und Aufbau von Kleinlüftern
C11: * Berechnung des Raumvolumens
C12: * Hinweis Leistungsnachweis => Handlungsanleitung durchlesen
C14: Lernziele
C15: * Sie benennen verschiedene Ventilatortypen, Einsätze und deren Gehäuse.
C16: * Sie beschreiben verschiedene Rohrmaterialien und deren Verbindungsmöglichkeiten.
C17: * Sie benennen die Anforderungen in Bezug auf den Schall- und Brandschutz.
C18: * Sie planen und dimensionieren Fortluftleitungen anhand von Tabellen.
B19: Pause
B21: Werkstattplan erstellen | F21: 5.2 | G21: Filme / Theorie
B23: 4 - 5 Lektion | C23: * individuelle Vorbereitung auf Prüfung
C24: Prüfung Auftrag 5.2 | F24: 60min
C32: Lernziele
C33: * Sie erstellen selbstständig einfache X-Mass Vorfabrikationszeichnungen
C34: inkl. Rohrlängen und Stückliste.
B36: Hausaufgaben | E36: Administratives

Sheet ST_12_KW_47
B1: Unterrichtsverlauf | E1: =Kompetenzraster!Q27 -> 46342 | G1: 12
B3: Kleinlüftungsanlagen montieren | F3: 5.8 | G3: Filme / Theorie
B5: 1 - 3 Lektion
C6: Auftrag 2
C7: * Einstieg mit Berechnung Raumvolumen & Luftwechsel
C9: Auftrag 3
C10: * Arbeit an Leistungsnachweis "Kleinlüfter montieren"
C14: Lernziele
C15: * Sie benennen verschiedene Ventilatortypen, Einsätze und deren Gehäuse.
C16: * Sie beschreiben verschiedene Rohrmaterialien und deren Verbindungsmöglichkeiten.
C17: * Sie benennen die Anforderungen in Bezug auf den Schall- und Brandschutz.
C18: * Sie planen und dimensionieren Fortluftleitungen anhand von Tabellen.
B19: Pause
B21: Werkstattplan erstellen | F21: 5.3 | G21: Filme / Theorie
B23: 4 - 5 Lektion
C24: Auftrag 1
C25: * Aufgabe 6.11 / Einlage Lüftung
C32: Lernziele
C33: * Sie erstellen selbstständig einfache X-Mass Vorfabrikationszeichnungen
C34: inkl. Rohrlängen und Stückliste.
B36: Hausaufgaben | E36: Administratives

Sheet ST_13_KW_48
B1: Unterrichtsverlauf | E1: =Kompetenzraster!Q29 -> 46349 | G1: 13
B3: Versorgungsapparate montieren | F3: 5.9 | G3: Filme / Theorie
B5: 1 - 3 Lektion
C6: Auftrag 1
C7: * Einstieg mit Expertenpuzzle "Bauarten von Wassererwärmer"
C9: Auftrag 2
C10: * Herstellung von Wassererwärmern & Bauteile
C11: * Funktion & Aufgabe Opferanode & Fühler / Thermostat
C14: Lernziele
C15: * Sie benennen gebräuchliche Arten von Wassererwärmern sowie deren Komponenten.
B19: Pause
B21: Werkstattplan erstellen | F21: 5.3 | G21: Filme / Theorie
B23: 4 - 5 Lektion
C24: Auftrag 1
C25: * Aufgabe 6.12 / Hindernisfreie Toilette
C32: Lernziele
C33: * Sie erstellen selbstständig einfache X-Mass Vorfabrikationszeichnungen
C34: inkl. Rohrlängen und Stückliste.
B36: Hausaufgaben | E36: Administratives

Sheet ST_14_KW_49
B1: Unterrichtsverlauf | E1: =Kompetenzraster!Q31 -> 46356 | G1: 14
B3: Versorgungsapparate montieren | F3: 5.9 | G3: Filme / Theorie
B5: 1 - 3 Lektion
C6: Auftrag 2
C7: * Funktion & Aufgabe Opferanode gemeinsam besprechen
C9: Auftrag 3
C10: * MindMap Montageanforderungen erstellen
C11: * Thermosifon & Isolierverschraubungen speziell besprechen
C12: * Anschlüsse & Schaltungen besprechen und behandeln
C14: Lernziele
C15: * Sie beschreiben die Funktion, die Einsatzmöglichkeiten und die
C16: Montageanforderungen von Wassererwärmern.
C17: * Sie bestimmen die Grösse eines Wassererwärmers anhand der geltenden Vorschriften.
B19: Pause
B21: Werkstattplan erstellen | F21: 5.3 | G21: Filme / Theorie
B23: 4 - 5 Lektion
C24: Auftrag 1
C25: * Aufgabe 6.14 / Einlegestück auf Schalungstafel
C32: Lernziele
C33: * Sie erstellen selbstständig einfache X-Mass Vorfabrikationszeichnungen
C34: inkl. Rohrlängen und Stückliste.
B36: Hausaufgaben | E36: Administratives

Sheet ST_15_KW_50
B1: Unterrichtsverlauf | E1: =Kompetenzraster!Q33 -> 46363 | G1: 15
B3: Versorgungsapparate montieren | F3: 5.9 | G3: Filme / Theorie
B5: 1 - 3 Lektion | C5: * Einstieg mit Quiz Academy
C7: Auftrag 4
C8: * Schichtung und Bauform von Wassererwärmern.
C10: Auftrag 5
C11: * Gemeinsames Herleiten des Warmwasserverbrauchs
C12: * Dimensionieren von Wassererwärmern gem. SIA 385
C14: Lernziele
C15: * Sie beschreiben die Funktion, die Einsatzmöglichkeiten und die
C16: Montageanforderungen von Wassererwärmern.
C17: * Sie bestimmen die Grösse eines Wassererwärmers anhand der geltenden Vorschriften.
B19: Pause
B21: Werkstattplan erstellen | F21: 5.3 | G21: Filme / Theorie
B23: 4 - 5 Lektion
C24: Auftrag 1
C25: * Aufgabe 6.15 / Holzkonstruktion
C32: Lernziele
C33: * Sie erstellen selbstständig einfache X-Mass Vorfabrikationszeichnungen
C34: inkl. Rohrlängen und Stückliste.
B36: Hausaufgaben | E36: Administratives

Sheet ST_16_KW_48
B1: Unterrichtsverlauf | E1: =Kompetenzraster!Q35 -> 46370 | G1: 16
B3: Versorgungsapparate montieren | F3: 5.9 | G3: Filme / Theorie
B5: 1 - 3 Lektion
C6: Auftrag 5
C7: * gemeinsame Korrektur Aufgaben 20 & 21
C9: Auftrag 6
C10: * Abgabe und Einführung den Leistungsnachweis
G11: Lernziele / Prüfung
C14: Lernziele
C15: * Sie beschreiben die Funktion, die Einsatzmöglichkeiten und die
C16: Montageanforderungen von Wassererwärmern.
C17: * Sie bestimmen die Grösse eines Wassererwärmers anhand der geltenden Vorschriften.
B19: Pause
B21: Werkstattplan erstellen | F21: 5.3 | G21: Filme / Theorie
B23: 4 - 5 Lektion
C24: Auftrag 1
C25: * Aufgabe Küche / Keller
C26: * Aufgabe WC / Keller
G29: Lernziele / Prüfung
C32: Lernziele
C33: * Sie erstellen selbstständig einfache X-Mass Vorfabrikationszeichnungen
C34: inkl. Rohrlängen und Stückliste.
B36: Hausaufgaben | E36: Administratives

Sheet ST_17_KW_1
B1: Unterrichtsverlauf | E1: =Kompetenzraster!Q37 -> 46391 | G1: 17
B3: Projektarbeit 5.Semester | F3: 5.1 | G3: Filme / Theorie
B5: 1 - 3 Lektion | C5: Prüfung Auftrag 5.3 | F5: 60min
C7: Einstieg / Projekt
C8: * Vermittlung der Ziele / Darstellung / Abgabe
C9: * Erklärung der Teilaufgaben
C10: * Reduktion für Lernende die alleine Arbeiten möchten
C12: Arbeit an Projektarbeit
C13: Lernziele
C15: * Sie erstellen anhand von Planunterlagen einen Werkstattplan für eine Vorwand.
C16: * Sie wenden die X- und z-Mass-Methode an verschiedenen Beispielen an.
C17: * Sie erstellen anhand von Planunterlagen, Apparatelisten und Massskizzen
C18: einen massstäblichen Detailplan.
C19: * Sie zeichnen einfache Installationspläne unter Berücksichtigung der relevanten Vorschriften.
C20: * Sie beschreiben die handelsüblichen Vorwandsysteme.
... C23: * Sie bestimmen die Rohrweiten von Trinkwasser-Leitungen anhand der geltenden Vorschriften.
B24: Pause
B26: Projektarbeit 5.Semester | F26: 5.1 | G26: Filme / Theorie
B28: 4 - 5 Lektion
C29: Arbeit an Projektarbeit
C31: Lernziele
B35: Hausaufgaben | E35: Administratives

Sheet ST_18_KW_3
B1: Unterrichtsverlauf | E1: =Kompetenzraster!Q39 -> 46398 | G1: 18
B3: Projektarbeit 5.Semester | F3: 5.1 | G3: Filme / Theorie
B5: 1 - 3 Lektion | C5: Arbeit an Projektarbeit
C12: Zeugnisbesprechung
C13: Lernziele
C15: * Sie erstellen anhand von Planunterlagen einen Werkstattplan für eine Vorwand.
C16: * Sie wenden die X- und z-Mass-Methode an verschiedenen Beispielen an.
C17: * Sie erstellen anhand von Planunterlagen, Apparatelisten und Massskizzen
C18: einen massstäblichen Detailplan.
C19: * Sie zeichnen einfache Installationspläne unter Berücksichtigung der relevanten Vorschriften.
C20: * Sie beschreiben die handelsüblichen Vorwandsysteme.
C21: * Sie berechnen den Druck unter Berücksichtigung der Kompressibilität des Wassers.
C22: * Sie beschreiben das korrekte Vorgehen zur Überprüfung der Ausstosszeiten.
C23: * Sie bestimmen die Rohrweiten von Trinkwasser-Leitungen anhand der geltenden Vorschriften.
B24: Pause
B26: Projektarbeit 5.Semester | F26: 5.1 | G26: Filme / Theorie
B28: 4 - 5 Lektion
C29: Arbeit an Projektarbeit
C31: Lernziele
B35: Hausaufgaben | E35: Administratives

Sheet ST_19_KW_4
B1: Unterrichtsverlauf | E1: =ST_18_KW_3!E1+7 -> 46405 | G1: 19
G3: Filme / Theorie
B5: 1 - 3 Lektion
C13: Lernziele
B24: Pause
G26: Filme / Theorie
B28: 4 - 5 Lektion
C31: Lernziele
B35: Hausaufgaben | E35: Administratives

Sheet Aufgaben_Teams
B1: Aufgaben Teams
B4: Auftrag 5.1 | C4: Lernziele: - Sie bestimmen die Rohrweiten von Abwasserleitungen anhand der geltenden Vorschriften. Abzugebende Leistungsnachweise: - Leistungsnachweis«Dimensionierung WAS»
B6: Punkte
B7: =Kompetenzraster!N10 -> 2
B8: Zuweisung
B9: =Kompetenzraster!Q5 -> 46244
B10: Abgabe
B11: =Kompetenzraster!Q11-1 -> 46264
B13: Auftrag 5.2 | C13: Lernziele: - Sie zeichnen einfache Installationspläne unter Berücksichtigung der relevanten Vorschriften. Abzugebende Leistungsnachweise: - Leistungsnachweis "Projektierung"
B15: Punkte
B16: =Kompetenzraster!N11 -> 3
B17: Zuweisung
B18: =Kompetenzraster!Q13 -> 46272
B19: Abgabe
B20: =Kompetenzraster!Q29-1 -> 46348
B22: Auftrag 5.3 | C22: Lernziele: - Sie erstellen genaue und vollständige Isometrie-Zeichnungen anhand von Planunterlagen. (K3) - Sie wenden die Z- und X-Mass-Methode an verschiedenen Beispielen an. - Sie erstellen anhand von isometrischen Zeichnungen vollständige Stücklisten. - Sie berechnen Längen- und Höhenmasse und Dreiecke Abzugebende Leistungsnachweise: - Leistungsnachweis "Abgabe von drei korrigierten Fachzeichnungen"
B24: Punkte
B25: =Kompetenzraster!N12 -> 2
B26: Zuweisung
B27: =Kompetenzraster!Q29 -> 46349
B28: Abgabe
B29: =Kompetenzraster!Q37-1 -> 46390
B32: Auftrag 5.4 | C32: Lernziele: - Sie beschreiben die Inhalte der geltenden Vorschriften in Bezug auf die Erdgasinstallation. - Sie können den Gasherd und die Gasheizung als wichtige Gasapparate beschreiben und erklären. - Sie wissen, wie man Gasgeräte fachgerecht anschliesst und wissen, welche Punkte bei der Inbetriebnahme wichtig sind. Abzugebende Leistungsnachweise: - Leistungsnachweis "Apparatemontage & Anschluss"
B34: Punkte
B35: =Kompetenzraster!N13 -> 2
B36: Zuweisung
B37: =Kompetenzraster!Q5 -> 46244
B38: Abgabe
B39: =Kompetenzraster!Q11-1 -> 46264
B43: Auftrag 5.6 | C43: Lernziele: - Sie bestimmen die Rohrweiten von Erdgasleitungen anhand der SVGW-Richtlinie G1. Abzugebende Leistungsnachweise: - Leistungsnachweis "Dimensionierung Erdgas"
B45: Punkte
B46: 1.5
B47: Zuweisung
B48: =Kompetenzraster!Q13 -> 46272
B49: Abgabe
B50: =Kompetenzraster!Q17-1 -> 46285
B52: Auftrag 5.7 | C52: Lernziele: - Sie erläutern die Funktionsweise von Retentions- und Versickerungsanlagen. - Sie bestimmen die Rohrweiten von Rohrleitungen. - Sie beschreiben die Inhalte der geltenden Vorschriften in Bezug auf die Installation von Entsorgungsleitungen. Abzugebende Leistungsnachweise: - Leistungsnachweis «Dimensionierung Rohrleitungen»
B54: Punkte
B55: =Kompetenzraster!N15 -> 1
B56: Zuweisung
...
