Workbook

Sheet Kompetenzraster
B1: Kompetenzraster 6.Semester Sanitärinstallateur/in EFZ | I1: Semesterstart: | J1: 46061 | K1: Schultag: | L1: Montag
B3: Handlungsfelder und Kompetenzen | M3: Bewertung / Benotung | Q3: Unterichtsplanung 6. Semester
B5: HF 1 | E5: Auftrag 6.1 | G5: Auftrag 6.2 | I5: Auftrag 6.3 | M5: Note Leistungsnachweis | Q5: =J1+0 -> 46061 | R5: Pumpen in der Sanitärtechnik
E6: 8 Schultage (14L) | G6: 3 Schultage (8L) | I6: 4 Schultage (8L) | M6: Die Note aus den Leistungsnachweisen berechnet sich aus den während des Semestes erzielten Punkten. | Q6: 6.5 6.1 | R6: Projektierung Grundrisse
B7: Planen der Arbeiten | E7: Sie interpretieren und unterscheiden die gebräuchlichen Pläne. | F7: Sie zeichnen einfache Installationspläne unter Berücksichtigung der relevanten Vorschriften, sowie der Ausstosszeiten. | G7: Sie erstellen Isometrie-Zeichnungen und berechnen Sie mit der Z und X-Mass Methode. | H7: Sie erstellen anhand von isometrischen Zeichnungen vollständige Stücklisten. | I7: Sie bestimmen anhand von Beispielen den Platzbedarf, Achsabstände und Montage­höhen von Apparaten und den zugehörigen Garnituren. (K3) | J7: Sie erstellen anhand von Planunterlagen, Apparatelisten und Massskizzen einen massstäblichen Detailplan. (inkl. Leitungsführung) | Q7: =Q5+7 -> 46068 | R7: Pumpen in der Sanitärtechnik
Q8: 6.5 6.1 | R8: Projektierung Grundrisse
Q9: =Q7+7 -> 46075 | R9: Pumpen in der Sanitärtechnik
E10: Sie ordnen die gebräuchlichen Plansymbole korrekt zu. | G10: Sie zeichnen und berechnen stumpfwinklige und "normale" Dreiecke in isometrischen Zeichnungen | H10: Sie erstellen anhand von isometrischen Zeichnungen vollständige Stücklisten. | M10: Auftrag 6.1 | N10: 3 | O10: 3 | Q10: 6.5 6.1 | R10: Projektierung Grundrisse
M11: Auftrag 6.2 | N11: 2 | O11: 2 | Q11: =Q9+7 -> 46082 | R11: Pumpen in der Sanitärtechnik
M12: Auftrag 6.3 | N12: 1.5 | O12: 1.5 | Q12: 6.5 6.1 | R12: Projektierung Grundrisse
M13: Auftrag 6.4 | N13: 2 | O13: 2 | Q13: =Q11+7 -> 46089 | R13: Solaranlagen montieren
B14: HF 6 | E14: Auftrag 6.4 | H14: Auftrag 6.5 | M14: Auftrag 6.5 | N14: 1.5 | O14: 1.5 | Q14: 6.4 6.1 | R14: Projektierung Grundrisse
E15: 4 Schultage (12L) | H15: 4 Schultage (12L) | M15: Auftrag 6.6 | N15: 2 | O15: 2 | Q15: =Q13+7 -> 46096 | R15: Solaranlagen montieren
B16: Montieren von sanitären Anlagen und Apparate | E16: Sie beschreiben den Aufbau verschiedener Solaranlagen (z.B. thermische Solaranlage, Photovoltaikanlage). | F16: Sie beschreiben die Vorteile von Solaranlagen in Bezug auf die Energieeffizienz. | G16: Sie beschreiben die hydraulischen Anschlussmöglichkeiten bei Solaranlagen. | H16: Sie benennen gebräuchliche Ver- und Entsorgungsapparate sowie deren Komponenten. | I16: Sie beschreiben den Aufbau und die Funktion von Pumpen in der Sanitärinstallation. | M16: Auftrag 6.7 | N16: 2 | O16: 2 | Q16: 6.4 6.1 | R16: Projektierung Grundrisse
M17: Auftrag 6.8 | N17: 1 | O17: 1 | Q17: =Q15+7 -> 46103 | R17: Solaranlagen montieren
M18: Auftrag 6.9 | N18: 1 | O18: 1 | Q18: 6.4 6.1 | R18: Projektierung Grundrisse
F19: Sie erläutern die Funktionsweise verschiedener Solaranlagen. | G19: Sie erläutern die wichtigsten Prinzipien der Solarregelung. (K2) | M19: Note | N19: =(SUM(O10:O18)*5)/SUM(N10:N18)+1 -> 6 | O19: =IF(N19>3.5,N19,(O22)) -> 6 | Q19: =Q17+7 -> 46110 | R19: Solaranlagen montieren
Q20: 6.4 6.1 | R20: Projektierung Grundrisse
Q21: =Q19+7 -> 46117 | R21: Druckverlust in Rohren
O22: X | Q22: 6.7 6.3 | R22: Detailplanung Vorwand
B23: HF 7 | E23: Auftrag 6.7 | G23: Auftrag 6.8 | J23: Auftrag 6.11 | M23: Noten Prüfungen | Q23: =Q21+21 -> 46138 | R23: Druckverlust in Rohren
E24: 5 Schultage (12L) | G24: 2 Schultage (12L) | J24: 1 Schultag (3-5L) | M24: Zu einzelnen Aufträgen wird im Unterricht eine Zwischenprüfung geschrieben. | Q24: 6.7 6.3 | R24: Detailplanung Vorwand
B25: Durchführen von Abschlussarbeiten | E25: Sie erklären den Zusammenhang zwischen Volumenstrom, Fliessgeschwindigkeit, Druckverlust und Rohrdurchmessern. | F25: Sie erklären die hygienischen Anforderungen an Sanitäranlagen gemäss den Vorschriften. | G25: Sie erstellen ein Materialausmass anhand von verschiedenen Beispielen. | H25: Sie erläutern Sinn und Zweck der Werkübergabe. | I25: Sie erklären die hygienischen Anforderungen an Sanitäranlagen gemäss den geltenden Vorschriften. | J25: QV Vorbereitung Schmutzwasser & Vorwandsysteme Sie erstellen selbstständig Lernkarten zu den Grundlagenkenntnissen im Bereich Schmutzwasser und Vorwand. | Q25: =Q23+7 -> 46145 | R25: Druckverlust in Rohren
Q26: 6.7 6.3 | R26: Detailplanung Vorwand
Q27: =Q25+7 -> 46152 | R27: Druckverlust in Rohren
G28: Sie erläutern die Bedeutung von Revisions­plänen. | H28: Sie erklären die gebräuchlichen Anlagenteile in einfachen Worten. | M28: Zeugnisnote | Q28: 6.7 6.2 | R28: Detailplanung Vorwand
M29: Die Note aus den Lernprodukten zählt zu 30%. Alle Noten der Prüfungen zählen zu 60%. | Q29: =Q27+7 -> 46159 | R29: Druckverlust in Rohren
Q30: 6.7 6.2 | R30: AVOR X-Mass "Einlage"
Q31: =Q29+7 -> 46166 | R31: Hygiene in der Sanitärtechnik
B32: HF 1/2/3/4/5/6/7 | E32: Auftrag 6.9 | J32: Auftrag 6.10 | Q32: 6.8 6.2 | R32: AVOR X-Mass "Einlage"
E33: 2 Schultage (10L) | J33: 1 Schultag (5L) | M33: Gesetzliche Feiertage | Q33: =Q31+7 -> 46173 | R33: Hygiene in der Sanitärtechnik
B34: Vernetzung von allen Handlungsfelder | E34: Sie interpretieren Aussparungspläne für die Installation von Vorwänden. | F34: Sie bestimmen die Grösse eines Wassererwärmers anhand der geltenden Vorschriften. | G34: Sie erklären die Schnittstellen zu anderen Gewerken (z.B. Speicherladung sanitärseitig). | H34: Sie beschreiben Massnahmen, mit denen Versorgungsleitungen energieeffizient und wasserverbrauchsarm geführt werden können. | I34: Sie bestimmen Kleinlüftungsanlagen und erklären die Montageanforderungen der unterschiedlichen Ausführungen. | J34: Exkursion Georg Fischer | M34: Allerheiligen | N34: 45231 | Q34: 6.8 6.2 | R34: AVOR X-Mass "Einlage"
M35: Karfreitag | N35: 45023 | Q35: =Q33+7 -> 46180 | R35: QV Vorbereitung / Lernkarten WAS & Vorwand
M36: Ostermontag | N36: 43931 | Q36: 6.11
E37: Sie erstellen anhand von Planunterlagen einen Werkstattplan für eine Vorwand. | F37: Sie bestimmen die Rohrweiten von Trinkwasser-Leitungen anhand der geltenden Vorschriften. | G37: Sie beschreiben den Unterhalt, die Ersatzteile von Sanitäranlagen und Apparaten. | M37: Auffahrt | N37: 45064 | Q37: =Q35+7 -> 46187 | R37: Exkursion +GF Piping Systems"
M38: Pfingstmontag | N38: 45075 | Q38: 6.9
Q39: =Q37+7 -> 46194 | R39: Vernetzende Projektarbeit / Bespr. Zeugnis
B41: Fachgruppe Sanitär Spengler | K41: itm I sanitärlernen.ch

Sheet ST_1_KW_6
B1: Unterrichtsverlauf | E1: =Kompetenzraster!Q5 -> 46061 | G1: 1
B3: Versorgungsapparate montieren | F3: 6.5 | G3: Filme / Theorie
B5: 1 - 3 Lektion
C6: Auftrag 1
C7: * Einstieg mit Expertenpuzzle "Grundlagen Pumpen"
C8: * Fragekatalog bearbeiten und mündlich besprechen
C10: * Ausblick "Druckerhöhungsanlage" => Thema lesen im LM!
C14: Lernziele
C15: * Sie benennen gebräuchliche Ver- und Entsorgungsapparate sowie deren Komponenten.
C16: * Sie beschreiben den Aufbau und die Funktion von Pumpen in der Sanitärinstallation.
B18: Pause
B20: Projektierung Sanitäranlagen | F20: 6.1 | G20: Filme / Theorie
B22: 4 - 5 Lektion
C23: Auftrag 1
C24: * Einstieg mit Repetition Grundlagen "Projektieren"
C26: Auftrag 2
C27: * Gemeinsames Zeichnen einer kleinen Kellerverteilung
C31: Lernziele
C32: * Sie zeichnen einfache Installationspläne unter Berücksichtigung der
C33: relevanten Vorschriften.
B36: Hausaufgaben | E36: Administratives
B44: 2
B55: 2

Sheet ST_2_KW_7
B1: Unterrichtsverlauf | E1: =Kompetenzraster!Q7 -> 46068 | G1: 2
B3: Versorgungsapparate montieren | F3: 6.5 | G3: Filme / Theorie
B5: 1 - 3 Lektion
C6: Auftrag 2
C7: * Thema Druckerhöhung behandeln
C8: => Klasse halbiert / Demoraum
C9: => Bearbeitung & Besprechung Fragen
C11: * Regenwassernutzung als klasssiche Awendung einer Druckerhöhung
C14: Lernziele
C15: * Sie benennen gebräuchliche Ver- und Entsorgungsapparate sowie deren Komponenten.
C16: * Sie beschreiben den Aufbau und die Funktion von Pumpen in der Sanitärinstallation.
B18: Pause
B20: Projektierung Sanitäranlagen | F20: 6.1 | G20: Filme / Theorie
B22: 4 - 5 Lektion
C23: Auftrag 2
C24: * Aufgabe 2 «EFH Laurentius»
C26: Auftrag 3
C27: * Aufgabe «EFH Ladis»
C31: Lernziele
C32: * Sie zeichnen einfache Installationspläne unter Berücksichtigung der
C33: relevanten Vorschriften.
B36: Hausaufgaben | E36: Administratives
B55: 2

Sheet ST_3_KW_8
B1: Unterrichtsverlauf | E1: =Kompetenzraster!Q9 -> 46075 | G1: 3
B3: Versorgungsapparate montieren | F3: 6.5 | G3: Filme / Theorie
B5: 1 - 3 Lektion
C6: Auftrag 2
C7: * Thema Zirkulation behandeln
C8: => Klasse halbiert / Demoraum
C9: => Bearbeitung & Besprechung Fragen
C11: * Erster Leistungsnachweis lösen und direkt abgeben…
C14: Lernziele
C15: * Sie benennen gebräuchliche Ver- und Entsorgungsapparate sowie deren Komponenten.
C16: * Sie beschreiben den Aufbau und die Funktion von Pumpen in der Sanitärinstallation.
B18: Pause
B20: Projektierung Sanitäranlagen | F20: 6.1 | G20: Filme / Theorie
B22: 4 - 5 Lektion
C23: Auftrag 3
C24: * Aufgabe «EFH Ladis»
C25: * Aufgabe «EFH Serfaus»
C31: Lernziele
C32: * Sie zeichnen einfache Installationspläne unter Berücksichtigung der
C33: relevanten Vorschriften.
B36: Hausaufgaben | E36: Administratives

Sheet ST_4_KW_9
B1: Unterrichtsverlauf | E1: =Kompetenzraster!Q11 -> 46082 | G1: 4
B3: Versorgungsapparate montieren | F3: 6.5 | G3: Filme / Theorie
B5: 1 - 3 Lektion
C6: Auftrag 5
C7: * Thema Schmutzwasserhebeanlage
C8: => Einstieg mit Repetition Rückstauebene
C9: => Video die zwei Arten zur Verhinderung von Rückstau
C10: => Klasse halbiert / Demoraum / Bearbeitung & Besprechung Fragen
C11: * Zweiter Leistungsnachweis lösen und direkt abgeben… | G11: Lernziele / Prüfung
C14: Lernziele
C15: * Sie benennen gebräuchliche Ver- und Entsorgungsapparate sowie deren Komponenten.
C16: * Sie beschreiben den Aufbau und die Funktion von Pumpen in der Sanitärinstallation.
B18: Pause
B20: Projektierung Sanitäranlagen | F20: 6.1 | G20: Filme / Theorie
B22: 3 - 5 Lektion
C23: Auftrag 5
C24: * Aufgabe «EFH Serfaus»
C25: * Aufgabe «EFH Fiss»
G28: Lernziele / Prüfung
C31: Lernziele
C32: * Sie zeichnen einfache Installationspläne unter Berücksichtigung der
C33: relevanten Vorschriften.
B36: Hausaufgaben | E36: Administratives

Sheet ST_5_KW_10
B1: Unterrichtsverlauf | E1: =Kompetenzraster!Q13 -> 46089 | G1: 5
B3: Solaranlagen montieren | F3: 6.4 | G3: Filme / Theorie
B5: 1 - 3 Lektion | C5: Prüfung Auftrag 6.5 | F5: 30min
C7: Auftrag 1
C8: * Einstige mit Film zum Thema Solaranlage
C9: * Aufgabe / Fragen und Lehrmittel
C10: * Die zwei Arten der Nutzung in der Gebäudetechnik
C11: * Abschluss mit PV Anlage / Projekt Item
C14: Lernziele
C15: * Sie beschreiben die Vorteile von Solaranlagen in Bezug auf die Energieeffizienz.
C16: * Sie erläutern die Funktionsweise verschiedener Solaranlagen.
B18: Pause
B20: Projektierung Sanitäranlagen | F20: 6.1 | G20: Filme / Theorie
B22: 4 - 5 Lektion
C24: Auftrag 5
C25: * Aufgabe «EFH Serfaus»
C26: * Aufgabe «EFH Fiss»
C30: Prüfung Auftrag 6.1 | F30: 80min
C31: Lernziele
C32: * Sie zeichnen einfache Installationspläne unter Berücksichtigung der
C33: relevanten Vorschriften.
B36: Hausaufgaben | E36: Administratives

Sheet ST_6_KW_11
B1: Unterrichtsverlauf | E1: =Kompetenzraster!Q15 -> 46096 | G1: 6
B3: Solaranlagen montieren | F3: 6.4 | G3: Filme / Theorie
B5: 1 - 3 Lektion
C6: Auftrag 2
C7: * Einstieg mit Erarbeitung und Besprechnung der Kollektorarten
C8: * Kollektormontage / Anschlussmöglichkeiten
C9: * Der Solaranschluss im Schema & Betrachtung unserer Anlage
C14: Lernziele
C15: * Sie erläutern die Funktionsweise verschiedener Solaranlagen.
C16: * Sie beschreiben die hydraulischen Anschlussmöglichkeiten bei Solaranlagen.
C17: * Sie erläutern die wichtigsten Prinzipien der Solarregelung.
B18: Pause
B20: Projektierung Sanitäranlagen | F20: 6.1 | G20: Filme / Theorie
B22: 4 - 5 Lektion
C23: Auftrag 4
C24: * Einstieg ins Zeichnen von Ablaufleitungen
C25: => Gemeinsames Aufzeichnen von Ablaufleitungen
C27: * Aufgabe «EFH Frauns»
C31: Lernziele
C32: * Sie zeichnen einfache Installationspläne unter Berücksichtigung der
C33: relevanten Vorschriften.
B36: Hausaufgaben | E36: Administratives

Sheet ST_7_KW_12
B1: Unterrichtsverlauf | E1: =Kompetenzraster!Q17 -> 46103 | G1: 7
B3: Solaranlagen montieren | F3: 6.4 | G3: Filme / Theorie
B5: 1 - 3 Lektion
C6: * Einstieg mit Quizacademy * Solaranlage*
C8: Auftrag 3
C9: * Experiment und Herleitung Wärmemenge
C10: * Gemeinsames Berechnen erster Aufgaben
C11: * Selbstständiges üben des Themas Wärmemenge
C14: Lernziele
C15: * Sie können die Wärmemenge und die Wärmeleistung berechnen.
B18: Pause
B20: Projektierung Sanitäranlagen | F20: 6.1 | G20: Filme / Theorie
B22: 4 - 5 Lektion
C23: Auftrag 5
C24: * Aufgabe «EFH Frauns»
C25: * Aufgabe «EFH Kauns»
C31: Lernziele
C32: * Sie zeichnen einfache Installationspläne unter Berücksichtigung der
C33: relevanten Vorschriften.
B36: Hausaufgaben | E36: Administratives

Sheet ST_8_KW_13
B1: Unterrichtsverlauf | E1: =Kompetenzraster!Q19 -> 46110 | G1: 8
B3: Solaranlagen montieren | F3: 6.4 | G3: Filme / Theorie
B5: 1 - 3 Lektion
C6: Auftrag 4
C7: * Experiment und Herleitung Wärmeleistung
C8: * Gemeinsames Berechnen erster Aufgaben
C10: Auftrag 5
C11: * Vernetztende Aufgaben selbstständig lösen | G11: Lernziele / Prüfung
C12: Auftrag 6
C13: * Abgabe und Zeit für Leistungsnachweis
C14: Lernziele
C15: * Sie können die Wärmemenge und die Wärmeleistung berechnen.
B18: Pause
B20: Projektierung Sanitäranlagen | F20: 6.1 | G20: Filme / Theorie
B22: 4 - 5 Lektion
C23: Auftrag 5
C24: * Aufgabe «EFH Chevre»
C26: Auftrag 6
C27: * Leistungsnachweis erstellen und abgeben
G28: Lernziele / Prüfung
C31: Lernziele
C32: * Sie zeichnen einfache Installationspläne unter Berücksichtigung der
C33: relevanten Vorschriften.
B36: Hausaufgaben | E36: Administratives

Sheet ST_9_KW_14
B1: Unterrichtsverlauf | E1: =Kompetenzraster!Q21 -> 46117 | G1: 9
B3: Installieren von Wasserleitungen | F3: 6.7 | G3: Filme / Theorie
B5: 1 - 3 Lektion | C5: Prüfung Auftrag 6.4 | F5: 30min
C7: Auftrag 1
C8: * Einstieg mit Demoraum "Druckverlust"
C9: * Klasse halbiert / Schulzimmer bearbeitet Frage 2-5
C11: Auftrag 2
C12: * Erste Druckverlustberechnung gemeinsam ausführen.
C14: Lernziele
C15: * Sie erklären den Zusammenhang zwischen Volumenstrom,Fliessgeschwindigkeit,
C16: Druckverlust und Rohrdurchmessern.
B18: Pause
B20: Detailplanung Sanitärapparate | F20: 6.3 | G20: Filme / Theorie
B22: 4 - 5 Lektion | C22: Prüfung Auftrag 6.1 | F22: 50min
C27: Auftrag 1
C28: * Gemeinsames Erstellen einer Strahlvermassung
C29: * Start mit Aufgabe 2
C31: Lernziele
C32: * Sie bestimmen anhand von Beispielen den Platzbedarf, Achsabstände
C33: und Montagehöhen von Apparaten und den zugehörigen Garnituren.
C34: * Sie erstellen anhand von Planunterlagen einen Werkstattplan für
C35: eine Vorwand.
B36: Hausaufgaben | E36: Administratives

Sheet ST_10_KW_15
B1: Unterrichtsverlauf | E1: =Kompetenzraster!Q23 -> 46138 | G1: 10
B3: Installieren von Wasserleitungen | F3: 6.7 | G3: Filme / Theorie
B5: 1 - 3 Lektion
C6: Auftrag 2
C7: * Korrektur Druckverlustberechnung Aufgabe 5
C8: *Berechnungen ausführen und besprechen
C14: Lernziele
C15: * Sie erklären den Zusammenhang zwischen Volumenstrom,Fliessgeschwindigkeit,
C16: Druckverlust und Rohrdurchmessern.
B18: Pause
B20: Detailplanung Sanitärapparate | F20: 6.3 | G20: Filme / Theorie
B22: 4 - 5 Lektion
C23: Auftrag 1
C24: * Aufgaben lösen und besprechen
C31: Lernziele
C32: * Sie bestimmen anhand von Beispielen den Platzbedarf, Achsabstände
C33: und Montagehöhen von Apparaten und den zugehörigen Garnituren.
C34: * Sie erstellen anhand von Planunterlagen einen Werkstattplan für
C35: eine Vorwand.
B36: Hausaufgaben | E36: Administratives

Sheet ST_11_KW_16
B1: Unterrichtsverlauf | E1: =Kompetenzraster!Q25 -> 46145 | G1: 11
B3: Installieren von Wasserleitungen | F3: 6.7 | G3: Filme / Theorie
B5: 1 - 3 Lektion
C6: * Einstieg mit Quizacademy Quiz * Hydraulik*
C8: Auftrag 3
C9: * Start echte Aufgaben Dimensionieren / Ausstosszeit & Druckverlust
C14: Lernziele
C15: * Sie erklären den Zusammenhang zwischen Volumenstrom,Fliessgeschwindigkeit,
C16: Druckverlust und Rohrdurchmessern.
B18: Pause
B20: Detailplanung Sanitärapparate | F20: 6.3 | G20: Filme / Theorie
B22: 4 - 5 Lektion
C23: Auftrag 1
C24: * Aufgaben lösen und besprechen
C31: Lernziele
C32: * Sie bestimmen anhand von Beispielen den Platzbedarf, Achsabstände
C33: und Montagehöhen von Apparaten und den zugehörigen Garnituren.
C34: * Sie erstellen anhand von Planunterlagen einen Werkstattplan für
C35: eine Vorwand.
B36: Hausaufgaben | E36: Administratives

Sheet ST_12_KW_17
B1: Unterrichtsverlauf | E1: =Kompetenzraster!Q27 -> 46152 | G1: 12
B3: Installieren von Wasserleitungen | F3: 6.7 | G3: Filme / Theorie
B5: 1 - 3 Lektion
C6: Auftrag 4
C7: * Start Dimensionierung / Ausstosszeiten und Druckverlust
C8: * Evtl. Start mit Cast über Hydraulik in Rohrleitungen
C14: Lernziele
C15: * Sie erklären den Zusammenhang zwischen Volumenstrom,Fliessgeschwindigkeit,
C16: Druckverlust und Rohrdurchmessern.
B18: Pause
B20: Detailplanung Sanitärapparate | F20: 6.3 | G20: Filme / Theorie
B22: 4 - 5 Lektion
C23: Auftrag 1
C24: * Start mit Leistungsnachweis
C31: Lernziele
C32: * Sie bestimmen anhand von Beispielen den Platzbedarf, Achsabstände
C33: und Montagehöhen von Apparaten und den zugehörigen Garnituren.
C34: * Sie erstellen anhand von Planunterlagen einen Werkstattplan für
C35: eine Vorwand.
B36: Hausaufgaben | E36: Administratives

Sheet ST_13_KW_18
B1: Unterrichtsverlauf | E1: =Kompetenzraster!Q29 -> 46159 | G1: 13
B3: Installieren von Wasserleitungen | F3: 6.7 | G3: Filme / Theorie
B5: 1 - 3 Lektion
C6: Auftrag 4
C7: * Korrektur & Besprechung Aufgabe 14
C8: * Start mit Cast zum Thema Rohrleitungen
C9: => individueller Übergang zu AVOR X-Mass
G11: Lernziele / Prüfung
C14: Lernziele
C15: * Sie erklären den Zusammenhang zwischen Volumenstrom,Fliessgeschwindigkeit,
C16: Druckverlust und Rohrdurchmessern.
B18: Pause
B20: Werkstattplan erstellen | F20: 6.2 | G20: Filme / Theorie
B22: 4 - 5 Lektion
C23: Auftrag 2
C24: * Start mit Leistungsnachweis "Einlagen richten"
C31: Lernziele
C32: • Sie kennen die Grundlagen der X-Mass Methode und wenden diese
C33: in einfachen Beispielen an.
C34: • Sie erstellen selbstständig einfache X-Mass Vorfabrikationszeichnunge
C35: inkl. Rohrlängen und Stückliste.
B36: Hausaufgaben | E36: Administratives

Sheet ST_14_KW_21
B1: Unterrichtsverlauf | E1: =Kompetenzraster!Q31 -> 46166 | G1: 14
B3: Hygiene in der Sanitärtechnik | F3: 6.8 | G3: Filme / Theorie
B5: 1 - 3 Lektion | C5: Prüfung Auftrag 6.7 | F5: 30min
C6: Situation
C7: * Einstieg mit Schema MFH
C9: Auftrag 1
C10: * Erstellung MindMap "Hygienische Anforderungen"
C11: Auftrag 2
C12: * Fragen 1 - 7 beantworten und besprechen
C14: Lernziele
C15: * Sie erklären die hygienischen Anforderungen an Sanitäranlagen gemäss Vorschriften.
C16: * Sie erklären die gebräuchlichen Anlagenteile in einfachen Worten.
C17: * Sie erläutern Sinn und Zweck der Werkübergabe.
C18: * Sie erläutern die Bedeutung von Revisionsplänen.
C19: * Sie erstellen ein Materialausmass anhand von verschiedenen Beispielen.
B20: Pause
B22: Werkstattplan erstellen | F22: 6.2 | G22: Filme / Theorie
B24: 4 - 5 Lektion
C25: Auftrag 2
C26: * Arbeit an Leistungsnachweis "Einlagen richten"
C32: Lernziele
C33: • Sie kennen die Grundlagen der X-Mass Methode und wenden diese
C34: in einfachen Beispielen an.
C35: • Sie erstellen selbstständig einfache X-Mass Vorfabrikationszeichnunge
C36: inkl. Rohrlängen und Stückliste.
B37: Hausaufgaben | E37: Administratives

Sheet ST_15_KW_22
B1: Unterrichtsverlauf | E1: =Kompetenzraster!Q33 -> 46173 | G1: 15
B3: Hygiene in der Sanitärtechnik | F3: 6.8 | G3: Filme / Theorie
B5: 1 - 3 Lektion
C6: Auftrag 2
C7: * Fragen 1 - 7 beantworten und besprechen
C9: Leistungsnachweis
C10: * Leistungsnachweis bearbeiten
C14: Lernziele
C15: * Sie erklären die hygienischen Anforderungen an Sanitäranlagen gemäss Vorschriften.
C16: * Sie erklären die gebräuchlichen Anlagenteile in einfachen Worten.
C17: * Sie erläutern Sinn und Zweck der Werkübergabe.
C18: * Sie erläutern die Bedeutung von Revisionsplänen.
C19: * Sie erstellen ein Materialausmass anhand von verschiedenen Beispielen.
B20: Pause
B22: Werkstattplan erstellen | F22: 6.2 | G22: Filme / Theorie
B24: 4 - 5 Lektion
C25: Auftrag 2
C26: * Arbeit an Leistungsnachweis "Einlagen richten"
C32: Lernziele
C33: • Sie kennen die Grundlagen der X-Mass Methode und wenden diese
C34: in einfachen Beispielen an.
C35: • Sie erstellen selbstständig einfache X-Mass Vorfabrikationszeichnunge
C36: inkl. Rohrlängen und Stückliste.
B37: Hausaufgaben | E37: Administratives

Sheet ST_16_KW_23
B1: Unterrichtsverlauf | E1: =Kompetenzraster!Q35 -> 46180 | G1: 16
B3: Vorb. Qualifikationsverfahren | F3: 6.11 | G3: Filme / Theorie
B5: 1 - 3 Lektion
C6: Einstieg
C7: * Erklärung der zu behandelnden Handlungskompetenzbereiche
C9: Gruppen / Einteilung
C11: Leistungsnachweis
C12: * Abgabe der Lernkarten ist direkt Leistungsnachweis
C15: Lernziele
C16: * Erstellung von Lernkarten für die Vorbereitung Qualifikationsverfahren.
B19: Pause
B21: Vorb. Qualifikationsverfahren | F21: 6.11 | G21: Filme / Theorie
B23: 4 - 5 Lektion
C24: Leistungsnachweis
C25: * Abgabe der Lernkarten ist direkt Leistungsnachweis
C32: Lernziele
C33: * Erstellung von Lernkarten für die Vorbereitung Qualifikationsverfahren.
B36: Hausaufgaben | E36: Administratives

Sheet ST_17_KW_23
B1: Unterrichtsverlauf | E1: =Kompetenzraster!Q37 -> 46187 | G1: 17
B3: Exkursion JRG / GF Piping Systems | F3: 6.1
B5: ganzer Tag | C5: Lernziele
C6: *Sie erklären die hygienischen Anforderungen an Sanitäranlagen gemäss den Vorschriften.
C7: *Sie erklären den Zusammenhang zwischen Volumenstrom, Fliessgeschwindigkeit,
C8: Druckverlust und Rohrdurchmessern.

Sheet ST_18_KW_24
B1: Unterrichtsverlauf | E1: =Kompetenzraster!Q39 -> 46194 | G1: 18
B3: Projektarbeit 6.Semester | F3: 6.9 | G3: Filme / Theorie
B5: 1 - 3 Lektion
C6: Einstieg / Projekt
C7: * Vermittlung der Ziele / Darstellung / Abgabe
C8: * Erklärung der Teilaufgaben
C9: * Reduktion für Lernende die alleine Arbeiten möchten
C11: Arbeit an Projektarbeit
C13: Lernziele
C15: * Sie erstellen anhand von Planunterlagen einen Werkstattplan für eine Vorwand.
C16: * Sie wenden die X- und z-Mass-Methode an verschiedenen Beispielen an.
C17: * Sie erstellen anhand von Planunterlagen, Apparatelisten und Massskizzen
C18: einen massstäblichen Detailplan.
C19: * Sie zeichnen einfache Installationspläne unter Berücksichtigung der relevanten Vorschriften.
C20: * Sie beschreiben die handelsüblichen Vorwandsysteme.
... C23: * Sie bestimmen die Rohrweiten von Trinkwasser-Leitungen anhand der geltenden Vorschriften.
B25: Pause
B27: Projektarbeit 6.Semester | F27: 6.9 | G27: Filme / Theorie
B29: 4 - 5 Lektion
C30: Arbeit an Projektarbeit
C32: Lernziele
B37: Hausaufgaben | E37: Administratives

Sheet ST_19_KW_25
B1: Unterrichtsverlauf | E1: =Kompetenzraster!Q39+7 -> 46201 | G1: 18
B3: Projektarbeit 6.Semester | F3: 6.9 | G3: Filme / Theorie
B5: 1 - 3 Lektion
C6: Arbeit an Projektarbeit
C8: => Hinweis / Erwatungen / Cast
C10: Zeugnisbesprechung
C13: Lernziele
C15: * Sie erstellen anhand von Planunterlagen einen Werkstattplan für eine Vorwand.
C16: * Sie wenden die X- und z-Mass-Methode an verschiedenen Beispielen an.
C17: * Sie erstellen anhand von Planunterlagen, Apparatelisten und Massskizzen
C18: einen massstäblichen Detailplan.
C19: * Sie zeichnen einfache Installationspläne unter Berücksichtigung der relevanten Vorschriften.
C20: * Sie beschreiben die handelsüblichen Vorwandsysteme.
C21: * Sie berechnen den Druck unter Berücksichtigung der Kompressibilität des Wassers.
C22: * Sie beschreiben das korrekte Vorgehen zur Überprüfung der Ausstosszeiten.
C23: * Sie bestimmen die Rohrweiten von Trinkwasser-Leitungen anhand der geltenden Vorschriften.
B25: Pause
B27: Projektarbeit 5.Semester | F27: 6.9 | G27: Filme / Theorie
B29: 4 - 5 Lektion
C30: Abgabe der Projektarbeit
C32: Lernziele
B37: Hausaufgaben | E37: Administratives

Sheet Aufgaben_Teams
B1: Aufgaben Teams
B4: Auftrag 6.1 | C4: Lernziele: - Sie interpretieren und unterscheiden die gebräuchlichen Pläne. - Sie ordnen die gebräuchlichen Plansymbole korrekt zu. - Sie zeichnen einfache Installationspläne unter Berücksichtigung der relevanten Vorschriften, sowie der Ausstosszeiten. Abzugebende Leistungsnachweise: - Leistungsnachweis «Projektierung Grundriss»
B6: Punkte
B7: 2
B8: Zuweisung
B9: =Kompetenzraster!Q5 -> 46061
B10: Abgabe
B11: =Kompetenzraster!Q19-1 -> 46109
B17: Auftrag 6.2 | C17: Lernziele: - Sie erstellen Isometrie-Zeichnungen und berechnen Sie mit der Z und X-Mass Methode. - Sie zeichnen und berechnen stumpfwinklige und "normale" Dreiecke in isometrischen Zeichnungen. - Sie erstellen anhand von isometrischen Zeichnungen vollständige Stücklisten. - Sie erstellen anhand von isometrischen Zeichnungen vollständige Stücklisten Abzugebende Leistungsnachweise: - Individueller Leistungsnachweis "AVOR X-Mass "
B19: Punkte
B20: 3
B21: Zuweisung
B22: =Kompetenzraster!Q27 -> 46152
B23: Abgabe
B24: =Kompetenzraster!Q35-1 -> 46179
B30: Auftrag 6.3 | C30: Lernziele: - Sie bestimmen anhand von Beispielen den Platzbedarf, Achsabstände und Montage­höhen von Apparaten und den zugehörigen Garnituren. - Sie erstellen anhand von Planunterlagen, Apparatelisten und Massskizzen einen massstäblichen Detailplan. (inkl. Leitungsführung) Abzugebende Leistungsnachweise: - Leistungsnachweis "Detailplanung Badezimmer"
B32: Punkte
B33: 0
B34: Zuweisung
B35: =Kompetenzraster!Q19 -> 46110
B36: Abgabe
B37: =Kompetenzraster!Q27-1 -> 46151
B41: Auftrag 6.4 | C41: Lernziele: - Sie beschreiben den Aufbau verschiedener Solaranlagen. - Sie beschreiben die Vorteile von Solaranlagen in Bezug auf die Energieeffizienz. -Sie erläutern die Funktionsweise verschiedener Solaranlagen. - Sie beschreiben die hydraulischen Anschlussmöglichkeiten bei Solaranlagen. - Sie erläutern die wichtigsten Prinzipien der Solarregelung. (K2) Abzugebende Leistungsnachweise: - Leistungsnachweis «Projektierung Solaranlage»
B43: Punkte
B44: 2
B45: Zuweisung
B46: =Kompetenzraster!Q13 -> 46089
B47: Abgabe
B48: =Kompetenzraster!Q23-1 -> 46137
B52: Auftrag 6.5 | C52: Lernziele: - Sie benennen gebräuchliche Ver- und Entsorgungsapparate sowie deren Komponenten. - Sie beschreiben den Aufbau und die Funktion von Pumpen in der Sanitärinstallation. Abzugebende Leistungsnachweise: - Leistungsnachweis «Zirkulation» - Leistungsnachweis «Schmutzwasser - Hebeanlage»
B54: Punkte
B55: 1.5
B56: Zuweisung
B57: 46567
B58: Abgabe
B59: 46573
B64: Auftrag 6.7 | C64: Lernziele: - Sie erklären den Zusammenhang zwischen Volumenstrom Fliessgeschwindigkeit, Druckverlust und Rohrdurchmessern. - Sie erklären die hygienischen Anforderungen an Sanitäranlagen gemäss den Vorschriften. Abzugebende Leistungsnachweise: - Leistungsnachweis «Druckverlust & Ausstosszeiten»
B66: Punkte
B67: 0
B68: Zuweisung
...
