Workbook

Sheet Kompetenzraster
B1: Kompetenzraster 7.Semester Sanitärinstallateur/in EFZ | I1: Semesterstart: | J1: 45152 | K1: Schultag: | L1: Mittwoch
B3: Handlungsfelder und Kompetenzen | M3: Bewertung / Benotung | Q3: Unterichtsplanung 7. Semester
B5: HF 1 | E5: Auftrag 7.1 | G5: Auftrag 7.2 | M5: Note Leistungsnachweis | Q5: =J1+2 -> 45154 | R5: San. Anlagen (Enthärtungsanlage)
E6: 10 Schultage (20L) | G6: 6 Schultage (12L) | M6: Die Note aus den Leistungsnachweisen berechnet sich aus den während des Semestes erzielten Punkten. | Q6: 7.3 I 7.1 | R6: Installationspläne erstellen (Schema)
B7: Planen der Arbeiten | E7: Sie zeichnen einfache Installationspläne unter Berücksichtigung der relevanten Vorschriften. | F7: Sie bestimmen die Rohrweiten von Trinkwasser- Schmutzwasser- und Gasleitungen anhand der geltenden Vorschriften | G7: Sie wenden die X- und z-Mass-Methode an verschiedenen Beispielen an. | H7: Sie erstellen genaue und vollständige Isometrie-Zeichnungen anhand von Planunterlagen. | I7: Sie berechnen rechtwinklige Dreiecke. | Q7: =Q5+7 -> 45161 | R7: San. Anlagen (Enthärtungsanlage)
Q8: 7.3 I 7.1 | R8: Installationspläne erstellen (Schema)
Q9: =Q7+7 -> 45168 | R9: San. Anlagen (Enthärtungsanlage)
E10: Sie bestimmen die Grösse eines Wassererwärmers anhand der geltenden Vorschriften. (K3 | H10: Sie erstellen anhand von isometrischen Zeichnungen vollständige Stücklisten. | I10: Sie bestimmen stumpfwinklige Dreiecke anhand der Tabellen. | M10: Auftrag 7.1 | N10: 3 | Q10: 7.3 I 7.1 | R10: Installationspläne erstellen (Schema)
M11: Auftrag 7.2 | N11: 3 | Q11: =Q9+7 -> 45175 | R11: Trinkwasserleitungen in Betrieb nehmen
M12: Auftrag 7.3 | N12: 1.5 | Q12: 7.6 I 7.1 | R12: Installationspläne erstellen (Schema)
M13: Auftrag 7.4 | N13: 2 | Q13: =Q11+7 -> 45182 | R13: Trinkwasserleitungen in Betrieb nehmen
B14: HF 6 | E14: Auftrag 7.3 | G14: Auftrag 7.4 | M14: Auftrag 7.5 | N14: 2 | Q14: 7.6 I 7.1 | R14: Installationspläne erstellen (Schema)
E15: 3 Schultage (9L) | G15: 4 Schultage (12L) | M15: Auftrag 7.6 | N15: 2 | Q15: =Q13+7 -> 45189 | R15: Trinkwasserleitungen in Betrieb nehmen
B16: Montieren von sanitären Anlagen und Apparaten | E16: Sie benennen gebräuchliche Ver- und Entsorgungsapparate sowie deren Komponenten. | F16: Sie beschreiben den Aufbau und die Funktion einer Enthärtungsanlage. | G16: Sie benennen gebräuchliche Ver- und Entsorgungsapparate sowie deren Komponenten. | H16: Sie erläutern die Unterschiede der verschiedenen Systeme der Wassererwärmung in Bezug auf die Energieeffizienz. | I16: Sie berechnen die benötigten Wassermengen zur Erreichung gewünschter Tempearaturen beim Mischen von Wasser. | M16: Auftrag 7.7 | N16: 4 | Q16: 7.6 I 7.1 | R16: Installationspläne erstellen (Schema)
M17: Auftrag 7.8 | N17: 1.5 | Q17: =Q15+7 -> 45196 | R17: Trinkwasserleitungen in Betrieb nehmen
M18: Auftrag 7.11 | N18: 1 | Q18: 7.6 I 7.1 | R18: Installationspläne erstellen (Schema)
G19: Sie beschreiben den Aufbau und die Funktion einer Wärmepumpe. | M19: Punkte max. | N19: =SUM(N10:N18) -> 20 | Q19: =Q17+28 -> 45224 | R19: Wartungsarbeiten ausführen
Q20: 7.5 I 7.1 | R20: Installationspläne erstellen (Schema)
Q21: =Q19+7 -> 45231 | R21: Wartungsarbeiten ausführen
O22: X | Q22: 7.5 I 7.1 | R22: Installationspläne erstellen (Schema)
B23: HF 6 | E23: Auftrag 7.5 | H23: Auftrag 7.6 | J23: Auftrag 7.8 | M23: Noten Prüfungen | Q23: =Q21+7 -> 45238 | R23: Vorbereitungsauftrag ÜK 7
E24: 3 Schultage (9L) | H24: 3 Schultage (9L) | J24: 1 Schultag (5L) | M24: Zu jedem Auftrag wird im Unterricht eine kurze Zwischenprüfung geschrieben. | Q24: 7.5 I 7.1 | R24: Installationspläne erstellen (Schema)
B25: Montieren von sanitären Anlagen und Apparaten | E25: Sie benennen die Ersatzteile von Spülkästen und Armaturen und erklären deren Funktion. | F25: Sie erklären die gebräuchlichen Anla- genteile in einfachen Worten. (K2) | G25: Sie beschreiben die wesentlichen Wartungsintervalle und Arbeiten einer sanitären Installation. (K2) | H25: Sie erklären den Zusammenhang zwischen Volumenstrom, Fliess- geschwindigkeit, Druckverlust und Rohrdurchmessern. (K2) | I25: Sie erklären die hygienischen Anforde- rungen an Sanitäranlagen gemäss den geltenden Vorschriften. (K2) | J25: Sie zeichnen einfache Installationspläne unter Berücksichtigung der relevanten Vorschriften. | K25: Sie erstellen selbstständig einfache X-Mass Vorfabrikationszeichnungen inkl. Rohrlängen und Stücklisten. | Q25: =Q23+7 -> 45245 | R25: Vorbereitungsauftrag ÜK 7
Q26: 7.4 I 7.2 | R26: Werkstattplanung AVOR X-Z Mass
Q27: =Q25+7 -> 45252 | R27: San. Anlagen (Wärmepumpe)
J28: Sie erstellen anhand von Planunterlagen einen Werkstattplan für eine Vorwand. | M28: Zeugnisnote | Q28: 7.4 I 7.2 | R28: Werkstattplanung AVOR X-Z Mass
M29: Die Note aus den Lernprodukten zählt zu 30%. Alle Noten der Prüfungen zählen zu 60%. | Q29: =Q27+7 -> 45259 | R29: San. Anlagen (Wärmepumpe)
Q30: 7.4 I 7.2 | R30: Werkstattplanung AVOR X-Z Mass
Q31: =Q29+7 -> 45266 | R31: San. Anlagen (Wärmepumpe)
B32: HF 1/2/3/4/5/6/7 | E32: Auftrag 7.7 | H32: Auftrag 7.9 | J32: Auftrag 7.11 | Q32: 7.4 I 7.2 | R32: Werkstattplanung AVOR X-Z Mass
E33: 2 Schultage (10L) | H33: 0.5 Schultage (3L) | J33: 1 Schultage (6L) | M33: Gesetzliche Feiertage | Q33: =Q31+7 -> 45273 | R33: San. Anlagen (Wärmepumpe)
B34: Vernetzung aller Handlungsfelder | E34: Sie erstellen anhand von Planunterla- gen und Massskizzen einen massstäblichen Detailplan. | F34: Sie erstellen anhand von Planunterlagen einen Werkstattplan für eine Vorwand. | G34: Sie erklären die gebräuchlichen Anla- genteile in einfachen Worten. (K2) | H34: Sie wissen, was am Qualifikationsverfahren von Ihnen gefordert wird. | I34: Sie wissen wann Sie welche Inhalte lernen. | J34: QV Vorbereitung Trinkwasserleitungen & Planen der Arbeiten Sie erstellen selbstständig Lernkarten zu den Grundlagenkenntnissen im Bereich Trinkwasserleitungen und Planen der Arbeiten. | M34: Allerheiligen | N34: 45231 | Q34: 7.4 I 7.2 | R34: Werkstattplanung AVOR X-Z Mass
M35: Karfreitag | N35: 45380 | Q35: =Q33+7 -> 45280 | R35: QV Vorbereitung / Fahrplan 2024
M36: Ostermontag | N36: 45383 | Q36: 7.9 I 7.2 | R36: Werkstattplanung AVOR X-Z Mass
E37: Sie erstellen ein Materialausmass anhand von verschiedenen Beispielen. | F37: Sie zeichnen einfache Installationspläne unter Berücksichtigung der relevanten Vorschriften. | G37: Sie beschreiben die wesentlichen Wartungsintervalle einer sanitären Installation. (K2) | M37: Auffahrt | N37: 45421 | Q37: =Q35+21 -> 45301 | R37: QV Vorbereitung / Lernkarten
M38: Pfingstmontag | N38: 45432 | Q38: 7.11 I 7.2 | R38: Werkstattplanung AVOR X-Z Mass
Q39: =Q37+7 -> 45308 | R39: Projektarbeit
B41: Fachgruppe Sanitär Spengler | K41: itm I sanitärlernen.ch

Sheet ST_1_KW_33
B1: Unterrichtsverlauf | E1: =Kompetenzraster!Q5 -> 45154 | G1: 1
B3: Versorgungsapparate montieren | F3: 7.3 | G3: Filme / Theorie
B5: 1 - 3 Lektion
C6: Auftrag 1
C7: * Einstieg mit Kurzvideo "Wie kommt der Kalk ins Wasser"
C8: * Abschnitt im Lehrmittel lesen und Einstiegfragen beantworten
C9: * Recherche "Mein Trinkwasser der Gemeinde"
C11: Auftrag 2
C12: * Recherche W3 / Einbau von Wassernachbehandlungsanlagen
C14: Auftrag 3
C15: * Vorbereitung Expertenpuzzle als Einstieg für nächste Woche
C17: Lernziele
C18: * Sie benennen gebräuchliche Ver- und Entsorgungsapparate sowie deren Komponenten.
C19: * Sie beschreiben den Aufbau und die Funktion einer Enthärtungsanlage
B22: Pause
B24: Installationspläne erstellen | F24: 7.1 | G24: Filme / Theorie
B26: 4 - 5 Lektion
C27: Auftrag 1
C28: * Gemeinsames Betrachten des Schemas im Lehrmittel
C29: * Hinweis zur Repetition => Erstellung Grundriss als Vorbereitung
C30: * Gemeinsames Zeichnen relevanter Schemasymbole als Grundlage
C32: Lernziele
C33: * Sie zeichnen einfache Installationspläne unter Berücksichtigung der relevanten Vorschriften.
C34: * Sie zeichnen einfache Schemapläne unter Berücksichtigung der relevanten Vorschriften.
B38: Hausaufgaben | E38: Administratives

Sheet ST_2_KW_34
B1: Unterrichtsverlauf | E1: =Kompetenzraster!Q7 -> 45161 | G1: 2
B3: Versorgungsapparate montieren | F3: 7.3 | G3: Filme / Theorie
B5: 1 - 3 Lektion
C6: Auftrag 3
C7: * Durchführung Expertenpuzzle als Einstieg in Thematik
C9: Auftrag 4
C10: * Einführung und Besprechung Enthärtungsanlage.
C11: * Klasse halbiert / Demoraum / Enthärtung betrachten.
C12: * Auftrag besprechen / Letzte Fragen klären.
C17: Lernziele
C18: * Sie benennen gebräuchliche Ver- und Entsorgungsapparate sowie deren Komponenten.
C19: * Sie beschreiben den Aufbau und die Funktion einer Enthärtungsanlage
B22: Pause
B24: Installationspläne erstellen | F24: 7.1 | G24: Filme / Theorie
B26: 4 - 5 Lektion
C27: Auftrag 1
C28: * Einzelne Schemazeichnungen vervollständigen
C29: Auftrag 2
C30: * Start mit EFH Fraun - gemeinsames Zeichnen
C32: Lernziele
C33: * Sie zeichnen einfache Installationspläne unter Berücksichtigung der relevanten Vorschriften.
C34: * Sie zeichnen einfache Schemapläne unter Berücksichtigung der relevanten Vorschriften.
B38: Hausaufgaben | E38: Administratives

Sheet ST_3_KW_35
B1: Unterrichtsverlauf | E1: =Kompetenzraster!Q9 -> 45168 | G1: 3
B3: Versorgungsapparate montieren | F3: 7.3 | G3: Filme / Theorie
B5: 1 - 3 Lektion
C6: Auftrag 4
C7: * Einstieg mit Quizacademy | E7: (30Sek)
C8: * Besprechung verbleibende Fragen aus Auftrag 4 (HA)
C9: * Abgabe und Instruktion Leistungsnachweis
C11: Einrichten / Vorstellung TopinSan
C12: * Vorstellung & Idee
C13: * Einladungen managen und erste Gehversuche
G14: Lernziele / Prüfung
C15: Link zu TopinSan
C17: Lernziele
C18: * Sie benennen gebräuchliche Ver- und Entsorgungsapparate sowie deren Komponenten.
C19: * Sie beschreiben den Aufbau und die Funktion einer Enthärtungsanlage
B22: Pause
B24: Installationspläne erstellen | F24: 7.1 | G24: Filme / Theorie
B26: 4 - 5 Lektion
C27: Auftrag 2
C28: * Aufgabe EFH Kauns lösen
C29: * Schema kontrollieren => Lehrperson
C32: Lernziele
C33: * Sie zeichnen einfache Installationspläne unter Berücksichtigung der relevanten Vorschriften.
C34: * Sie zeichnen einfache Schemapläne unter Berücksichtigung der relevanten Vorschriften.
B38: Hausaufgaben | E38: Administratives

Sheet ST_4_KW_36
B1: Unterrichtsverlauf | E1: =Kompetenzraster!Q11 -> 45175 | G1: 4
B3: Wasserleitungen in Betrieb nehmen | F3: 7.6 | G3: Filme / Theorie
B5: 1 - 3 Lektion | C5: Prüfung Auftrag 7.3 | F5: 30min
C7: Einstieg
C8: * Gruppendiskussion zum Thema Legionellen
C9: Auftrag 1
C10: * Filmbeitrag Legionellen
C11: * Bearbeitung und Besprechung Fragen 1-6
C12: * Hinweis Wasserprobe GBS
C13: * Technische Lösungen gegen Legionellen => Lehrmittel
C14: * Bearbeitung und Besprechung Fragen 7-10
C15: ?? Top in San ??
C17: Lernziele
C18: * Sie erklären die hygienischen Anforderungen an Sanitäranlagen
C19: gemäss den geltenden Vorschriften.
... C21: Fliessgeschwindigkeit, Druckverlust und Rohrdurchmessern.
B22: Pause
B24: Installationspläne erstellen | F24: 7.1 | G24: Filme / Theorie
B26: 4 - 5 Lektion
C27: Auftrag 3
C28: * Aufgabe EFH Psi lösen
G30: Lernziele / Prüfung
C33: Lernziele
C34: * Sie zeichnen einfache Installationspläne unter Berücksichtigung der relevanten Vorschriften.
C35: * Sie zeichnen einfache Schemapläne unter Berücksichtigung der relevanten Vorschriften.
B39: Hausaufgaben | E39: Administratives

Sheet ST_5_KW_37
B1: Unterrichtsverlauf | E1: =Kompetenzraster!Q13 -> 45182 | G1: 5
B3: Wasserleitungen in Betrieb nehmen | F3: 7.6 | G3: Filme / Theorie
B5: 1 - 3 Lektion
C6: Auftrag 2
C7: * Theorie gemeinsam herleiten - > Formeln kennen lernen
C8: * Fliessgeschwindigkeiten definieren / festhalten gem. W3
C9: * Erste Berechnungen gemeinsam lösen
C10: * Übungen selbstständig lösen
C17: Lernziele
C18: * Sie erklären die hygienischen Anforderungen an Sanitäranlagen
C19: gemäss den geltenden Vorschriften.
C20: * Sie erklären den Zusammenhang zwischen Volumenstrom
C21: Fliessgeschwindigkeit, Druckverlust und Rohrdurchmessern.
B22: Pause
B24: Installationspläne erstellen | F24: 7.1 | G24: Filme / Theorie
B26: 4 - 5 Lektion
C27: Auftrag 3
C28: * Aufgabe EFH Leermoos
C32: Prüfung 1 Auftrag 7.1 | F32: 20min
C33: Lernziele
C34: * Sie zeichnen einfache Installationspläne unter Berücksichtigung der relevanten Vorschriften.
C35: * Sie zeichnen einfache Schemapläne unter Berücksichtigung der relevanten Vorschriften.
B39: Hausaufgaben | E39: Administratives

Sheet ST_6_KW_38
B1: Unterrichtsverlauf | E1: =Kompetenzraster!Q15 -> 45189 | G1: 6
B3: Wasserleitungen in Betrieb nehmen | F3: 7.6 | G3: Filme / Theorie
B5: 1 - 3 Lektion
C6: Auftrag 2
C7: Quiz / Einstieg Fliessgeschwindigkeit
C9: Auftrag 3
C10: * Gemeinsames Erarbeiten des Auftrages 3
C11: * Hinweis zu einzelnen Themen
C17: Lernziele
C18: * Sie erklären die hygienischen Anforderungen an Sanitäranlagen
C19: gemäss den geltenden Vorschriften.
C20: * Sie erklären den Zusammenhang zwischen Volumenstrom
C21: Fliessgeschwindigkeit, Druckverlust und Rohrdurchmessern.
B22: Pause
B24: Installationspläne erstellen | F24: 7.1 | G24: Filme / Theorie
B26: 4 - 5 Lektion
C27: Auftrag 3
C28: * Aufgabe EFH Engelburg
C33: Lernziele
C34: * Sie zeichnen einfache Installationspläne unter Berücksichtigung der relevanten Vorschriften.
C35: * Sie zeichnen einfache Schemapläne unter Berücksichtigung der relevanten Vorschriften.
B39: Hausaufgaben | E39: Administratives

Sheet ST_7_KW_39
B1: Unterrichtsverlauf | E1: =Kompetenzraster!Q17 -> 45196 | G1: 7
B3: Wasserleitungen in Betrieb nehmen | F3: 7.6 | G3: Filme / Theorie
B5: 1 - 3 Lektion
C6: Auftrag 4
C7: Leistungsnachweis lösen
G14: Lernziele / Prüfung
C17: Lernziele
C18: * Sie erklären die hygienischen Anforderungen an Sanitäranlagen
C19: gemäss den geltenden Vorschriften.
C20: * Sie erklären den Zusammenhang zwischen Volumenstrom
C21: Fliessgeschwindigkeit, Druckverlust und Rohrdurchmessern.
B22: Pause
B24: Installationspläne erstellen | F24: 7.1 | G24: Filme / Theorie
B26: 4 - 5 Lektion
C27: Auftrag 4
C28: * Aufgabe EFH Neudorf
C33: Lernziele
C34: * Sie zeichnen einfache Installationspläne unter Berücksichtigung der relevanten Vorschriften.
C35: * Sie zeichnen einfache Schemapläne unter Berücksichtigung der relevanten Vorschriften.
B39: Hausaufgaben | E39: Administratives

Sheet ST_8_KW_43
B1: Unterrichtsverlauf | E1: =Kompetenzraster!Q19 -> 45224 | G1: 8
B3: Wartungsarbeiten ausführen | F3: 7.5 | G3: Filme / Theorie
B5: 1 - 3 Lektion | C5: Prüfung Auftrag 7.6 | F5: 20min
C6: Auftrag 1
C7: * Einstiegsfragen 1-4 lösen / Beantworten in Diskussionsrunde
C8: * Aufgabe 5 / Erarbeitung Mind - Map / Übersicht Wartung von Anlagen
C9: * Zu erledigende Arbeiten vor dem Ausführen eines Serviceauftrages
C10: => Aufgabe 6 - 7
C12: => Aufgabe 8 -13 als Vorbereitung 7 HA
C17: Lernziele
C18: * Sie benennen die Ersatzteile von Spülkästen und Armaturen und erklären deren Funktion.
C19: * Sie beschreiben die wesentlichen Wartungsintervalle und Arbeiten einer sanitären Installation.
C20: * Sie erklären die gebräuchlichen Anlagenteile in einfachen Worten.
B22: Pause
B24: Installationspläne erstellen | F24: 7.1 | G24: Filme / Theorie
B26: 4 - 5 Lektion
C27: Auftrag 4
C28: * Aufgabe EFH Omega
C33: Lernziele
C34: * Sie zeichnen einfache Installationspläne unter Berücksichtigung der relevanten Vorschriften.
C35: * Sie zeichnen einfache Schemapläne unter Berücksichtigung der relevanten Vorschriften.
B39: Hausaufgaben | E39: Administratives

Sheet ST_9_KW_44
B1: Unterrichtsverlauf | E1: =Kompetenzraster!Q21 -> 45231 | G1: 9
B3: Wartungsarbeiten ausführen | F3: 7.5 | G3: Filme / Theorie
B5: 1 - 3 Lektion
C6: Auftrag 2
C7: * Einstieg mit Serviceauftrag Wartung eines Waschtisch
C8: * Besprechung und Korrektur
C10: Auftrag 3
C11: * Einzelheiten zum Service Wassererwärmer / Fragen 22 - 29
C12: * Abschluss mit Video "Domotec" / Fehler bei der Wartung
C17: Lernziele
C18: * Sie benennen die Ersatzteile von Spülkästen und Armaturen und erklären deren Funktion.
C19: * Sie beschreiben die wesentlichen Wartungsintervalle und Arbeiten einer sanitären Installation.
C20: * Sie erklären die gebräuchlichen Anlagenteile in einfachen Worten.
B22: Pause
B24: Installationspläne erstellen | F24: 7.1 | G24: Filme / Theorie
B26: 4 - 5 Lektion
C27: Auftrag 5
C28: * Leistungsnachweis 7.1
G30: Lernziele / Prüfung
C33: Lernziele
C34: * Sie zeichnen einfache Installationspläne unter Berücksichtigung der relevanten Vorschriften.
C35: * Sie zeichnen einfache Schemapläne unter Berücksichtigung der relevanten Vorschriften.
B39: Hausaufgaben | E39: Administratives

Sheet ST_10_KW_45
B1: Unterrichtsverlauf | E1: =Kompetenzraster!Q23 -> 45238 | G1: 10
B3: Vorbereitungsauftrag ÜK 7 | F3: 7.8 | G3: Filme / Theorie
B5: 4 - 5 Lektion
C6: Instruktion / Hinweise zu Auftrag
C17: Lernziele
C18: * Sie zeichnen einfache Installationspläne unter Berücksichtigung der relevanten Vorschriften.
C19: * Sie erstellen anhand von Planunterlagen einen Werkstattplan für eine Vorwand.
C20: * Sie erstellen selbstständig einfache X-Mass Vorfabrikationszeichnungen inkl. Rohrlängen
C21: und Stückliste.
B22: Pause
B24: Installationspläne erstellen | F24: 7.1 | G24: Filme / Theorie
B26: 4 - 5 Lektion
C27: Auftrag 5
C28: * Leistungsnachweis 7.1
C32: Prüfung 1 Auftrag 7.1 | F32: 65min
C33: Lernziele
C34: * Sie zeichnen einfache Installationspläne unter Berücksichtigung der relevanten Vorschriften.
C35: * Sie zeichnen einfache Schemapläne unter Berücksichtigung der relevanten Vorschriften.
B39: Hausaufgaben | E39: Administratives

Sheet ST_11_KW_46
B1: Unterrichtsverlauf | E1: =Kompetenzraster!Q25 -> 45245 | G1: 11
B3: Vorbereitungsauftrag ÜK 7 | F3: 7.8 | G3: Filme / Theorie
B5: 4 - 5 Lektion
C6: Instruktion / Hinweise zu Auftrag
C17: Lernziele
C18: * Sie zeichnen einfache Installationspläne unter Berücksichtigung der relevanten Vorschriften.
C19: * Sie erstellen anhand von Planunterlagen einen Werkstattplan für eine Vorwand.
C20: * Sie erstellen selbstständig einfache X-Mass Vorfabrikationszeichnungen inkl. Rohrlängen
C21: und Stückliste.
B22: Pause
B24: Arbeitsvorbereitung AVOR X-Mass | F24: 7.2 | G24: Filme / Theorie
B26: 4 - 5 Lektion
C27: Einstieg
C28: * Gruppendiskussion zum Thema Verschränkungen / Bezug ÜK
C30: Auftrag 1
C31: * Verschränkungen aufzeichnen / Einfache Beispiele
C33: Lernziele
C34: * Sie kennen die Grundlagen der X-Mass Methode und wenden
C35: diese in einfachen Beispielen an.
C36: * Sie erstellen selbstständig X-Mass Vorfabrikationszeichnungen inkl.
C37: Rohrlängen und Stücklisten.
B39: Hausaufgaben | E39: Administratives

Sheet ST_12_KW_47
B1: Unterrichtsverlauf | E1: =Kompetenzraster!Q27 -> 45252 | G1: 12
B3: Versorgungsapparate montieren | F3: 7.4 | G3: Filme / Theorie
B5: 1 - 3 Lektion
C6: Korrektur / Auftrag / ÜK => Schwerpunkt X-Mass
C8: Einstieg / Gruppendiskussion => Wärmepumpe / Flipchart
C10: Auftrag 1
C11: * Theorie lesen / Einstigesfragen 1 - 5 beantworten.
C13: Auftrag 2
C14: * Video der Funktion schauen / Funktionsweise erläutern!
C15: * Fragen 6-9 erarbeiten und besprechen
C17: Lernziele
C18: * Sie benennen gebräuchliche Ver- und Entsorgungsapparate sowie deren Komponenten.
C19: * Sie beschreiben den Aufbau und die Funktion einer Wärmepumpe
C20: * Sie erläutern die verschiedenen Systeme der Wassererwärmung in Bezug auf die Energieffizienz.
C21: * Sie berechnen die benötigten Wassermengen zur Erreichung gewünschter Temperaturen.
B22: Pause
B24: Arbeitsvorbereitung AVOR X-Mass | F24: 7.2 | G24: Filme / Theorie
B26: 4 - 5 Lektion
C27: Auftrag 1
C28: * Verschränkungen aufzeichnen / Einfache Beispiele
C29: * Komplexere Beispiele lösen….
C33: Lernziele
C34: * Sie kennen die Grundlagen der X-Mass Methode und wenden
C35: diese in einfachen Beispielen an.
C36: * Sie erstellen selbstständig X-Mass Vorfabrikationszeichnungen inkl.
C37: Rohrlängen und Stücklisten.
B39: Hausaufgaben | E39: Administratives

Sheet ST_13_KW_48
B1: Unterrichtsverlauf | E1: =Kompetenzraster!Q29 -> 45259 | G1: 13
B3: Versorgungsapparate montieren | F3: 7.4 | G3: Filme / Theorie
B5: 1 - 3 Lektion
C6: Quiz oder irgendwas zum Einstieg machen….
C8: Auftrag 3
C10: * Wirkungsgrad berechnen / Einstieg mit Versuch
C11: * Theorie herleiten und Bezug zur Wärmelehre
C12: * Berechnungen lösen und üben…
C17: Lernziele
C18: * Sie benennen gebräuchliche Ver- und Entsorgungsapparate sowie deren Komponenten.
C19: * Sie beschreiben den Aufbau und die Funktion einer Wärmepumpe
C20: * Sie erläutern die verschiedenen Systeme der Wassererwärmung in Bezug auf die Energieffizienz.
C21: * Sie berechnen die benötigten Wassermengen zur Erreichung gewünschter Temperaturen.
B22: Pause
B24: Arbeitsvorbereitung AVOR X-Mass | F24: 7.2 | G24: Filme / Theorie
B26: 4 - 5 Lektion
C27: Auftrag 3
C28: * Kombinierte Aufgaben lösen
C29: * Aufgabe "Alpha"
C33: Lernziele
C34: * Sie kennen die Grundlagen der X-Mass Methode und wenden
C35: diese in einfachen Beispielen an.
C36: * Sie erstellen selbstständig X-Mass Vorfabrikationszeichnungen inkl.
C37: Rohrlängen und Stücklisten.
B39: Hausaufgaben | E39: Administratives

Sheet ST_14_KW_49
B1: Unterrichtsverlauf | E1: =Kompetenzraster!Q31 -> 45266 | G1: 14
B3: Versorgungsapparate montieren | F3: 7.4 | G3: Filme / Theorie
B5: 1 - 3 Lektion
C6: Auftrag 4
C8: * Mischwassertemperaturberechnung mit der Formel
C9: * Einstieg mit Situation aus der Praxis / Versuch
C10: * Theorie herleiten und Bezug zur Wärmelehre
C11: * Berechnungen lösen und üben…
C13: * Mischwassermengenberechnung mit dem Mischwasserkreuz
C14: * Erste Berechnung gemeinsam an der Tafel lösen
C15: * Berechnungen lösen und üben…
C17: Lernziele
C18: * Sie benennen gebräuchliche Ver- und Entsorgungsapparate sowie deren Komponenten.
C19: * Sie beschreiben den Aufbau und die Funktion einer Wärmepumpe
C20: * Sie erläutern die verschiedenen Systeme der Wassererwärmung in Bezug auf die Energieffizienz.
C21: * Sie berechnen die benötigten Wassermengen zur Erreichung gewünschter Temperaturen.
B22: Pause
B24: Arbeitsvorbereitung AVOR X-Mass | F24: 7.2 | G24: Filme / Theorie
B26: 4 - 5 Lektion
C27: Auftrag 3
C28: * Kombinierte Aufgaben lösen
C29: * Aufgabe "Beta"
C33: Lernziele
C34: * Sie kennen die Grundlagen der X-Mass Methode und wenden
C35: diese in einfachen Beispielen an.
C36: * Sie erstellen selbstständig X-Mass Vorfabrikationszeichnungen inkl.
C37: Rohrlängen und Stücklisten.
B39: Hausaufgaben | E39: Administratives

Sheet ST_15_KW_50
B1: Unterrichtsverlauf | E1: =Kompetenzraster!Q33 -> 45273 | G1: 15
B3: Versorgungsapparate montieren | F3: 7.4 | G3: Filme / Theorie
B5: 1 - 3 Lektion
C6: Einstieg mit Powepoint "PP_WP_Einstieg_Schultag_4"
C8: * Abgabe und Arbeit an Leistungsnachweis / Abgabe 12.00 Uhr
C15: * Individuell / Arbeit an VA falls gewünscht und gearbeitet wird….
C17: Lernziele
C18: * Sie benennen gebräuchliche Ver- und Entsorgungsapparate sowie deren Komponenten.
C19: * Sie beschreiben den Aufbau und die Funktion einer Wärmepumpe
C20: * Sie erläutern die verschiedenen Systeme der Wassererwärmung in Bezug auf die Energieffizienz.
C21: * Sie berechnen die benötigten Wassermengen zur Erreichung gewünschter Temperaturen.
B22: Pause
B24: Arbeitsvorbereitung AVOR X-Mass | F24: 7.2 | G24: Filme / Theorie
B26: 4 - 5 Lektion
C27: Auftrag 3
C28: * Kombinierte Aufgaben lösen
C29: * Aufgabe "Gamma"
C33: Lernziele
C34: * Sie kennen die Grundlagen der X-Mass Methode und wenden
C35: diese in einfachen Beispielen an.
C36: * Sie erstellen selbstständig X-Mass Vorfabrikationszeichnungen inkl.
C37: Rohrlängen und Stücklisten.
B39: Hausaufgaben | E39: Administratives

Sheet ST_16_KW_51
B1: Unterrichtsverlauf | E1: =Kompetenzraster!Q35 -> 45280 | G1: 16
B3: Mein Fahrplan zum QV | F3: 7.9 | G3: Filme / Theorie
B5: 1 - 3 Lektion
C6: Einstieg mit Betrachtung QV / Ablaufplanung
C7: * Was muss ich wann können?
C8: * Wie wird geprüft?
C10: Wie wird was geübt?
C11: * Welche Themen werden in der Schule geübt?
C12: * Was muss ich selbstständig üben?
C14: Erstellung Terminplan | E14: Link Terminplan
C17: Lernziele
C18: * Sie wissen, was am Qualifikationsverfahren von Ihnen gefordert wird.
C19: * Sie wissen, wann Sie welche Themen und Inhalte lernen.
B22: Pause
B24: Arbeitsvorbereitung AVOR X-Mass | F24: 7.2 | G24: Filme / Theorie
B26: 4 - 5 Lektion
C27: Auftrag 3
C28: * Leistungsnachweis
G30: Lernziele / Prüfung
C33: Lernziele
C34: * Sie kennen die Grundlagen der X-Mass Methode und wenden
C35: diese in einfachen Beispielen an.
C36: * Sie erstellen selbstständig X-Mass Vorfabrikationszeichnungen inkl.
C37: Rohrlängen und Stücklisten.
B39: Hausaufgaben | E39: Administratives

Sheet ST_17_KW_2
B1: Unterrichtsverlauf | E1: =Kompetenzraster!Q37 -> 45301 | G1: 17
B3: Vorb. Qualifikationsverfahren | F3: 7.11 | G3: Filme / Theorie
B5: 1 - 3 Lektion
C6: Einstieg
C7: * Erklärung der zu behandelnden Handlungskompetenzbereiche
C9: Gruppen / Einteilung
C11: Leistungsnachweis
C12: * Abgabe der Lernkarten ist direkt Leistungsnachweis
C15: Arbeit bis 09.35
C17: Lernziele
C18: * Sie wissen, was am Qualifikationsverfahren von Ihnen gefordert wird.
C19: * Sie wissen, wann Sie welche Themen und Inhalte lernen.
B22: Pause
B24: Arbeitsvorbereitung AVOR X-Mass | F24: 7.2 | G24: Filme / Theorie
B26: 4 - 5 Lektion | C26: Prüfung 1 Auftrag 7.1 | F26: 105min
C33: Lernziele
C34: * Sie kennen die Grundlagen der X-Mass Methode und wenden
C35: diese in einfachen Beispielen an.
C36: * Sie erstellen selbstständig X-Mass Vorfabrikationszeichnungen inkl.
C37: Rohrlängen und Stücklisten.
B39: Hausaufgaben | E39: Administratives

Sheet ST_18_KW_3
B1: Unterrichtsverlauf | E1: =Kompetenzraster!Q39 -> 45308 | G1: 18
B3: Semesterarbeit | F3: 6.9 | G3: Filme / Theorie
B5: 1 - 5 Lektion
C6: Arbeit an Projektarbeit
C8: => Hinweis / Erwatungen / Cast
C10: Zeugnisbesprechung
C12: Lernziele
C13: * Sie erstellen anhand von Planunterlagen einen Werkstattplan für eine Vorwand.
C14: * Sie wenden die X- und z-Mass-Methode an verschiedenen Beispielen an.
C15: * Sie erstellen anhand von Planunterlagen, Apparatelisten und Massskizzen
C16: einen massstäblichen Detailplan.
C17: * Sie zeichnen einfache Installationspläne unter Berücksichtigung der relevanten Vorschriften.
C18: * Sie beschreiben die handelsüblichen Vorwandsysteme.
C19: * Sie berechnen den Druck unter Berücksichtigung der Kompressibilität des Wassers.
C20: * Sie beschreiben das korrekte Vorgehen zur Überprüfung der Ausstosszeiten.
C21: * Sie bestimmen die Rohrweiten von Trinkwasser-Leitungen anhand der geltenden Vorschriften.
B22: Pause
B24: Semesterarbeit | F24: 6.9 | G24: Filme / Theorie
B26: 4 - 5 Lektion
C33: Lernziele
B39: Hausaufgaben | E39: Administratives

Sheet Aufgaben_Teams
B1: Aufgaben Teams
B4: Auftrag 7.1 | C4: Lernziele: - Sie zeichnen einfache Installationspläne unter Berücksichtigung der relevanten Vorschriften. - Sie zeichnen einfache Schemapläne unter Berücksichtigung der relevanten Vorschriften. - Sie bestimmen die Rohrweiten von Trinkwasser- Schmutzwasser- und Gasleitungen anhand der geltenden Vorschriften - Sie bestimmen die Grösse eines Wassererwärmers anhand der geltenden Vorschriften. Abzugebende Leistungsnachweise: - Leistungsnachweis "Grundriss inkl. Schema"
B6: Punkte
B7: 3
B8: Zuweisung
B9: =Kompetenzraster!Q5 -> 45154
B10: Abgabe
B11: =Kompetenzraster!Q11-1 -> 45174
B18: Auftrag 7.2 | C18: Lernziele: - Sie kennen die Grundlagen der X-Mass Methode und wenden diese in einfachen Beispielen an. - Sie erstellen selbstständig einfache X-Mass Vorfabrikationszeichnungen inkl. Rohrlängen und Stückliste. Abzugebende Leistungsnachweise: - Leistungsnachweis "AVOR X-Mass "
B20: Punkte
B21: 3
B22: Zuweisung
B23: =Kompetenzraster!Q25 -> 45245
B24: Abgabe
B25: =Kompetenzraster!Q37-1 -> 45300
B28: Auftrag 7.3 | C28: Lernziele: - Sie benennen gebräuchliche Ver- und Entsorgungsapparate sowie deren Komponenten. - Sie beschreiben den Aufbau und die Funktion einer Enthärtungsanlage Abzugebende Leistungsnachweise: - Leistungsnachweis "Enthärtungsanlage"
B30: Punkte
B31: 2
B32: Zuweisung
B33: =Kompetenzraster!Q5 -> 45154
B34: Abgabe
B35: =Kompetenzraster!Q11-1 -> 45174
B37: Auftrag 7.4 | C37: Lernziele: - Sie benennen gebräuchliche Ver- und Entsorgungsapparate sowie deren Komponenten. - Sie beschreiben den Aufbau und die Funktion einer Wärmepumpe. - Sie erläutern die Unterschiede der verschiedenen Systeme der Wassererwärmung in Bezug auf die Energieeffizienz. - Sie berechnen die benötigten Wassermengen zur Erreichung gewünschter Temperaturen beim Mischen von Wasser. Abzugebende Leistungsnachweise: - Leistungsnachweis "Wärmepumpe & Wirkungsgrad"
B39: Punkte
B40: 2
B41: Zuweisung
B42: =Kompetenzraster!Q27 -> 45252
B43: Abgabe
B44: =Kompetenzraster!Q33-1 -> 45272
B50: Auftrag 7.5 | C50: Lernziele: - Sie benennen die Ersatzteile von Spülkästen und Armaturen und erklären deren Funktion. - Sie beschreiben die wesentlichen Wartungsintervalle und Arbeiten einer sanitären Installation. - Sie erklären die gebräuchlichen Anlagenteile in einfachen Worten. Abzugebende Leistungsnachweise: - Leistungsnachweis "Praxisauftrag Spülkasten reparieren"
B52: Punkte
B53: 2
B54: Zuweisung
B55: =Kompetenzraster!Q19 -> 45224
B56: Abgabe
B57: =Kompetenzraster!Q25-1 -> 45244
B61: Auftrag 7.6 | C61: Lernziele: - Sie erklären die hygienischen Anforderungen an Sanitäranlagen gemäss den geltenden Vorschriften. - Sie erklären den Zusammenhang zwischen Volumenstrom, Fliessgeschwindigkeit, Druckverlust und Rohrdurchmessern. Abzugebende Leistungsnachweise: - Leistungsnachweis "Projektierung & Berechnung EFH"
B63: Punkte
B64: 2
B65: Zuweisung
...
