Workbook

Sheet Kompetenzraster
B1: Kompetenzraster 3.Semester Sanitäripraktiker/in EBA | I1: Semesterstart: | J1: 45518 | K1: Schultag: | L1: Mittwoch | V1: SSPb_23-25
B3: Handlungsfelder und Kompetenzen | M3: Bewertung / Benotung | Q3: Unterichtsplanung 3. Semester
B5: HF1(PDA) | D5: Auftrag 3.1 | F5: Auftrag 3.2 | H5: Auftrag 3.3 | J5: Auftrag 3.6 | M5: Zeugnisnote | Q5: =Schultage!C4 -> 1 | R5: =Schultage!D4 -> 45518 | T5: Volumenberechnung
D6: 4 Schultage (10L) | F6: 5 Schultage (10L) | H6: 3 Schultage (4L) | J6: 9 Schultage (18L) | M6: Die Zeugnisnote setzt sich aus den Leistungsnachweisen und Kompetenzprüfungen zusammen. Die Note aus den Leistungsnachweisen zählt zu ca. 30% an die Zeugnisnote. Alle Noten der Prüfungen zählen zu ca. 60% an die Zeugnisnote. | R6: 3.4 | S6: 3.1 | T6: Arbeitsvorbereitung Z-Mass
B7: Planen der Arbeiten | D7: 1.4.2 Sie berechnen das Volumen verschiedener Behältnisse. (K3) | E7: 1.4.3 Sie schätzen das Gewicht von verschiedenen Komponenten ab (z.B. Heizkörper, WCSchüssel, Lüftungsrohre, Dachrinne) (K3) | F7: 2.1.1 Sie erstellen selbstständig anspruchsvolle Z-Mass Vorfabrikationszeichnungen inkl. Rohrlängen und Stückliste.(K3) | G7: 2.1.4 Sie wenden die Z-Mass-Methode an verschiedenen Beispielen an. (K3) | H7: 2.3.1 Sie erstellen einen einfachen Materialauszug aufgrund einer typischen Baustellensitu-ation. (K3) | I7: 2.3.2 Sie benennen die gebräuchlichen Installationssysteme und deren Material und Verwendungszweck. (K1) | J7: 3.1.1 Sie erstellen genaue und vollständige Isometrie-Zeichnungen von einfachen Entsorgungsinstallationen anhand von Grundriss- und Ansichtsplänen. (K3) | K7: 3.1.4 Sie wenden die x-Mass-Methode an verschiedenen Beispielen an. (K3) | Q7: =Schultage!C5 -> 2 | R7: =Schultage!D5 -> 45525 | T7: Volumenberechnung
R8: 3.4 | S8: 3.1 | T8: Arbeitsvorbereitung Z-Mass
G9: 2.1.6 Sie erstellen anhand von isometrischen Zeich-nungen vollständige Stklisten von einfachen TW-installationen. (K3) | Q9: =Schultage!C6 -> 3 | R9: =Schultage!D6 -> 45532 | T9: Volumenberechnung
I10: 2.3.7 Sie ordnen die gebräuchlichen Armaturen den Armaturengruppen korrekt zu. (K1) | K10: 3.1.5 Sie berechnen 45° Dreiecke mit Faktoren. (K3) | R10: 3.4 | S10: 3.1 | T10: Arbeitsvorbereitung Z-Mass
D11: 1.4.1 Sie können Abfälle unterscheiden und fachgerecht trennen und entsorgen (K3) | F11: 2.1.5 Sie berechnen Längen- und Höhen-masse von TW-Installationen. (K3) | H11: 2.3.8 Sie benennen verschiedene Rohrbefestigungen. (K1) | Q11: =Schultage!C7 -> 4 | R11: =Schultage!D7 -> 45539 | T11: Warmwasser & Leitungsbefestigung
J12: 3.1.6 Sie berechnen Längen- und Höhenmasse von einfachen Entsorgungsinstallationen. (K3) | K12: 3.1.7 Sie erstellen anhand von isometrischen Zeichnungen vollständige Stücklisten von einfachen Entsorgungsinstallationen. (K3) | R12: 3.4 | S12: 3.1 | T12: Arbeitsvorbereitung Z-Mass
Q13: =Schultage!C8 -> 5 | R13: =Schultage!D8 -> 45546 | T13: Warmwasser & Leitungsbefestigung
B14: HF2 (MVS) | D14: Auftrag 3.4 | G14: Auftrag 3.5 | M14: Leistungsnachweise | R14: 3.4 | S14: 3.2 | T14: Arbeitsvorbereitung Z-Mass
D15: 5 Schultage (15L) | G15: 2 Schultage (10L) | M15: Die Note der Leistungsnachweise entsteht aus den während des Semestes erzielten Punkten. | Q15: =Schultage!C9 -> 6 | R15: =Schultage!D9 -> 45553 | T15: Warmwasser & Leitungsbefestigung
B16: Installieren von Versorgungslei tungen Trinkwasser | D16: 2.4.1 Sie benennen geeignete Leitungsbefestigungen und deren Funktion. (K1) | F16: 2.4.5 Sie erklären den Zweck und die Funktion verschiedener Armaturen für Trinkwasserleitungen. (K2) | G16: 2.5.1 Sie beschreiben Einsatzgebiete, Anwendungen und Eigenschaften der gebräuchlichen Dämmmaterialien für Trinkwasserleitungen. (K2) | R16: 3.5 | S16: 3.2 | T16: Materialauszug von Trinkwasserleitungen
Q17: =Schultage!C10 -> 7 | R17: =Schultage!D10 -> 45560 | T17: Warmwasser & Leitungsbefestigung
D18: 2.4.4 Sie beschreiben die verschiedenen Verteilsysteme für Warmwasser. (K2) | R18: 3.5 | S18: 3.2 | T18: Rohrbefestigungen von Trinkwasserleitungen
F19: 2.4.10 Sie beschreiben Massnahmen zur Reduktion des Energie- und Trinkwasserverbrauches in der Haustechnik. (K2) | M19: Planen der Arbeiten (PDA) | Q19: =Schultage!C14 -> 8 | R19: =Schultage!D14 -> 45588 | T19: Warmwasser & Leitungsbefestigung
D20: 2.4.9 Sie beschreiben dieBedeutung des sparsamen Trinkwasserverbrauches. | M20: Auftrag 3.1 | N20: 2 | R20: 3.7 | S20: 3.2 | T20: Rohrmaterialien und Armaturen TW
M21: Auftrag 3.2 | N21: 3 | Q21: =Schultage!C15 -> 9 | R21: =Schultage!D15 -> 45595 | T21: Dämmungen Ver- und Entsorgungsleitungen
M22: Auftrag 3.3 | N22: 1 | R22: 3.7 | S22: 3.2 | T22: Rohrmaterialien und Armaturen TW
B23: HF3 (MVS) | E23: Auftrag 3.7 | H23: Auftrag3.5 | M23: Auftrag 3.6 | N23: 2 | Q23: =Schultage!C16 -> 10 | R23: =Schultage!D16 -> 45602 | T23: Dämmungen Ver- und Entsorgungsleitungen
E24: 4Schultage (10L) | H24: 2Schultage(10L) | M24: Total Punkte | N24: =SUM(N20:O23) -> 8 | R24: 3.7 | S24: 3.3 | T24: Arbeitsvorbereitung X-Mass
B25: Installieren von Entsorgungsleitungen | E25: 3.3.4 Sie beschreiben die verschiedenen Rohrmaterialien für Entsorgungsleitungen. (K2) | F25: 3.4.2 Sie berechnen das Gefälle von Entsorgungsleitungen anhand von Beispielen (K3). | G25: 3.4.11 Sie erläutern den Einsatz und die Funktion einfacher Abwasserhebeanlagen. (K2) | H25: 3.5.1 Sie beschreiben Einsatzgebiete, Anwendungen und Eigenschaften der gebräuchlichen Dämmmaterialien für Entsorgungsleitungen. (K2) | Q25: =Schultage!C17 -> 11 | R25: =Schultage!D17 -> 45609 | T25: Rohrmaterialien Entsorgungsleitungen
M26: Montieren von Sanitäranlagen | R26: 3.7 | S26: 3.3 | T26: Arbeitsvorbereitung X-Mass
M27: Auftrag 3.4 | N27: 1.5 | Q27: =Schultage!C18 -> 12 | R27: =Schultage!D18 -> 45616 | T27: Verbindungen & Richtlinien Entsorg.Leitungen
E28: 3.3.5 Sie erläutern die Verbindungsmöglichkeiten der verschiedenen Installationssysteme. (K2) | F28: 3.4.6 Sie beschreiben die relevanten Inhalte der geltenden Vorschriften in Bezug auf die Installation von Entsorgungsleitungen. (K2) | G28: 3.4.12 Sie beschreiben die Funktionsweise der Abwasserentsorgung. (K2) | M28: Auftrag 3.5 | N28: 1.5 | R28: 3.7 | S28: 3.3 | T28: Arbeitsvorbereitung X-Mass
M29: Auftrag 3.7 | N29: 1.5 | Q29: =Schultage!C19 -> 13 | R29: =Schultage!D19 -> 45623 | T29: Gefällsberechnungen Entsorgungsleitungen
M30: Auftrag 3.8 | N30: 2 | R30: 3.8 | S30: 3.6 | T30: Arbeitsvorbereitung X-Mass
M31: Auftrag 3.9 | N31: 2 | Q31: =Schultage!C20 -> 14 | R31: =Schultage!D20 -> 45630 | T31: Funktionsweise Abwasserentsorgung
B32: HF4 / HF5 (MVS) | E32: Auftrag 3.8 | H32: Auftrag 3.9 | M32: Total Punkte | N32: =SUM(N27:O31) -> 8.5 | R32: 3.8 | S32: 3.6 | T32: Arbeitsvorbereitung X-Mass
E33: 3 Schultage (10L) | H33: 2 Schultage (5L) | Q33: =Schultage!C21 -> 15 | R33: =Schultage!D21 -> 45637 | T33: Vorwandsysteme
B34: Installieren von Vorwandsystemen | E34: 4.1.1 Sie beschreiben die handelsüblichen Vorwandsysteme. (K2) | F34: 4.1.5 Sie erläutern die Befestigungstechnik und Schallschutzmassnahmen bei einfachen Vorwänden. (K2) | G34: 4.2.4 Sie erklären, wie und mit welchen Materialien einfache Vorwände beplankt werden. (K2) | H34: 5.2.1 Sie benennen gebräuchliche Apparate, Entnahmearmaturen und Garnituren sowie deren Bestandteile. (K1) | I34: 5.2.2 Sie beschreiben Mass-Skizzen und Detailpläne anhand von Beispielen. (K2) | J34: 5.2.3 Sie beschreiben die Material-Eigenschaften von Apparaten (z.B. Keramik, Kunststoff). (K2) | M34: Schulferien& Feiertage | R34: 3.8 | S34: 3.6 | T34: Arbeitsvorbereitung X-Mass
M35: Herbstferien 29.09.2024 - 20.10.2024 | Q35: =Schultage!C22 -> 16 | R35: =Schultage!D22 -> 45644 | T35: Vorwandsysteme
B36: Montieren von sanitären Anlagen und Apparaten | R36: 3.9 | S36: 3.6 | T36: Arbeitsvorbereitung X-Mass
M37: Weihnachtsferien 22.12.2024 - 05.01.2025 | Q37: =Schultage!C25 -> 17 | R37: =Schultage!D25 -> 45665 | T37: Vorwandsysteme
R38: 3.9 | S38: 3.6 | T38: Apparate, Entnahmearmaturen & Garnituren
M39: Winterferien 29.01.-05.02.25 | Q39: =Schultage!C26 -> 18 | R39: =Schultage!D26 -> 45672 | T39: Abschluss &
R40: 3.9 | S40: 3.6 | T40: Zeugnisbesprechung
Q41: 19 | R41: 45679 | T41: Skitag Savognin
B43: Fachgruppe Sanitär Spengler | K43: ARTO

Sheet Kompetenzraster alt
B1: Kompetenzraster 3.Semester Sanitäripraktiker/in EBA | I1: Semesterstart: | J1: 45518 | K1: Schultag: | L1: Mittwoch | U1: SSPb_23-25
B3: Handlungsfelder und Kompetenzen | M3: Bewertung / Benotung | Q3: Unterichtsplanung 3. Semester
B5: HF1(PDA) | D5: Auftrag 3.1 | M5: Note Leistungsnachweis | Q5: =Schultage!C4 -> 1 | R5: =Schultage!D4 -> 45518 | S5: Volumenberechnung
D6: 3 Schultage (10L) | M6: Die Note aus den Leistungsnachweisen erechnet sich aus den während des Semestes erzielten Punkten. | R6: 3.1 | 3.2 | S6: Arbeitsvorbereitung Z-Mass
B7: Planen der Arbeiten | D7: 1.4.2 Sie berechnen das Volumen verschiedener Behältnisse. (K3) | E7: 1.4.3 Sie schätzen das Gewicht von verschiedenen Komponenten ab (z.B. Heizkörper, WCSchüssel, Lüftungsrohre, Dachrinne) (K3) | Q7: =Schultage!C5 -> 2 | R7: =Schultage!D5 -> 45525 | S7: Volumenberechnung
R8: 3.1 | 3.2 | S8: Arbeitsvorbereitung Z-Mass
Q9: =Schultage!C6 -> 3 | R9: =Schultage!D6 -> 45532 | S9: Volumenberechnung
M10: Auftrag 3.1 | N10: 2 | R10: 3.1 | 3.2 | S10: Arbeitsvorbereitung Z-Mass
D11: 1.4.1 Sie können Abfälle unterscheiden und fachgerecht trennen und entsorgen (K3) | M11: Auftrag 3.2 | N11: 3 | Q11: =Schultage!C7 -> 4 | R11: =Schultage!D7 -> 45539 | S11: Warmwasser & Leitungsbefestigung
M12: Auftrag 3.3 | N12: 2 | R12: 3.4 | 3.2 | S12: Arbeitsvorbereitung Z-Mass
M13: Auftrag 3.4 | N13: 1 | Q13: =Schultage!C8 -> 5 | R13: =Schultage!D8 -> 45546 | S13: Warmwasser & Leitungsbefestigung
B14: HF2 | D14: Auftrag 3.2 | F14: Auftrag 3.3 | H14: Auftrag 3.4 | J14: Auftrag 3.5 | M14: Auftrag 3.5 | N14: 1 | R14: 3.4 | 3.2 | S14: Arbeitsvorbereitung Z-Mass
D15: 5 Schultage (10L) | F15: 4 Schultage (10L) | H15: 5 Schultage (15L) | J15: 2 Schultage (10L) | M15: Auftrag 3.6 | N15: 3 | Q15: =Schultage!C9 -> 6 | R15: =Schultage!D9 -> 45553 | S15: Warmwasser & Leitungsbefestigung
B16: Installieren von Versorgungslei tungen Trinkwasser | D16: 2.1.1 Sie erstellen selbstständig anspruchsvolle Z-Mass Vorfabrikationszeichnungen inkl. Rohrlängen und Stückliste.(K3) | E16: 2.1.4 Sie wenden die Z-Mass-Methode an verschiedenen Beispielen an. (K3) | F16: 2.3.1 Sie erstellen einen einfachen Materialauszug aufgrund einer typischen Baustellensitu-ation. (K3) | G16: 2.3.2 Sie benennen die gebräuchlichen Installationssysteme und deren Material und Verwendungszweck. (K1) | H16: 2.4.1 Sie benennen geeignete Leitungsbefestigungen und deren Funktion. (K1) | I16: 2.4.5 Sie erklären den Zweck und die Funktion verschiedener Armaturen für Trinkwasserleitungen. (K2) | J16: 2.5.1 Sie beschreiben Einsatzgebiete, Anwendungen und Eigenschaften der gebräuchlichen Dämmmaterialien für Trinkwasserleitungen. (K2) | M16: Auftrag 3.7 | N16: 2 | R16: 3.4 | 3.3 | S16: Materialauszug von Trinkwasserleitungen
M17: Auftrag 3.8 | N17: 1 | Q17: =Schultage!C10 -> 7 | R17: =Schultage!D10 -> 45560 | S17: Warmwasser & Leitungsbefestigung
E18: 2.1.6 Sie erstellen anhand von isometrischen Zeich-nungen vollständige Stklisten von einfachen TW-installationen. (K3) | H18: 2.4.4 Sie beschreiben die verschiedenen Verteilsysteme für Warmwasser. (K2) | M18: Auftrag 3.9 | N18: 1 | R18: 3.4 | 3.3 | S18: Rohrbefestigungen von Trinkwasserleitungen
G19: 2.3.7 Sie ordnen die gebräuchlichen Armaturen den Armaturengruppen korrekt zu. (K1) | I19: 2.4.10 Sie beschreiben Massnahmen zur Reduktion des Energie- und Trinkwasserverbrauches in der Haustechnik. (K2) | Q19: =Schultage!C14 -> 8 | R19: =Schultage!D14 -> 45588 | S19: Warmwasser & Leitungsbefestigung
D20: 2.1.5 Sie berechnen Längen- und Höhen-masse von TW-Installationen. (K3) | F20: 2.3.8 Sie benennen verschiedene Rohrbefestigungen. (K1) | H20: 2.4.9 Sie beschreiben dieBedeutung des sparsamen Trinkwasserverbrauches. | M20: Punkte max. | N20: =SUM(N10:O19) -> 16 | R20: 3.4 | 3.3 | S20: Rohrmaterialien und Armaturen TW
N21: =(SUM(O10:O18)*5)/SUM(N10:N18)+1 -> 1 | Q21: =Schultage!C15 -> 9 | R21: =Schultage!D15 -> 45595 | S21: Dämmungen Ver- und Entsorgungsleitungen
O22: X | R22: 3.5 | 3.3 | S22: Rohrmaterialien und Armaturen TW
B23: HF3 | E23: Auftrag 3.6 | H23: Auftrag 3.7 | K23: Auftrag3.5 | M23: Noten Prüfungen | Q23: =Schultage!C16 -> 10 | R23: =Schultage!D16 -> 45602 | S23: Dämmungen Ver- und Entsorgungsleitungen
E24: 7 Schultage (20L) | H24: 4Schultage (10L) | K24: 2Schultage(10L) | M24: Zu einzelnen Aufträgen wird im Unterricht eine Zwischenprüfung geschrieben. | R24: 3.5 | 3.6 | S24: Arbeitsvorbereitung X-Mass
B25: Installieren von Entsorgungsleitungen | E25: 3.1.1 Sie erstellen genaue und vollständige Isometrie-Zeichnungen von einfachen Entsorgungsinstallationen anhand von Grundriss- und Ansichtsplänen. (K3) | F25: 3.1.4 Sie wenden die x-Mass-Methode an verschiedenen Beispielen an. (K3) | G25: 3.1.6 Sie berechnen Längen- und Höhenmasse von einfachen Entsorgungsinstallationen. (K3) | H25: 3.3.4 Sie beschreiben die verschiedenen Rohrmaterialien für Entsorgungsleitungen. (K2) | I25: 3.4.2 Sie berechnen das Gefälle von Entsorgungsleitungen anhand von Beispielen (K3). | J25: 3.4.11 Sie erläutern den Einsatz und die Funktion einfacher Abwasserhebeanlagen. (K2) | K25: 3.5.1 Sie beschreiben Einsatzgebiete, Anwendungen und Eigenschaften der gebräuchlichen Dämmmaterialien für Entsorgungsleitungen. (K2) | Q25: =Schultage!C17 -> 11 | R25: =Schultage!D17 -> 45609 | S25: Rohrmaterialien Entsorgungsleitungen
R26: 3.7 | 3.6 | S26: Arbeitsvorbereitung X-Mass
Q27: =Schultage!C18 -> 12 | R27: =Schultage!D18 -> 45616 | S27: Verbindungen & Richtlinien Entsorg.Leitungen
F28: 3.1.5 Sie berechnen 45° Dreiecke mit Faktoren. (K3) | G28: 3.1.7 Sie erstellen anhand von isometrischen Zeichnungen vollständige Stücklisten von einfachen Entsorgungsinstallationen. (K3) | H28: 3.3.5 Sie erläutern die Verbindungsmöglichkeiten der verschiedenen Installationssysteme. (K2) | I28: 3.4.6 Sie beschreiben die relevanten Inhalte der geltenden Vorschriften in Bezug auf die Installation von Entsorgungsleitungen. (K2) | J28: 3.4.12 Sie beschreiben die Funktionsweise der Abwasserentsorgung. (K2) | M28: Zeugnisnote | R28: 3.7 | 3.6 | S28: Arbeitsvorbereitung X-Mass
M29: Die Note aus den Lernprodukten zählt zu 25%. Alle Noten der Prüfungen zählen zu 60%. | Q29: =Schultage!C19 -> 13 | R29: =Schultage!D19 -> 45623 | S29: Gefällsberechnungen Entsorgungsleitungen
R30: 3.7 | 3.6 | S30: Arbeitsvorbereitung X-Mass
Q31: =Schultage!C20 -> 14 | R31: =Schultage!D20 -> 45630 | S31: Funktionsweise Abwasserentsorgung
B32: HF4 / HF5 | E32: Auftrag 3.8 | H32: Auftrag 3.9 | R32: 3.7 | 3.6 | S32: Arbeitsvorbereitung X-Mass
E33: 3 Schultage (10L) | H33: 2 Schultage (5L) | M33: Gesetzliche Feiertage | Q33: =Schultage!C21 -> 15 | R33: =Schultage!D21 -> 45637 | S33: Vorwandsysteme
B34: Installieren von Vorwandsystemen | E34: 4.1.1 Sie beschreiben die handelsüblichen Vorwandsysteme. (K2) | F34: 4.1.5 Sie erläutern die Befestigungstechnik und Schallschutzmassnahmen bei einfachen Vorwänden. (K2) | G34: 4.2.4 Sie erklären, wie und mit welchen Materialien einfache Vorwände beplankt werden. (K2) | H34: 5.2.1 Sie benennen gebräuchliche Apparate, Entnahmearmaturen und Garnituren sowie deren Bestandteile. (K1) | I34: 5.2.2 Sie beschreiben Mass-Skizzen und Detailpläne anhand von Beispielen. (K2) | J34: 5.2.3 Sie beschreiben die Material-Eigenschaften von Apparaten (z.B. Keramik, Kunststoff). (K2) | M34: Allerheiligen | N34: 45597 | R34: 3.8 | 3.6 | S34: Arbeitsvorbereitung X-Mass
M35: Karfreitag | N35: 45765 | Q35: =Schultage!C22 -> 16 | R35: =Schultage!D22 -> 45644 | S35: Vorwandsysteme
B36: Montieren von sanitären Anlagen und Apparaten | M36: Ostermontag | N36: 45768 | R36: 3.8 | 3.6 | S36: Arbeitsvorbereitung X-Mass
M37: Auffahrt | N37: 45806 | Q37: =Schultage!C25 -> 17 | R37: =Schultage!D25 -> 45665 | S37: Vorwandsysteme
M38: Pfingstmontag | N38: 45817 | R38: 3.8 | 3.9 | S38: Apparate, Entnahmearmaturen & Garnituren
Q39: =Schultage!C26 -> 18 | R39: =Schultage!D26 -> 45672 | S39: Abschluss &
R40: 3.8 | 3.9 | S40: Zeugnisbesprechung
B42: Fachgruppe Sanitär Spengler | K42: TAR

Sheet Schultage
B2: 3.Semester | E2: Lernaufträge
C3: ST Nr. | D3: Datum: | E3: NR.
C4: 1 | D4: ='Kompetenzraster alt'!J1 -> 45518 | E4: =Kompetenzraster!R6 -> 3.4 | F4: =Kompetenzraster!S6 -> 3.1
C5: 2 | D5: =D4+7 -> 45525 | E5: =Kompetenzraster!R8 -> 3.4 | F5: =Kompetenzraster!S8 -> 3.1
C6: 3 | D6: =D5+7 -> 45532 | E6: =Kompetenzraster!R10 -> 3.4 | F6: =Kompetenzraster!S10 -> 3.1
C7: 4 | D7: =D6+7 -> 45539 | E7: =Kompetenzraster!R12 -> 3.4 | F7: =Kompetenzraster!S12 -> 3.1
C8: 5 | D8: =D7+7 -> 45546 | E8: =Kompetenzraster!R14 -> 3.4 | F8: =Kompetenzraster!S14 -> 3.2
C9: 6 | D9: =D8+7 -> 45553 | E9: =Kompetenzraster!R16 -> 3.5 | F9: =Kompetenzraster!S16 -> 3.2
C10: 7 | D10: =D9+7 -> 45560 | E10: =Kompetenzraster!R18 -> 3.5 | F10: =Kompetenzraster!S18 -> 3.2
B11: Herbst Ferien | D11: =D10+7 -> 45567
D12: =D11+7 -> 45574
D13: =D12+7 -> 45581
C14: 8 | D14: =D13+7 -> 45588 | E14: =Kompetenzraster!R20 -> 3.7 | F14: =Kompetenzraster!S20 -> 3.2
C15: 9 | D15: =D14+7 -> 45595 | E15: =Kompetenzraster!R22 -> 3.7 | F15: =Kompetenzraster!S22 -> 3.2
C16: 10 | D16: =D15+7 -> 45602 | E16: =Kompetenzraster!R24 -> 3.7 | F16: =Kompetenzraster!S24 -> 3.3
C17: 11 | D17: =D16+7 -> 45609 | E17: =Kompetenzraster!R26 -> 3.7 | F17: =Kompetenzraster!S26 -> 3.3
C18: 12 | D18: =D17+7 -> 45616 | E18: =Kompetenzraster!R28 -> 3.7 | F18: =Kompetenzraster!S28 -> 3.3
C19: 13 | D19: =D18+7 -> 45623 | E19: =Kompetenzraster!R30 -> 3.8 | F19: =Kompetenzraster!S30 -> 3.6
C20: 14 | D20: =D19+7 -> 45630 | E20: =Kompetenzraster!R32 -> 3.8 | F20: =Kompetenzraster!S32 -> 3.6
C21: 15 | D21: =D20+7 -> 45637 | E21: =Kompetenzraster!R34 -> 3.8 | F21: =Kompetenzraster!S34 -> 3.6
C22: 16 | D22: =D21+7 -> 45644 | E22: =Kompetenzraster!R36 -> 3.9 | F22: =Kompetenzraster!S36 -> 3.6
B23: Weihnachts Ferien | D23: =D22+7 -> 45651
D24: =D23+7 -> 45658
C25: 17 | D25: =D24+7 -> 45665 | E25: =Kompetenzraster!R38 -> 3.9 | F25: =Kompetenzraster!S38 -> 3.6
C26: 18 | D26: =D25+7 -> 45672 | E26: =Kompetenzraster!R40 -> 3.9 | F26: =Kompetenzraster!S40 -> 3.6
B27: Skitag | C27: 19 | D27: =D26+7 -> 45679
B28: Sportwoche | C28: 20 | D28: =D27+7 -> 45686
B30: 4.Semester
C31: Schultag: | D31: Datum:
C32: 1 | D32: =D28+7 -> 45693
C33: 2 | D33: =D32+7 -> 45700
C34: 3 | D34: =D33+7 -> 45707
C35: 4 | D35: =D34+7 -> 45714
C36: 5 | D36: =D35+7 -> 45721
C37: 6 | D37: =D36+7 -> 45728
C38: 7 | D38: =D37+7 -> 45735
C39: 8 | D39: =D38+7 -> 45742
C40: 9 | D40: =D39+7 -> 45749
B41: Frühlings Ferien | D41: =D40+7 -> 45756
D42: =D41+7 -> 45763
...

Sheet Leistungsziele 1-4.Semester
A1: Leistungsziele Spengler-Sanitärpraktiker 1.- 4.Semester | T1: 45484
A2: Sanitär
A3: 1. Semester | F3: 2. Semester | K3: 3. Semester | P3: 4. Semester
A5: LA suissetec | B5: LA GBS SG | C5: Leistungsziele Berufsfachschule | D5: Lektionen | E5: Inhalte Grundlagen | F5: LA suissetec | G5: LA GBS SG | H5: Leistungsziele Berufsfachschule | I5: Lektionen | J5: Inhalte Grundlagen | K5: LA suissetec | L5: LA GBS SG | M5: Leistungsziele Berufsfachschule | N5: Lektionen | O5: Inhalte Grundlagen | P5: LA suissetec | Q5: LA GBS SG | R5: Leistungsziele Berufsfachschule | S5: Lektionen | T5: Inhalte Grundlagen
B6: 1.1 | C6: 1.1.1 Sie beschreiben einen Bauablauf auf der Baustelle. (K2) | D6: 15 | E6: Bauablauf, Enstehung eines Gebäudes | R6: 1.1.1 Sie beschreiben einen Bauablauf auf der Baustelle. (K2) | S6: 10 | T6: Bauablauf, Entstehung eines Gebäudes
C7: 1.1.2 Sie beschreiben verschiedene Planarten (z.B.Montageplan, Einlageplan, Koordinationsplan, Aussparungsplan, Schema, Schnittplan, Fassadenansicht). (K2) | E7: Planarten unterscheiden, Planlesen (Koten,Bemassung, Materialien)
R8: 1.1.3 Sie erläutern einen Auftrag aus ihrem Betrieb mit den korrekten Fachbegriffen. (K2) | T8: Fachbegriffe, Praxisbeispiele, Aufträge (Arbeitssituation)
C9: 1.1.4 Sie benennen die Akteure auf dem Bau und deren Funktionen. (K1) | E9: Am Bau beteiligte Gewerke und Personen
R11: 1.1.5 Sie organisieren sich anhand eines Beispielauftrags im Team. (K3) | T11: Absprachen, Schnittstellen und Koordination im Team
R12: 1.1.6 Sie bestimmen die Montagezeit aufgrund von einfachen Beispielen. (K3) | T12: Terminprogramm, Zeiteinteilung
C14: 1.2.3 Sie erläutern einen einfachen Stromkreislauf. (K2) | D14: 15 | E14: Grundlagen Elektrotechnik, einfacher Stromkreislauf | R14: 1.2.3 Sie erläutern einen einfachen Stromkreislauf. (K2) | S14: 10 | T14: Grundlagen Elektrotechnik, einfacher Stromkreislauf
C15: 1.2.5 Sie beschreiben, bei welchen Situationen und Tätigkeiten eine entsprechende PSA getragen werden muss. (K2) | E15: Arbeitssicherheit PSA, PSAgA, SUVA-Merkblätter | R15: 1.2.5 Sie beschreiben, bei welchen Situationen und Tätigkeiten eine entsprechende PSA getragen werden muss. (K2) | T15: Arbeitssicherheit PSA, PSAgA, SUVA-Merkblätter
C16: 1.2.8 Sie erläutern die Gefahren und Risiken auf der Baustelle und in der Werkstatt (z.B. Strombezug für die verschiedenen Maschinen, Lagerung von Gas, Asbest, Gerüstbau, Brandschutz, Gasinstallationen). (K2) | E16: Arbeitssicherheit SUVA – Gas, Flüssigkeiten, Strom – Asbest, gefährliche Stoffe – Gerüste, Rollgerüste, tragbare Leitern | R16: 1.2.8 Sie erläutern die Gefahren und Risiken auf der Baustelle und in der Werkstatt (z.B. Strombezug für die verschiedenen Maschinen, Lagerung von Gas, Asbest, Gerüstbau,Brandschutz, Gasinstallationen). (K2) | T16: Arbeitssicherheit SUVA – Gas, Flüssigkeiten, Strom – Asbest, gefährliche Stoffe – Gerüste, Rollgerüste, tragbare Leitern
C18: 1.3.1 Sie erläutern die Unterschiede der verschiedenen Rapport-Arten. (K2) | D18: 5 | E18: Lieferschein, Stundenrapport, Materialrapport, Regierapport
C19: 1.3.2 Sie erläutern den Sinn und Zweck des Rapportierens. (K2) | E19: Sinn und Zweck der verschiedenen Dokumente, Wirtschaftlichkeit des Betriebes | H19: 1.4.1 Sie erklären anhand eines einfachen Beispiels den organisatorischen Ablauf bei der Trennung und Entsorgung von Abfällen gemäss Abfallverordnung. (K2) | I19: 10 | J19: Muldenkonzept, ökologische Kriterien zur Abfallentsorgung, Recycling – Abfalltrennung
H20: 1.4.2 Sie berechnen das Volumen verschiedener Behältnisse. (K3) | J20: Grundlagen Fachrechnen, Funktion Taschenrechner, SI-Einheiten, Einheitenvorzeichen, Strecken, Flächen, Volumen | M20: 1.4.2 Sie berechnen das Volumen verschiedener Behältnisse. (K3) | N20: 10 | O20: Grundlagen Fachrechnen, Funktion Taschenrechner,SI-Einheiten, Einheitenvorzeichen, Strecken, Flächen, Volumen | R20: 1.4.2 Sie berechnen das Volumen verschiedener Behältnisse. (K3) | S20: 10 | T20: Grundlagen Fachrechnen, Funktion Taschenrechner,SI-Einheiten, Einheitenvorzeichen, Strecken, Flächen, Volumen
C21: 1.4.3 Sie schätzen das Gewicht von verschiedenen Komponenten ab (z.B. Heizkörper, WCSchüssel, Lüftungsrohre, Dachrinne) (K3) | D21: 25 | H21: 1.4.3 Sie schätzen das Gewicht von verschiedenen Komponenten ab (z.B. Heizkörper, WCSchüssel, Lüftungsrohre, Dachrinne) (K3) | J21: Volumen, Masse, Dichte | M21: 1.4.3 Sie schätzen das Gewicht von verschiedenen Komponenten ab (z.B. Heizkörper, WCSchüssel, Lüftungsrohre, Dachrinne) (K3) | O21: Volumen, Masse, Dichte | R21: 1.4.3 Sie schätzen das Gewicht von verschiedenen Komponenten ab (z.B. Heizkörper, WCSchüssel, Lüftungsrohre, Dachrinne) (K3) | T21: Volumen, Masse, Dichte
C22: 1.4.4 Sie erläutern den Recycling-Kreislauf und den Zusammenhang zur Kreislaufwirtschaft im Baugewerbe. (K2) | E22: Stoffkreislauf, Recycling, Kreislaufwirtschaft, ökologische Kriterien zur Abfallentsorgung
C23: 1.4.5 Sie benennen die relevanten Umweltvorschriften im Zusammenhang mit der Vermeidung und Entsorgung von Abfällen. (K1) | E23: Nachhaltigkeit, Umweltschutz, Gewässerschutz
C24: 1.4.6 Sie zählen die Gefahren von Sonderabfällen (z.B. Asbest, Kältemittel, Chemikalien) auf. (K1) | E24: Nachhaltigkeit, Arbeitssicherheit, Sonderabfälle | R24: 1.4.6 Sie zählen die Gefahren von Sonderabfällen (z.B. Asbest, Kältemittel, Chemikalien) auf. (K1) | T24: Nachhaltigkeit, Arbeitssicherheit, Sonderabfälle
C25: 1.4.7 Sie ordnen die verschiedenen Gefahrensymbole korrekt zu. (K2) | E25: Säuren, Laugen, Gifte, pH-Wert, GHS-Gefahrensymbole | R25: 1.4.7 Sie ordnen die verschiedenen Gefahrensymbole korrekt zu. (K2) | T25: Säuren, Laugen, Gifte, pH-Wert, GHS-Gefahrensymbole
C27: 1.5.1 Sie benennen die gebräuchlichen Werkzeuge und Maschinen. (K1) | D27: 15 | E27: Maschinen und Werkzeuge
C28: 1.5.2 Sie erläutern die Gefahren, welche vom Strom ausgehen können. (K2) | E28: Wirkungen und Gefahren des Stroms, Grundlagen elektrischer Strom
C29: 1.5.3 Sie beschreiben den Personen- und Sachschutz bei Elektro-Installationen. (K2) | E29: Arbeitssicherheit, SUVA, Gefahren erkennen, erlaubte Arbeiten, Sicherheitseinrichtungen (z. B. FI-Schalter)
C30: 1.5.4 Sie erklären, welche Reparatur- und Wartungsarbeiten an Maschinen erlaubt sind. (K2) | E30: Reparatur und Wartungsarbeiten an Werkzeug und Maschinen
C32: 2.1.1 Sie erstellen genaue und vollständige Isometrie-Zeichnungen von einfachen Trinkwasserinstallationen anhand von Grundriss- und Ansichtsplänen. (K3) | D32: 10 | E32: Grundlagen Isometrie, perspektivisches Zeichnen, räumliches Vorstellungsvermögen, einfache Beispiele | F32: 04_LA_HK_2.1_Grundlagen_ Werkstattplan_Isometrie_Trinkwasserleitungen | H32: 2.1.1 Sie erstellen genaue und vollständige Isometrie-Zeichnungen von einfachen Trinkwasserinstallationen anhand von Grundriss- und Ansichtsplänen. (K3) | I32: 30 | J32: Grundlagen Isometrie, perspektivisches Zeichnen, räumliches Vorstellungsvermögen, einfache Beispiele | M32: 2.1.1 Sie erstellen genaue und vollständige Isometrie-Zeichnungen von einfachen Trinkwasserinstallationen anhand von Grundriss- und Ansichtsplänen. (K3) | N32: 10 | O32: Beispiele aus Fachbuch «Arbeitsvorbereitung» Grundlage 45° Etagierungen rechnen | R32: 2.1.1 Sie erstellen genaue und vollständige Isometrie-Zeichnungen von einfachen Trinkwasserinstallationen anhand von Grundriss- und Ansichtsplänen. (K3) | S32: 10 | T32: Umfangreichere Beispiele
C33: 2.1.4 Sie wenden die Z-Mass-Methode an verschiedenen Beispielen an. (K3) | E33: Grundlagen Arbeitsvorbereitung, einfache Beispiele | F33: 05_LA_HK_2.1_Z-Mass-Methode_anwenden | H33: 2.1.4 Sie wenden die Z-Mass-Methode an verschiedenen Beispielen an. (K3) | J33: Grundlagen Arbeitsvorbereitung, einfache Beispiele | M33: 2.1.4 Sie wenden die Z-Mass-Methode an verschiedenen Beispielen an. (K3) | O33: Umfangreichere Beispiele | R33: 2.1.4 Sie wenden die Z-Mass-Methode an verschiedenen Beispielen an. (K3) | T33: Umfangreichere Beispiele
C34: 2.1.5 Sie berechnen Längen- und Höhenmasse von einfachen Trinkwasserinstallationen. (K3) | E34: M-M, Höhenkoten, Bezugspunkt, einfache Beispiele | H34: 2.1.5 Sie berechnen Längen- und Höhenmasse von einfachen Trinkwasserinstallationen. (K3) | J34: M-M, Höhenkoten, Bezugspunkt, einfache Beispiele | M34: 2.1.5 Sie berechnen Längen- und Höhenmasse von einfachen Trinkwasserinstallationen. (K3) | O34: Umfangreichere Beispiele | R34: 2.1.5 Sie berechnen Längen- und Höhenmasse von einfachen Trinkwasserinstallationen. (K3) | T34: Umfangreichere Beispiele
H35: 2.1.6 Sie erstellen anhand von isometrischen Zeichnungen vollständige Stücklisten von einfachen Trinkwasserinstallationen. (K3) | J35: Einfache Beispiele | K35: 06_LA_HK_2.1_Stueckliste_ Materialauszug_erstellen | M35: 2.1.6 Sie erstellen anhand von isometrischen Zeichnungen vollständige Stücklisten von einfachen Trinkwasserinstallationen. (K3) | O35: Umfangreichere Beispiele | R35: 2.1.6 Sie erstellen anhand von isometrischen Zeichnungen vollständige Stücklisten von einfachen Trinkwasserinstallationen. (K3) | T35: Umfangreichere Beispiele
H37: 2.3.1 Sie erstellen einen einfachen Materialauszug aufgrund einer typischen Baustellensituation. (K3) | I37: 10 | J37: Materialauzüge mit einfachen Beispielen erstellen, Evtl. in Kombination mit Rapporten / Regierapporte und «Stückliste» HK 2.1 | M37: 2.3.1 Sie erstellen einen einfachen Materialauszug aufgrund einer typischen Baustellensituation. (K3) | N37: 10 | O37: Materialauzüge mit einfachen Beispielen erstellen. Evtl. in Kombination mit Rapporten / Regierapporten und «Stückliste» HK 2.1 | R37: 2.3.1 Sie erstellen einen einfachen Materialauszug aufgrund einer typischen Baustellensituation. (K3) | S37: 10 | T37: Vertiefung / Vernetzung
F38: 07_LA_HK_2.1_Installationssysteme _Trinkwasserleitungen | H38: 2.3.2 Sie benennen die gebräuchlichen Installationssysteme und deren Material und Verwendungszweck. (K1) | J38: Materialien und gängige Systeme im Bereich Verteilund Ausstossleitungen. Einsatz der Systeme. Evtl. Arbeit über Systeme im eigenen Betrieb | M38: 2.3.2 Sie benennen die gebräuchlichen Installationssysteme und deren Material und Verwendungszweck. (K1) | O38: Fokus «Warmwasserversorgung» Materialien und gängige Systeme im Bereich Verteilund Ausstossleitungen. Einsatz der Systeme Kombi HK 2.4 | R38: 2.3.2 Sie benennen die gebräuchlichen Installationssysteme und deren Material und Verwendungszweck. (K1) | T38: Vertiefung / Vernetzung
H39: 2.3.4 Sie benennen die Verbindungsmöglichkeiten der gebräuchlichen Installationssysteme. (K1) | J39: Verbindungsarten in Kombination mit Dichtstoffen | R39: 2.3.4 Sie benennen die Verbindungsmöglichkeiten der gebräuchlichen Installationssysteme. (K1) | T39: Vertiefung / Vernetzung
H40: 2.3.5 Sie erläutern den richtigen Einsatz der Dichtungsmaterialien bei Trinkwasserleitungen. (K2) | J40: Arten von Dichtstoffen in Kombination mit Verbindungsmöglichkeiten
F41: 08_LA_HK_2.3_Armaturen_ Trinkwasserleitungen gruppieren | H41: 2.3.7 Sie ordnen die gebräuchlichen Armaturen den Armaturengruppen korrekt zu. (K1) | J41: Armaturen zuordnen in die Gruppen gem. Fachbuch «Kaltwasserversorgung» | M41: 2.3.7 Sie ordnen die gebräuchlichen Armaturen den Armaturengruppen korrekt zu. (K1) | O41: Fokus «Warmwasserversorgung» Kombi HK 2.4 | R41: 2.3.7 Sie ordnen die gebräuchlichen Armaturen den Armaturengruppen korrekt zu. (K1) | T41: Vertiefung / Vernetzung
H42: 2.3.8 Sie benennen verschiedene Rohrbefestigungen. (K1) | J42: Baustoffe, Werkstoffe, Schallschutz | M42: 2.3.8 Sie benennen verschiedene Rohrbefestigungen. (K1) | O42: Fokus «Warmwasserversorgung» Kombi HK 2.4 | R42: 2.3.8 Sie benennen verschiedene Rohrbefestigungen. (K1) | T42: Vertiefung / Vernetzung
C44: 2.4.2 Sie benennen die Grundlagen bezüglich Trinkwasserhygiene (K1). | D44: 5 | E44: Lebensmittelgesetzgebung, SVGW kennenlernen, Trinkwasserqualität (chemische und physikalische Parameter) | F44: 09_LA_HK_2.3.4_Anforderungen_ Schallschutz | H44: 2.4.1 Sie benennen geeignete Leitungsbefestigungen und deren Funktion. (K1) | I44: 30 | J44: Unterschiedliche Arten und Einsatz der Befestigungen, Kombi mit LZ 2.3.8 HK 2.3 | M44: 2.4.1 Sie benennen geeignete Leitungsbefestigungen und deren Funktion. (K1) | N44: 15 | O44: Unterschiedliche Arten und Einsatz der Befestigungen Fokus «Warmwasserversorgung»
C45: 2.4.3 Sie beschreiben die wichtigsten Eigenschaften von Wasser. (K2) | E45: Chemisch physikalische Eigenheiten von Wasser. Warum steigt warmes Wasser? Aggregatszustände etc. | H45: 2.4.5 Sie erklären den Zweck und die Funktion verschiedener Armaturen für Trinkwasserleitungen. (K2) | J45: Armaturengruppen, Werkstoffe, Bauarten, Funktion | M45: 2.4.4 Sie beschreiben die verschiedenen Verteilsysteme für Warmwasser. (K2) | O45: Wassererwärmer, Gruppenversorgung, Zentralversorgung, Einzelzapfstellen, Warmhalteband, Zirkulation, Ausstosszeiten | R45: 2.4.4 Sie beschreiben die verschiedenen Verteilsysteme für Warmwasser. (K2) | S45: 10 | T45: Gruppenversorgung, Zentralversorgung, Einzelzapfstellen, Warmhalte- band, Zirkulation, Ausstosszeiten
C46: 2.4.6 Sie erläutern die Gefahren, die von verschmutztem Trinkwasser ausgehen können (z.B. durch Schmutzwasserverbindungen). (K2) | E46: Evtl. mit Bezug zu W3 / Gefahren von verschmutztem Trinkwasser / Sicherheitsventil etc. | H46: 2.4.7 Sie erklären die Trinkwassergewinnung. (K2) | J46: Gewinnung Trinkwasser (Grundwasser, Seewasser, Quellen), SVGW kennenlernen, Aufbereitung,Trinkwasserqualität | M46: 2.4.5 Sie erklären den Zweck und die Funktion verschiedener Armaturen für Trinkwasserleitungen.(K2) | O46: Armaturengruppen, Werkstoffe, Bauarten, Funktion Fokus «Warmwasserversorgung» | R46: 2.4.5 Sie erklären den Zweck und die Funktion verschiedener Armaturen für Trinkwasserleitungen. (K2) | T46: Funktion
H47: 2.4.8 Sie beschreiben die Funktionsweise der Wasserversorgung. (K2) | J47: Trinkwasserverteilung, -speicherung, Verteilleitungen, Armaturen, Hauszuleitung, Hauseinführung
M48: 2.4.9 Sie beschreiben die Bedeutung des sparsamen Trinkwasserverbrauches. (K2) | O48: Fokus «Warmwasserversorgung» | R48: 2.4.9 Sie beschreiben die Bedeutung des sparsamen Trinkwasserverbrauches. (K2) | T48: Nachhaltigkeit / Klimaerwärmung /
...

Sheet ST_1_KW33 
A1: Unterrichtsplanung BKU | F1: =Kompetenzraster!R5 -> 45518 | I1: 1
A4: Themen:
A5: MVS | C5: Repetition & Standortbestimmung / Rechnen | I5: 0.01
A7: PDA | C7: Standortbestimmung / AVOR Z-Mass | I7: 0.02
A10: Lernziele
B11: *Sie frischen Ihre Rechnungskentnisse auf
B12: *Sie frischen Ihre Kenntnisse über Trinkwassersysteme auf
B13: *Sie repetieren ihre Normprojektionskenntnisse
B14: *Sie repetieren ihre Z-Mass Vorfabrikationskenntnisse
A16: Zeit | C16: min. | D16: Inhalt | H16: SF | I16: Material / Links
B19: Lektion 1 | C19: 30' | D19: * Gemeinsames Kennenlernen | H19: PL
B20: 07:30 - 08:15 | C20: 15' | D20: *Erklärung Administratives | H20: LV
B23: Lektion 2 | C23: 25' | D23: *Gemeinsames Erarbeiten Auftrag 1.5 | H23: PL
B24: 08:20 - 09:05 | D24: Fragen 1-7 / + Fragen 8-17
C25: 20' | D25: *Gemeinsames Erarbeiten Auftrag 2.4 | H25: PL
D26: Fragen 1-3 / Kurze Rep. Gruppe 1-12
B27: Lektion 3 | C27: 20' | D27: *Repetition Fachrechnen / Umrechnung von Masseinheiten | H27: PL | I27: 1.1_Übung_1
B28: 09:10 - 09:55 | C28: 25' | D28: *Übungen Fachrechnen / Flächen- und Volumenberechnungen | H28: PL | I28: 1.1_Übung_2
I29: 1.1_Übung_3
I30: 2.1_Übung_3
A31: Pause 09:55Uhr-10:15Uhr
B34: Lektion 4 | C34: 15' | D34: *Repetition Normprojektion | I34: Auftrag 1.2
B35: 10:15 - 11:00 | C35: 30' | D35: *Selbständige Arbeit an 2.2_Übungen_1 | I35: 2.2_Übung_1
B38: Lektion 5 | C38: 15' | D38: *Repetition Z-Mass
B39: 11:05 - 11:50 | C39: 25' | D39: *Selbständige Arbeit an Auftrag 2.2
C40: 5' | D40: *Abschluss und Ausblick
A43: Hausaufgaben: | E43: Administratives: | G43: Ausblick nächste Woche:
E45: Taschenrechner mitnehmen!

Sheet ST_2_KW34
A1: Unterrichtsplanung BKU | F1: =Kompetenzraster!R7 -> 45525 | I1: 2
A4: Themen:
A5: MVS | C5: Repetition & Standortbestimmung / Rechnen | I5: 0.01
A7: PDA | C7: Standortbestimmung / AVOR Z-Mass | I7: 0.02
A10: Lernziele
B11: *Sie frischen Ihre Rechnungskentnisse auf
B12: *Sie frischen Ihre Kenntnisse über Trinkwassersysteme auf
B13: *Sie repetieren ihre Normprojektionskenntnisse
B14: *Sie repetieren ihre Z-Mass Vorfabrikationskenntnisse
A16: Zeit | C16: min. | D16: Inhalt | H16: SF | I16: Material / Links
B19: Lektion 1 | C19: 5' | D19: *Einstieg & Unterrichtsplanung | H19: PL
B20: 07:30 - 08:15 | C20: 10' | D20: *Kennenlernen der 5 Armaturengruppen Trinkwasser | H20: LV
C21: 30' | D21: *Gruppierungsübung | H21: EA | I21: 1.5_Übung_1
B23: Lektion 2 | C23: 30' | D23: *Diskussionsrunde Fragen 1-12 | H23: PL
B24: 08:20 - 09:05 | H24: EA
C25: 15' | D25: *Repetition Fachrechnen / Umrechnung von Masseinheiten | I25: 1.1_Übung_1
B27: Lektion 3 | C27: 45' | D27: *Übungen Fachrechnen / Flächen- und Volumenberechnungen | H27: PL
B28: 09:10 - 09:55 | I28: 1.1_Übung_2
I29: 1.1_Übung_3
I30: 2.1_Übung_3
A31: Pause 09:55Uhr-10:15Uhr
B34: Lektion 4 | C34: 10' | D34: *Gemeinsamer Einstieg Leitungsisometrie | I34: Auftrag 1.2
B35: 10:15 - 11:00 | C35: 30' | D35: *Selbständige Arbeit an 2.2_Übungen_1 | I35: 2.2_Übung_1
B38: Lektion 5 | C38: 15' | D38: *Repetition Z-Mass
B39: 11:05 - 11:50 | C39: 25' | D39: *Selbständige Arbeit an Auftrag 2.2
C40: 5' | D40: *Abschluss und Ausblick
A43: Hausaufgaben: | E43: Administratives: | G43: Ausblick nächste Woche:
A45: 1.1_Übung_1 Seite 1-4 fertigstellen | E45: Taschenrechner mitnehmen!
A48: 2.2_Übung_1 fertigstellen

Sheet ST_3_KW35
A1: Unterrichtsplanung BKU | F1: =Kompetenzraster!R9 -> 45532 | I1: 3
A4: Themen:
A5: MVS | C5: Repetition Rechnen / Armaturen | I5: 3.4
A7: PDA | C7: AVOR Z-Mass | I7: 3.1
A10: Lernziele
B11: 1.4.2 Sie berechnen das Volumen verschiedener Behältnisse. (K3)
B13: *Sie repetieren ihre Normprojektionskenntnisse
B14: *Sie repetieren ihre Z-Mass Vorfabrikationskenntnisse
A16: Zeit | C16: min. | D16: Inhalt | H16: SF | I16: Material / Links
B19: Lektion 1 | C19: 5' | D19: *Einstieg & Unterrichtsplanung | H19: PL
B20: 07:30 - 08:15 | C20: 10' | D20: Erklärung Gruppenarbeit / | H20: LV
C21: 30' | D21: *Arbeit in der Gruppe | H21: GA
B23: Lektion 2 | C23: 10' | D23: *Vorstellung Gruppe 1-4 | H23: PL
B24: 08:20 - 09:05 | C24: 10' | D24: *Vorstellung Gruppe 5-8 | H24: PL
C25: 10' | D25: *Vorstellung Gruppe 9-12 | H25: PL
C26: 15' | D26: *Ergänzung aller Fragen 1-12 | H26: PL
B27: Lektion 3 | C27: 15' | D27: *Übungen Fachrechnen / Flächen- und Volumenberechnungen | H27: LV | I27: 2.1_Übung_3
B28: 09:10 - 09:55 | C28: 30' | D28: *Selbständige Arbeit 2.1_Übung 3 | H28: EA
A31: Pause 09:55Uhr-10:15Uhr
B34: Lektion 4 | C34: 10' | D34: *Kontrolle Arbeit an 2.2_Übungen_1 | H34: PL | I34: 2.2_Übung_1
B35: 10:15 - 11:00 | C35: 20' | D35: *Gemeinsamer Start mit Auftrag 2 / Zeichnung 1 | H35: LV
C36: 15' | D36: *Selbständiges Zeichnen Zeichnung 2 | H36: EA
B38: Lektion 5 | C38: 15' | D38: *Abschluss Zeichnung 2 | H38: EA
B39: 11:05 - 11:50 | C39: 25' | D39: *Start mit Aufgabe 10 | H39: EA
C40: 5' | D40: *Abschluss und Ausblick | H40: PL
A43: Hausaufgaben: | E43: Administratives: | G43: Ausblick nächste Woche:
A45: 2.2_Übung_3 fertigstellen bis Seite 5 | E45: Taschenrechner mitnehmen! | G45: Volumenberechnungen
A46: (Aufgabe 12)
A48: Fertigstellen der Zeichnung 10 | G48: Z-Mass Zeichnungen

Sheet ST_4_KW36
A1: Unterrichtsplanung BKU | F1: =Kompetenzraster!R11 -> 45539 | I1: 4
A4: Themen:
A5: MVS | C5: Repetition & Standortbestimmung / Rechnen | I5: 3.4
A7: PDA | C7: Standortbestimmung / AVOR Z-Mass | I7: 3.1
A10: Lernziele
B11: 1.4.2 Sie berechnen das Volumen verschiedener Behältnisse. (K3)
B13: *Sie repetieren ihre Normprojektionskenntnisse
B14: *Sie repetieren ihre Z-Mass Vorfabrikationskenntnisse
A16: Zeit | C16: min. | D16: Inhalt | H16: SF | I16: Material / Links
B19: Lektion 1 | C19: 5' | D19: *Einstieg & Unterrichtsplanung | H19: PL
B20: 07:30 - 08:15 | C20: 15' | D20: *Beantwortung der 12 Fragen Auftrag 2.4 | H20: PL
C21: 25' | D21: *Start mit Auftrag 2.3 / Teil 1+2 | H21: EA | I21: 2.3_Auftrag sui
B23: Lektion 2 | C23: 25' | D23: *Arbeit im Tandem / Teil 3 Aufgabe 1&2 | H23: GA
B24: 08:20 - 09:05 | C24: 20' | D24: *Einzelarbeit /Teil 3 Aufgabe 3 | H24: EA
B27: Lektion 3 | C27: 25' | D27: *Arbeit Teil 4 / Aufgabe 1-3 | H27: EA
B28: 09:10 - 09:55 | C28: 10' | D28: *Arbeit Teil 5 / Aufgabe Reflexion | H28: EA
C29: 10' | D29: *Besprechung Prüfung nächste Woche Mathe | H29: PL
A31: Pause 09:55Uhr-10:15Uhr
B34: Lektion 4 | C34: 10' | D34: *Kontrolle Hausaufgaben Aufgabe 10a,b,c | H34: PL
B35: 10:15 - 11:00 | C35: 35' | D35: *selbstständige Arbeit an Übungsaufgaben 3.1 - 4.6 | H35: EA
B38: Lektion 5 | C38: 10' | D38: *Erklärung Leistungsnachweis 2.2 / Aufgabe 4.6
B39: 11:05 - 11:50 | C39: 25' | D39: *Arbeit an Leistungsnachweis 2.2
A43: Hausaufgaben: | E43: Administratives: | G43: Ausblick nächste Woche:
A45: Üben für Prüfung 3.4 / Mathe | E45: Taschenrechner mitnehmen! | G45: Prüfung 3.4_Mathe rep. 11.09.2024
A48: Abgabe Leistungsnachweis 2.2

Sheet ST_5_KW37
A1: Unterrichtsplanung BKU | F1: =Kompetenzraster!R13 -> 45546 | I1: 5
A4: Themen:
A5: MVS | C5: Repetition & Standortbestimmung / Rechnen | I5: 3.4
A7: PDA | C7: Standortbestimmung / AVOR Z-Mass | I7: 3.1
A10: Lernziele
B11: 1.4.2 Sie berechnen das Volumen verschiedener Behältnisse. (K3)
B13: *Sie repetieren ihre Normprojektionskenntnisse
B14: *Sie repetieren ihre Z-Mass Vorfabrikationskenntnisse
A16: Zeit | C16: min. | D16: Inhalt | H16: SF | I16: Material / Links
B19: Lektion 1 | C19: 5' | D19: *Einstieg & Unterrichtsplanung | H19: PL
B20: 07:30 - 08:15 | C20: 40' | D20: 3.1_Prüfung Fachrechnen | H20: EA | I20: Formelbuch +
D21: 60 Minuten | I21: Taschenrechner
B23: Lektion 2 | C23: 20'
B24: 08:20 - 09:05
C25: 10' | D25: *Besprechung offener Fragen | H25: PL
C26: 10' | D26: *Einstieg in Prüfungsvorbereitung Trinkwassersysteme
B27: Lektion 3 | C27: 45' | D27: *Individuelle Prüfungsvorbereitung | H27: EA
B28: 09:10 - 09:55 | D28: *offene Fragerunde | H28: PL
A31: Pause 09:55Uhr-10:15Uhr
B34: Lektion 4 | C34: 10' | D34: *Einstieg & Kontrolle Auftrag 2.2 | H34: PL
B35: 10:15 - 11:00 | C35: 35' | D35: *selbstständige Arbeit an Übungsaufgaben 3.1 - 4.6 | H35: EA
B38: Lektion 5 | C38: 10' | D38: *Erklärung Leistungsnachweis 2.2 / Aufgabe 4.6
B39: 11:05 - 11:50 | C39: 25' | D39: *Arbeit an Leistungsnachweis 2.2
A43: Hausaufgaben: | E43: Administratives: | G43: Ausblick nächste Woche:
A45: Üben für Prüfung Trinkwasserversorgung | E45: Taschenrechner mitnehmen! | G45: Einstieg Auftrag 3.4
A46: 45553 | G46: Warmwassersysteme
A48: Arbeit an Leistungsnachweis, Abgabe per | G48: Z-Mass Zeichnungen
A49: Teams am 22.09.2024

Sheet ST_6_KW38
A1: Unterrichtsplanung BKU | F1: =Kompetenzraster!R15 -> 45553 | I1: 6
A4: Themen:
A5: MVS | C5: Entsorgungsleitungen montieren | I5: 3.01
A7: PDA | C7: Standortbestimmung / AVOR Z-Mass | I7: 3.1
A10: Lernziele
B11: 1.4.2 Sie berechnen das Volumen verschiedener Behältnisse. (K3)
B13: *Sie repetieren ihre Normprojektionskenntnisse
B14: *Sie repetieren ihre Z-Mass Vorfabrikationskenntnisse
A16: Zeit | C16: min. | D16: Inhalt | H16: SF | I16: Material / Links
B19: Lektion 1 | C19: 5' | D19: *Einstieg & Unterrichtsplanung | H19: PL
B20: 07:30 - 08:15 | C20: 40' | D20: Prüfung Trinkwasserversorgung | H20: EA | I20: Formelbuch +
D21: 40 Minuten | I21: Taschenrechner
B23: Lektion 2 | C23: (60') | D23: Prüfung nachholen (Valentin, Lorik, Lorenzo)
B24: 08:20 - 09:05 | C24: 10' | D24: *Einstieg Auftrag 3.01 | H24: PL
C25: 35' | D25: *Selbständige Arbeit an Auftrag 3.01 | H25: EA
B27: Lektion 3 | C27: 40' | D27: *Selbständige Arbeit an Auftrag 3.01 | H27: EA
B28: 09:10 - 09:55 | C28: 5' | D28: *Abschlussbesprechung | H28: PL
A31: Pause 09:55Uhr-10:15Uhr
B34: Lektion 4 | C34: 10' | D34: *Einstieg & Kontrolle Auftrag 2.2 | H34: PL
B35: 10:15 - 11:00 | C35: 35' | D35: *selbstständige Arbeit an Übungsaufgaben 3.1 - 4.6 | H35: EA
B38: Lektion 5 | C38: 10' | D38: *Erklärung Leistungsnachweis 2.2 / Aufgabe 4.6
B39: 11:05 - 11:50 | C39: 25' | D39: *Arbeit an Leistungsnachweis 2.2
A43: Hausaufgaben: | E43: Administratives: | G43: Ausblick nächste Woche:
G45: Einstieg Auftrag 3.4
G46: Warmwassersysteme
A48: Arbeit an Leistungsnachweis, Abgabe per | G48: Z-Mass Zeichnungen
A49: Teams am 22.09.2024

Sheet ST_7_KW39
A1: Unterrichtsplanung BKU | F1: =Kompetenzraster!R17 -> 45560 | I1: 7
A4: Themen:
A5: MVS | C5: Entsorgungsleitungen montieren | I5: 3.01
A7: PDA | C7: Standortbestimmung / AVOR Z-Mass | I7: 3.1
A10: Lernziele
B11: *Sie beschreiben die unterschiedlichen Abwasserarten
B12: *Sie beschreiben die Materialien und Werkstoffe der Entsorgungsleitungssysteme
B13: *Sie repetieren ihre Z-Mass Vorfabrikationskenntnisse
B14: *Sie erstellen anspruchsvollere Z-Mass Zeichnungen inkl. Rohr- und Stückliste
A16: Zeit | C16: min. | D16: Inhalt | H16: SF | I16: Material / Links
B19: Lektion 1 | C19: 5' | D19: *Einstieg & Unterrichtsplanung | H19: PL
B20: 07:30 - 08:15 | C20: 10' | D20: *Gemeinsame Betrachtung Auftrag 3.01 | H20: PL
C21: 30' | D21: *Selbständige Arbeit an Fragen 1-11 | H21: EA
B23: Lektion 2 | C23: 30' | D23: *Sichtung verschiedener Systeme im Labor | H23: PL
B24: 08:20 - 09:05 | C24: 15' | D24: *Start mit Übersichtsplan _Aufgabe 12 | H24: GA | I24: Übersichtsplan
B27: Lektion 3 | C27: 10' | D27: *Diskussion Leitungsteile | H27: PL
B28: 09:10 - 09:55 | C28: 15' | D28: *Selbständige Bearbeitung Aufgabe 15 | H28: EA
C29: 20' | D29: *Einstieg und Besprechung Gewichtskraft | H29: LV
A31: Pause 09:55Uhr-10:15Uhr
B34: Lektion 4 | C34: 10' | D34: *Gemeinsamer Einstieg Übung 4.4 | H34: PL
B35: 10:15 - 11:00 | C35: 25' | D35: *selbstständige Arbeit an Übungsaufgabe - 4.4 | H35: EA
C36: 10' | D36: *Erklärung Leistungsnachweis 2.2 / Aufgabe 4.6 | I36: Übung_4.4
B38: Lektion 5 | C38: 35' | D38: *Arbeit an Leistungsnachweis 2.2 | H38: EA | I38: 2.2_LNW
B39: 11:05 - 11:50 | C39: 10' | D39: *Abschluss & Ausblick | H39: PL
A43: Hausaufgaben: | E43: Administratives: | G43: Ausblick nächste Woche:
A45: Ergänzung Auftrag 3.01 bis und mit | E45: Schulferien | G45: Einstieg Auftrag 3.4
A46: Aufgabe 15 | E46: 29.09.-20.10.2024 | G46: Warmwassersysteme
A48: Fertigstellung Leistungsnachweis 2.2 | E48: nächster Schultag: | G48: Z-Mass Zeichnungen
A49: Abgabe per Teams am 23.10.2024 | E49: 45588

Sheet ST_8_KW43
A1: Unterrichtsplanung BKU | F1: =Kompetenzraster!R19 -> 45588 | I1: 8
A4: Themen:
A5: MVS | C5: Entsorgungsleitungen montieren | I5: 3.01
A7: PDA | C7: Standortbestimmung / AVOR Z-Mass | I7: 2.2
A10: Lernziele
B11: *Sie beschreiben die unterschiedlichen Abwasserarten
B12: *Sie beschreiben die Materialien und Werkstoffe der Entsorgungsleitungssysteme
B13: *Sie repetieren ihre Z-Mass Vorfabrikationskenntnisse
B14: *Sie erstellen anspruchsvollere Z-Mass Zeichnungen inkl. Rohr- und Stückliste
A16: Zeit | C16: min. | D16: Inhalt | H16: SF | I16: Material / Links
B19: Lektion 1 | C19: 5' | D19: *Einstieg & Begrüssung | H19: PL
B20: 07:30 - 08:15 | C20: 15' | D20: *Gemeinsame Kontrolle Auftrag 3.01 | H20: PL
C21: 10' | D21: *Rückgabe Prüfung / Einheiten umwandeln + Kaltwasserversorg. | H21: PL
C22: 15' | D22: *Sie lesen die suissetec Theorie S.28-30 | H22: EA | I22: suissetecEdu
B23: Lektion 2 | C23: 10' | D23: *Input zu Gewichtskraft | H23: PL
B24: 08:20 - 09:05 | C24: 35' | D24: *Start mit Auftrag 5 (Auftrag 3.01) Aufgabe 16,17,18 | H24: EA
B27: Lektion 3 | C27: 35' | D27: *Selbständige Weiterarbeit an Aufgaben 19-22 | H27: EA
B28: 09:10 - 09:55 | C28: 10' | D28: *Kontrolle und Besprechung der Aufgaben | H28: PL
A31: Pause 09:55Uhr-10:15Uhr
B34: Lektion 4 | C34: 20' | D34: *Besprechung Leistungsnachweis 2.2 | H34: PL | I34: 2.2_Leistungsnachweis
B35: 10:15 - 11:00 | C35: 25' | D35: *Abschluss und Kontrolle Aufgabe 4.5 & 4.6 | H35: EA
B38: Lektion 5 | C38: 35' | D38: *Selbständiges Üben für Prüfung 2.2 | H38: EA
B39: 11:05 - 11:50 | C39: 10' | D39: *Abschluss & Ausblick | H39: PL
A43: Hausaufgaben: | E43: Administratives: | G43: Ausblick nächste Woche:
A45: Auftrag 3.01 fertigstellen bis Aufgabe 22 | G45: Einstieg Auftrag 3.4
G46: Warmwassersysteme
A48: Prüfung 2.2_Z-Mass 30.10.2024 | G48: Vorbereitung Z-Mass Prüfung

Sheet ST_9_KW44
A1: Unterrichtsplanung BKU | F1: =Kompetenzraster!R21 -> 45595 | I1: 9
A4: Themen:
A5: MVS | C5: Entsorgungsleitungen montieren | I5: 3.7
A7: PDA | C7: VOR Z-Mass | I7: 2.2
A10: Lernziele
B11: *Sie beschreiben die unterschiedlichen Abwasserarten
B12: *Sie beschreiben die Materialien und Werkstoffe der Entsorgungsleitungssysteme
B13: *Sie repetieren ihre Z-Mass Vorfabrikationskenntnisse
B14: *Sie erstellen anspruchsvollere Z-Mass Zeichnungen inkl. Rohr- und Stückliste
A16: Zeit | C16: min. | D16: Inhalt | H16: SF | I16: Material / Links
B19: Lektion 1 | C19: 10' | D19: *Einstieg und Vorbereitung für Prüfung | H19: PL
B20: 07:30 - 08:15 | C20: 65' | D20: *Prüfung 2.2
B23: Lektion 2
B24: 08:20 - 09:05
B27: Lektion 3 | C27: 15' | D27: *Repetition Gewichtskraft | H27: LV
B28: 09:10 - 09:55 | C28: 30' | D28: *Arbeit an Auftrag 5 / Aufgabe 15-18 | H28: EA
A31: Pause 09:55Uhr-10:15Uhr
B34: Lektion 4 | C34: 45' | D34: *Kontrolle Aufgabe 15-18 | H34: PL
B35: 10:15 - 11:00 | C35: 35' | D35: *Selbständige Arbeit an Augabe 19-22 danach 1.6_ Übung_1 | I35: 1.6_ Übung_1
B38: Lektion 5 | C38: 15' | D38: *Gemeinsamer Start mit Auftrag 6 / Dichte | H38: LV
B39: 11:05 - 11:50 | C39: 10' | D39: *Sie lesen die Theorie zur Masse & Dichte | H39: EA | I39: suissetecEdu
C40: 10' | D40: *Fertigstellung Auftrag 3.01 | H40: EA
C41: 5' | D41: *Abschluss & Ausblick
A43: Hausaufgaben: | E43: Administratives: | G43: Ausblick nächste Woche:
A45: Fertigstellung Auftrag 3.01 / ohne Übungen | G45: Einstieg Auftrag 3.4
G46: Warmwassersysteme

Sheet ST_10_KW45
A1: Unterrichtsplanung BKU | F1: =Kompetenzraster!R23 -> 45602 | I1: 10
A4: Themen:
A5: MVS | C5: Entsorgungsleitungen montieren | I5: 3.7
A7: PDA | C7: AVOR X-Mass | I7: 3.3
A10: Lernziele
B11: *Sie beschreiben verschiedene Rohrmaterialien für Entsorgungsleitungen
B12: * Sie beschreiben Einsatzgebiete, und Eigenschaften der Dämmmaterialien für Entsorgungsleitungen.
B13: * Sie kennen die Grundlagen der X-Mass Methode und wenden diese in einfachen Beispielen an.
B14: * Sie erstellen einfache X-Mass Vorfabrikationszeichnungen inkl. Rohr- und Stückliste
A16: Zeit | C16: min. | D16: Inhalt | H16: SF | I16: Material / Links
B19: Lektion 1 | C19: 10' | D19: *Einstieg & Begrüssung | H19: PL
B20: 07:30 - 08:15 | C20: 35' | D20: *Start mit Auftrag 3.7 Fragen 1-10 | H20: EA
B23: Lektion 2 | C23: 10' | D23: *Erklärung Übung 1 | H23: PL
B24: 08:20 - 09:05 | C24: 35' | D24: *Selbständige Bearbeitung Übung 1 | H24: EA
B27: Lektion 3 | C27: 45' | D27: *Selbständige Arbeit an Übung 2 | H27: EA
B28: 09:10 - 09:55
A31: Pause 09:55Uhr-10:15Uhr
B34: Lektion 4 | C34: 25' | D34: *Einstieg in X-Mass | H34: LV
B35: 10:15 - 11:00 | C35: 20' | D35: *Selbständiger Start mit Aufgabe 1-7 | H35: EA
B38: Lektion 5 | C38: 15' | D38: *Sie lesen die Theorie S.44 | H38: EA | I38: suissetecEdu
B39: 11:05 - 11:50 | C39: 20' | D39: *Input Gefällsberechnung | H39: LV
C40: 10' | D40: *Abschluss und Ausblick | H40: PL
A43: Hausaufgaben: | E43: Administratives: | G43: Ausblick nächste Woche:
A45: Fertigstellung Übung 1+2 Auftrag 3.7
G48: X-Mass Übungen

Sheet ST_11_KW46
A1: Unterrichtsplanung BKU | F1: =Kompetenzraster!R25 -> 45609 | I1: 10
A4: Themen:
A5: MVS | C5: Entsorgungsleitungen montieren | I5: 3.7
A7: PDA | C7: AVOR X-Mass | I7: 3.3
A10: Lernziele
B11: *Sie beschreiben verschiedene Rohrmaterialien für Entsorgungsleitungen
B12: * Sie beschreiben Einsatzgebiete, und Eigenschaften der Dämmmaterialien für Entsorgungsleitungen.
B13: * Sie kennen die Grundlagen der X-Mass Methode und wenden diese in einfachen Beispielen an.
B14: * Sie erstellen einfache X-Mass Vorfabrikationszeichnungen inkl. Rohr- und Stückliste
A16: Zeit | C16: min. | D16: Inhalt | H16: SF | I16: Material / Links
B19: Lektion 1 | C19: 10' | D19: *Einstieg & Begrüssung | H19: PL
B20: 07:30 - 08:15 | C20: 35' | D20: Kontrolle & Besprechung Übung 1 & 2 | H20: EA
B23: Lektion 2 | C23: 45' | D23: *Selbständige Bearbeitung Übung 3 | H23: EA
B24: 08:20 - 09:05
B27: Lektion 3 | C27: 10' | D27: *Input zu Leistungsnachweis 3.7 | H27: EA
B28: 09:10 - 09:55 | C28: 35' | D28: *Selbständige Bearbeitung Leistungsnachweis 3.7 | I28: 3.7_LNW
A31: Pause 09:55Uhr-10:15Uhr
B34: Lektion 4 | C34: 10' | D34: *Input zu Aufgabe 7 | H34: LV
B35: 10:15 - 11:00 | C35: 35' | D35: *Selbständige Bearbeitung Aurgabe 7 inkl. gemeinsamer Kontrolle | H35: EA
B38: Lektion 5 | C38: 15' | D38: *Sie lesen die Theorie S.44 | H38: EA | I38: suissetecEdu
B39: 11:05 - 11:50 | C39: 20' | D39: *Input Gefällsberechnung | H39: LV
C40: 10' | D40: *Abschluss und Ausblick | H40: PL
A43: Hausaufgaben: | E43: Administratives: | G43: Ausblick nächste Woche:
A45: Abschluss Leistungsnachweis 3.7 | G45: Schallschutz Abwasser, Dämmung
A46: Abgabe per Teams bis 20.11.2024
G48: X-Mass Übungen

Sheet ST_12_KW47 (2)
A1: Unterrichtsplanung BKU | F1: =Kompetenzraster!R27 -> 45616 | I1: 12
A4: Themen:
A5: MVS | C5: Entsorgungsleitungen montieren | I5: 3.7
A7: PDA | C7: AVOR X-Mass | I7: 3.3
A10: Lernziele
B11: *Sie beschreiben verschiedene Rohrmaterialien für Entsorgungsleitungen
B12: * Sie beschreiben Einsatzgebiete, und Eigenschaften der Dämmmaterialien für Entsorgungsleitungen.
B13: * Sie kennen die Grundlagen der X-Mass Methode und wenden diese in einfachen Beispielen an.
B14: * Sie erstellen einfache X-Mass Vorfabrikationszeichnungen inkl. Rohr- und Stückliste
A16: Zeit | C16: min. | D16: Inhalt | H16: SF | I16: Material / Links
B19: Lektion 1 | C19: 10' | D19: *Einstieg & Begrüssung | H19: PL
B20: 07:30 - 08:15 | C20: 35' | D20: Kontrolle & Besprechung Leistungsnachweis 3.7 | H20: EA
B23: Lektion 2 | C23: 15' | D23: * Einstieg Thema Schall | H23: LV
B24: 08:20 - 09:05 | C24: 10' | D24: * Sie studieren die Theorie auf S.108-111 | H24: EA
D25: * Gemeinsame Bearbeitung Fragen 15-19
B27: Lektion 3 | C27: 10' | D27: * Einstieg Aufgabe 20 | H27: PL
B28: 09:10 - 09:55 | C28: 35' | D28: *Selbständige Bearbeitung Fragen 21-24 | H28: EA
A31: Pause 09:55Uhr-10:15Uhr
B34: Lektion 4 | C34: 10' | D34: * Start mit Aufgabe 6.5 "Bodenkloset | H34: LV
B35: 10:15 - 11:00 | C35: 35' | D35: * Selbständige Bearbeitung Aufgabe 6.5 | H35: EA
B38: Lektion 5 | C38: 35' | D38: * Selbständige Arbeit an Aufgabe 6.6 | H38: EA | I38: suissetecEdu
B39: 11:05 - 11:50 | C39: 10' | D39: * Abschluss und Ausblick | H39: PL
A43: Hausaufgaben: | E43: Administratives: | G43: Ausblick nächste Woche:
A48: Abschluss Aufgabe 6.5 & 6.6 | G48: X-Mass Übungen

Sheet ST_13_KW48
A1: Unterrichtsplanung BKU | F1: =Kompetenzraster!R29 -> 45623 | I1: 13
A4: Themen:
A5: MVS | C5: Vorwände | I5: 3.1
A7: PDA | C7: AVOR X-Mass | I7: 3.3
A10: Lernziele
B11: *Sie beschreiben verschiedene Rohrmaterialien für Entsorgungsleitungen
B12: * Sie beschreiben Einsatzgebiete, und Eigenschaften der Dämmmaterialien für Entsorgungsleitungen.
B13: * Sie kennen die Grundlagen der X-Mass Methode und wenden diese in einfachen Beispielen an.
B14: * Sie erstellen einfache X-Mass Vorfabrikationszeichnungen inkl. Rohr- und Stückliste
A16: Zeit | C16: min. | D16: Inhalt | H16: SF | I16: Material / Links
B19: Lektion 1 | C19: 10' | D19: *Einstieg & Begrüssung | H19: PL
B20: 07:30 - 08:15 | C20: 20' | D20: *Abschluss Lernauftrag 3.7 | H20: EA
C21: 15' | D21: *Überprüfen der Fragen | H21: EA
B23: Lektion 2 | C23: 20' | D23: * Selbständiges Lernen für die Prüfung 3.7 | H23: EA
B24: 08:20 - 09:05 | C24: 25' | D24: * Einstieg in Auftrag 3.10 / Vorwände | H24: EA
B27: Lektion 3 | C27: 5' | D27: *Erklärung Auftrag 2 | H27: LV
B28: 09:10 - 09:55 | C28: 40' | D28: * Bearbeitung Auftrag 2 | H28: GA
A31: Pause 09:55Uhr-10:15Uhr
B34: Lektion 4 | C34: 10' | D34: * Start mit Aufgabe 6.5 "Bodenkloset | H34: LV
B35: 10:15 - 11:00 | C35: 35' | D35: * Selbständige Bearbeitung Aufgabe 6.5 | H35: EA
B38: Lektion 5 | C38: 35' | D38: * Selbständige Arbeit an Aufgabe 6.6 | H38: EA | I38: suissetecEdu
B39: 11:05 - 11:50 | C39: 10' | D39: * Abschluss und Ausblick | H39: PL
A43: Hausaufgaben: | E43: Administratives: | G43: Ausblick nächste Woche:
G45: Vorwandtechnik
A48: Abschluss Aufgabe 6.5 & 6.6 | G48: X-Mass Übungen

Sheet ST_14_KW49
A1: Unterrichtsplanung BKU | F1: =Kompetenzraster!R31 -> 45630 | I1: 14
A4: Themen:
A5: MVS | C5: Vorwände | I5: 3.1
A7: PDA | C7: AVOR X-Mass | I7: 3.3
A10: Lernziele
B11: *Sie beschreiben die handeslüblichen Vorwandsysteme
B12: * Sie beschreiben Einsatzgebiete, und Eigenschaften der Dämmmaterialien für Entsorgungsleitungen.
B13: * Sie kennen die Grundlagen der X-Mass Methode und wenden diese in einfachen Beispielen an.
B14: * Sie erstellen einfache X-Mass Vorfabrikationszeichnungen inkl. Rohr- und Stückliste
A16: Zeit | C16: min. | D16: Inhalt | H16: SF | I16: Material / Links
B19: Lektion 1 | C19: 10' | D19: *Einstieg & Begrüssung | H19: PL
B20: 07:30 - 08:15 | C20: 20' | D20: *Bearbeitung Auftrag 3 | H20: EA
C21: 15' | D21: *Besprechung Auftrag 3 | H21: PL
B23: Lektion 2 | C23: 10' | D23: *Besprechung Leistungsnachweis 3.10 | H23: EA
B24: 08:20 - 09:05 | C24: 35' | D24: *Selbständige Arbeit an Leistungsnachweis | H24: EA
B27: Lektion 3 | C27: 10' | D27: *Erklärung Lernziele 3.7Prüfung | H27: LV
B28: 09:10 - 09:55 | C28: 35' | D28: * Selbständiges Lernen für die Prüfung 3.7 | H28: GA
A31: Pause 09:55Uhr-10:15Uhr
B34: Lektion 4 | C34: 20' | D34: *Abschluss Aufgabe 6.6 "Reservestutzen" | H34: PL
B35: 10:15 - 11:00 | C35: 25' | D35: *Start mit der Aufgabe 6.7 "Duschwannenanschluss" | H35: EA
B38: Lektion 5 | C38: 20' | D38: *Abschluss | H38: EA
B39: 11:05 - 11:50 | C39: 10' | H39: PL
A43: Hausaufgaben: | E43: Administratives: | G43: Ausblick nächste Woche:
A45: Arbeit an Leistungsnachweis 3.10 | G45: Vorwandtechnik
A46: Abgabe am 18.12.2024
G48: X-Mass Übungen

Sheet ST_15_KW50
A1: Unterrichtsplanung BKU | F1: =Kompetenzraster!R33 -> 45637 | I1: 15
A4: Themen:
A5: MVS | C5: Vorwände | I5: 3.1
A7: PDA | C7: AVOR X-Mass | I7: 3.3
A10: Lernziele
B11: *Sie beschreiben die handeslüblichen Vorwandsysteme
B12: * Sie beschreiben Einsatzgebiete, und Eigenschaften der Dämmmaterialien für Entsorgungsleitungen.
B13: * Sie kennen die Grundlagen der X-Mass Methode und wenden diese in einfachen Beispielen an.
B14: * Sie erstellen einfache X-Mass Vorfabrikationszeichnungen inkl. Rohr- und Stückliste
A16: Zeit | C16: min. | D16: Inhalt | H16: SF | I16: Material / Links
B19: Lektion 1 | C19: 10' | D19: *Einstieg & Begrüssung | H19: PL
B20: 07:30 - 08:15 | C20: 40' | D20: Prüfung 3.7 | H20: EA | I20: Formelbuch &
I21: Taschenrechner
B23: Lektion 2
B24: 08:20 - 09:05 | C24: 5' | D24: * Pause
C25: 30' | D25: * Arbeit an 3.10 Leistungsnachweis
B27: Lektion 3 | C27: 45' | D27: * Arbeit an 3.10 Leistungsnachweis
B28: 09:10 - 09:55
A31: Pause 09:55Uhr-10:15Uhr
B34: Lektion 4 | C34: 10' | D34: *Abschluss Aufgabe 6.6 "Reservestutzen" | H34: PL
B35: 10:15 - 11:00 | C35: 35' | D35: *Start mit der Aufgabe 6.7 "Duschwannenanschluss" | H35: EA
B38: Lektion 5 | C38: 35' | D38: *Abschluss Aufgabe 6.7 | H38: EA
B39: 11:05 - 11:50 | C39: 10' | D39: *Abschluss & Ausblick auf Prüfung 3.3 | H39: PL
A43: Hausaufgaben: | E43: Administratives: | G43: Ausblick nächste Woche:
A45: Arbeit an Leistungsnachweis 3.10 | G45: Vorwandtechnik
A46: Abgabe am 18.12.2024
A49: Lernen für die Prüfung 3.3 / 18.12.2024 | G49: X-Mass Übungen

Sheet ST_16_KW51
A1: Unterrichtsplanung BKU | F1: =Kompetenzraster!R35 -> 45644 | I1: 16
A4: Themen:
A5: MVS | C5: Vorwände | I5: 3.1
A7: PDA | C7: AVOR X-Mass | I7: 3.3
A10: Lernziele
B11: *Sie beschreiben die handeslüblichen Vorwandsysteme
B12: * Sie beschreiben Einsatzgebiete, und Eigenschaften der Dämmmaterialien für Entsorgungsleitungen.
B13: * Sie kennen die Grundlagen der X-Mass Methode und wenden diese in einfachen Beispielen an.
B14: * Sie erstellen einfache X-Mass Vorfabrikationszeichnungen inkl. Rohr- und Stückliste
A16: Zeit | C16: min. | D16: Inhalt | H16: SF | I16: Material / Links
B19: Lektion 1 | C19: 15' | D19: *Einstieg & Begrüssung | H19: PL
B20: 07:30 - 08:15 | C20: 75' | D20: Prüfung 3.3 | H20: EA | I20: Formelbuch &
I21: Taschenrechner
B23: Lektion 2
B24: 08:20 - 09:05
B27: Lektion 3 | C27: 15' | D27: *Überprüfung und gemeinsame Betrachtung Leistungsnachweis 3.10 | H27: PL
B28: 09:10 - 09:55 | C28: 30' | D28: *Abschluss und Ausblick nach den Ferien
A31: Pause 09:55Uhr-10:15Uhr
B34: Lektion 4 | C34: 45' | D34: *Abschluss Aufgabe 6.5, 6.6, 6.7 | H34: PL
B35: 10:15 - 11:00 | D35: 3 unterzeichnete X-Mass Blätter abgeben 3.3 LNW | H35: EA
B38: Lektion 5 | C38: 45' | D38: *Gemeinsamer Abschluss / Diskussion | H38: PL
B39: 11:05 - 11:50
A43: Hausaufgaben: | E43: Administratives: | G43: Ausblick nächste Woche:
E45: Schulferien:
E46: 23.12.2024 - 06.01.2025
E47: Nächster Schultag:
E48: 45665

Sheet ST_17_KW02
A1: Unterrichtsplanung BKU | F1: =Kompetenzraster!R37 -> 45665 | I1: 17
A4: Themen:
A5: MVS | C5: Vorwände | I5: 3.1
A7: PDA | C7: AVOR X-Mass | I7: 3.3
A10: Lernziele
B11: *Sie beschreiben die handeslüblichen Vorwandsysteme
B12: * Sie beschreiben Einsatzgebiete, und Eigenschaften der Dämmmaterialien für Entsorgungsleitungen.
